Workbook

Sheet APRIL 25
C1: DISPOSAFE HEALTH AND LIFE CARE LIMITED Plot No.37A, Sector-06, Ballabgarh (Faridabad) Haryana India 121006
A3: ASSEMBLY SECTION DAILY REJECTION REPORT FOR APRIL 25
A4: DATE | B4: VISUAL QTY | C4: VISUAL ACPT QTY | D4: REJ QTY | E4: REJ % | F4: BALLOON CHKD QTY | G4: BALLOON ACPT QTY | H4: REJ QTY | I4: REJ % | J4: VALVE INT CHKD QTY | K4: VALVE INTY ACPT QTY | L4: VALVE INTY REJ Qty | M4: REJ % | N4: FINAL CHECKED QTY | O4: FINAL REJECTION | P4: TOTAL REJ QTY | Q4: FINAL REJ % | R4: VISUAL CHECKED QTY | S4: VISUAL REJ QTY | T4: VISUAL REJ %
A6: 45748 | B6: 10982 | C6: 9627 | D6: 1054 | E6: =D6/B6*100 -> 9.5975232 | F6: 9627 | G6: 9612 | H6: 15 | I6: =H6/F6*100 -> 0.15581178 | J6: 9612 | K6: 9483 | L6: 129 | M6: =L6/J6*100 -> 1.3420724 | N6: 6685 | O6: 1448 | P6: =D6+H6+L6+O6 -> 2646 | Q6: =O6/N6*100 -> 21.660434 | R6: WEEK 1
A7: 45749 | B7: 11054 | C7: 9907 | D7: 828 | E7: =D7/B7*100 -> 7.4905012 | F7: 9907 | G7: 9858 | H7: 49 | I7: =H7/F7*100 -> 0.49459978 | J7: 9858 | K7: 9767 | L7: 91 | M7: =L7/J7*100 -> 0.92310814 | N7: 9767 | O7: 140 | P7: =D7+H7+L7+O7 -> 1108 | Q7: =O7/N7*100 -> 1.4333982 | R7: =SUM(B6:B10) -> 53701 | S7: =SUM(P6:P10) -> 6932 | T7: =S7/R7*100 -> 12.908512
A8: 45750 | B8: 12039 | C8: 10946 | D8: 847 | E8: =D8/B8*100 -> 7.0354681 | F8: 10746 | G8: 10683 | H8: 63 | I8: =H8/F8*100 -> 0.58626466 | J8: 10683 | K8: 10632 | L8: 51 | M8: =L8/J8*100 -> 0.47739399 | N8: 4231 | O8: 99 | P8: =D8+H8+L8+O8 -> 1060 | Q8: =O8/N8*100 -> 2.3398724
A9: 45751 | B9: 11041 | C9: 9573 | D9: 1117 | E9: =D9/B9*100 -> 10.116837 | F9: 9573 | G9: 9555 | H9: 18 | I9: =H9/F9*100 -> 0.18802883 | J9: 9555 | K9: 9481 | L9: 74 | M9: =L9/J9*100 -> 0.77446363 | P9: =D9+H9+L9+O9 -> 1209 | Q9: 0
A10: 45752 | B10: 8585 | C10: 7801 | D10: 654 | E10: =D10/B10*100 -> 7.6179383 | F10: 7038 | G10: 7018 | H10: 20 | I10: =H10/F10*100 -> 0.28417164 | J10: 7018 | K10: 6963 | L10: 55 | M10: =L10/J10*100 -> 0.78369906 | N10: 6401 | O10: 180 | P10: =D10+H10+L10+O10 -> 909 | Q10: =O10/N10*100 -> 2.8120606
B11: =SUM(B6:B10) -> 53701 | C11: =SUM(C6:C10) -> 47854 | D11: =SUM(D6:D10) -> 4500 | E11: =D11/B11*100 -> 8.3797322 | F11: =SUM(F6:F10) -> 46891 | G11: =SUM(G6:G10) -> 46726 | H11: =SUM(H6:H10) -> 165 | I11: =H11/F11*100 -> 0.35187989 | J11: =SUM(J6:J10) -> 46726 | K11: =SUM(K6:K10) -> 46326 | L11: =SUM(L6:L10) -> 400 | M11: =L11/J11*100 -> 0.85605445 | N11: =SUM(N6:N10) -> 27084 | O11: =SUM(O6:O10) -> 1867 | P11: =SUM(P6:P10) -> 6932 | Q11: =O11/N11*100 -> 6.8933688
A12: SUNDAY
A13: 45754 | B13: 5230 | C13: 4553 | D13: 609 | E13: =D13/B13*100 -> 11.644359 | F13: 4553 | G13: 4498 | H13: 55 | I13: =H13/F13*100 -> 1.2079947 | J13: 4498 | K13: 4443 | L13: 55 | M13: =L13/J13*100 -> 1.2227657 | N13: 6963 | O13: 87 | P13: =D13+H13+L13+O13 -> 806 | Q13: =O13/N13*100 -> 1.2494614 | R13: WEEK 2
A14: 45755 | B14: 10167 | C14: 9400 | D14: 680 | E14: =D14/B14*100 -> 6.6883053 | F14: 9400 | G14: 9326 | H14: 71 | I14: =H14/F14*100 -> 0.75531915 | J14: 9326 | K14: 9100 | L14: 226 | M14: =L14/J14*100 -> 2.4233326 | N14: 3590 | O14: 91 | P14: =D14+H14+L14+O14 -> 1068 | Q14: =O14/N14*100 -> 2.5348189 | R14: =SUM(B13:B18) -> 56572 | S14: =SUM(P13:P18) -> 4845 | T14: =S14/R14*100 -> 8.5643074
A15: 45756 | B15: 9455 | C15: 8912 | D15: 297 | E15: =D15/B15*100 -> 3.1411951 | F15: 8912 | G15: 8886 | H15: 26 | I15: =H15/F15*100 -> 0.29174147 | J15: 8886 | K15: 8820 | L15: 66 | M15: =L15/J15*100 -> 0.74274139 | N15: 5527 | O15: 170 | P15: =D15+H15+L15+O15 -> 559 | Q15: =O15/N15*100 -> 3.0758097
A16: 45757 | B16: 10959 | C16: 10350 | D16: 455 | E16: =D16/B16*100 -> 4.1518387 | F16: 10350 | G16: 10279 | H16: 71 | I16: =H16/F16*100 -> 0.68599034 | J16: 10279 | K16: 10159 | L16: 120 | M16: =L16/J16*100 -> 1.1674287 | N16: 9970 | O16: 220 | P16: =D16+H16+L16+O16 -> 866 | Q16: =O16/N16*100 -> 2.2066199
A17: 45758 | B17: 12959 | C17: 12214 | D17: 527 | E17: =D17/B17*100 -> 4.0666718 | F17: 12214 | G17: 12114 | H17: 100 | I17: =H17/F17*100 -> 0.8187326 | J17: 12114 | K17: 12058 | L17: 56 | M17: =L17/J17*100 -> 0.46227505 | N17: 9689 | O17: 139 | P17: =D17+H17+L17+O17 -> 822 | Q17: =O17/N17*100 -> 1.4346166
A18: 45759 | B18: 7802 | C18: 7250 | D18: 379 | E18: =D18/B18*100 -> 4.8577288 | F18: 7250 | G18: 7214 | H18: 36 | I18: =H18/F18*100 -> 0.49655172 | J18: 7214 | K18: 7148 | L18: 66 | M18: =L18/J18*100 -> 0.91488772 | N18: 12748 | O18: 243 | P18: =D18+H18+L18+O18 -> 724 | Q18: =O18/N18*100 -> 1.9061814
B19: =SUM(B13:B18) -> 56572 | C19: =SUM(C13:C18) -> 52679 | D19: =SUM(D13:D18) -> 2947 | E19: =D19/B19*100 -> 5.2092908 | F19: =SUM(F13:F18) -> 52679 | G19: =SUM(G13:G18) -> 52317 | H19: =SUM(H13:H18) -> 359 | I19: =H19/F19*100 -> 0.68148598 | J19: =SUM(J13:J18) -> 52317 | K19: =SUM(K13:K18) -> 51728 | L19: =SUM(L13:L18) -> 589 | M19: =L19/J19*100 -> 1.1258291 | N19: =SUM(N13:N18) -> 48487 | O19: =SUM(O13:O18) -> 950 | P19: =SUM(P13:P18) -> 4845 | Q19: =O19/N19*100 -> 1.9592881
A20: SUNDAY
A21: 45761 | B21: 7479 | C21: 6182 | D21: 1247 | E21: =D21/B21*100 -> 16.673352 | F21: 6152 | G21: 6088 | H21: 94 | I21: =H21/F21*100 -> 1.5279584 | J21: 6088 | K21: 5967 | L21: 121 | M21: =L21/J21*100 -> 1.9875164 | N21: 8733 | O21: 118 | P21: =D21+H21+L21+O21 -> 1580 | Q21: =O21/N21*100 -> 1.3511966 | R21: WEEK 3
A22: 45762 | B22: 12492 | C22: 11557 | D22: 700 | E22: =D22/B22*100 -> 5.6035863 | F22: 11557 | G22: 11479 | H22: 78 | I22: =H22/F22*100 -> 0.67491564 | J22: 11479 | K22: 11376 | L22: 103 | M22: =L22/J22*100 -> 0.8972907 | N22: 4077 | O22: 294 | P22: =D22+H22+L22+O22 -> 1175 | Q22: =O22/N22*100 -> 7.2111847 | R22: =SUM(B21:B26) -> 61231 | S22: =SUM(P21:P26) -> 10531 | T22: =S22/R22*100 -> 17.198805
A23: 45763 | B23: 10594 | C23: 8339 | D23: 671 | E23: =D23/B23*100 -> 6.3337738 | F23: 8339 | G23: 8267 | H23: 57 | I23: =H23/F23*100 -> 0.6835352 | J23: 8267 | K23: 7477 | L23: 790 | M23: =L23/J23*100 -> 9.5560663 | N23: 5022 | O23: 95 | P23: =D23+H23+L23+O23 -> 1613 | Q23: =O23/N23*100 -> 1.8916766
A24: 45764 | B24: 11049 | C24: 10209 | D24: 680 | E24: =D24/B24*100 -> 6.1544031 | F24: 10209 | G24: 10104 | H24: 105 | I24: =H24/F24*100 -> 1.0285043 | J24: 10104 | K24: 8874 | L24: 1230 | M24: =L24/J24*100 -> 12.173397 | N24: 11917 | O24: 224 | P24: =D24+H24+L24+O24 -> 2239 | Q24: =O24/N24*100 -> 1.8796677
A25: 45765 | B25: 9273 | C25: 8453 | D25: 722 | E25: =D25/B25*100 -> 7.7860455 | F25: 8453 | G25: 8390 | H25: 63 | I25: =H25/F25*100 -> 0.74529753 | J25: 8390 | K25: 6557 | L25: 1833 | M25: =L25/J25*100 -> 21.847437 | N25: 16314 | O25: 261 | P25: =D25+H25+L25+O25 -> 2879 | Q25: =O25/N25*100 -> 1.5998529
A26: 45766 | B26: 10344 | C26: 9612 | D26: 420 | E26: =D26/B26*100 -> 4.0603248 | F26: 10889 | G26: 10794 | H26: 95 | I26: =H26/F26*100 -> 0.87244008 | J26: 10794 | K26: 9967 | L26: 143 | M26: =L26/J26*100 -> 1.3248101 | N26: 4646 | O26: 387 | P26: =D26+H26+L26+O26 -> 1045 | Q26: =O26/N26*100 -> 8.329746
B27: =SUM(B21:B26) -> 61231 | C27: =SUM(C21:C26) -> 54352 | D27: =SUM(D21:D26) -> 4440 | E27: =D27/B27*100 -> 7.251229 | F27: =SUM(F21:F26) -> 55599 | G27: =SUM(G21:G26) -> 55122 | H27: =SUM(H21:H26) -> 492 | I27: =H27/F27*100 -> 0.884908 | J27: =SUM(J21:J26) -> 55122 | K27: =SUM(K21:K26) -> 50218 | L27: =SUM(L21:L26) -> 4220 | M27: =L27/J27*100 -> 7.6557454 | N27: =SUM(N21:N26) -> 50709 | O27: =SUM(O21:O26) -> 1379 | P27: =SUM(P21:P26) -> 10531 | Q27: =O27/N27*100 -> 2.7194384
A28: SUNDAY
A29: 45768 | B29: 0 | C29: 0 | D29: 0 | E29: =D29/B29*100 -> #DIV/0! | F29: 0 | G29: 0 | H29: 0 | I29: =H29/F29*100 -> #DIV/0! | J29: 0 | K29: 0 | L29: 0 | M29: =L29/J29*100 -> #DIV/0! | N29: 8720 | O29: 257 | P29: =D29+H29+L29+O29 -> 257 | Q29: =O29/N29*100 -> 2.9472477 | R29: WEEK 4
A30: 45769 | B30: 9439 | C30: 7281 | D30: 291 | E30: =D30/B30*100 -> 3.0829537 | F30: 7281 | G30: 7244 | H30: 37 | I30: =H30/F30*100 -> 0.50817195 | J30: 7244 | K30: 7177 | L30: 67 | M30: =L30/J30*100 -> 0.92490337 | N30: 15357 | O30: 262 | P30: =D30+H30+L30+O30 -> 657 | Q30: =O30/N30*100 -> 1.7060624 | R30: =SUM(B29:B34) -> 46816 | S30: =SUM(P29:P34) -> 6286 | T30: =S30/R30*100 -> 13.427033
A31: 45770 | B31: 8884 | C31: 7370 | D31: 414 | E31: =D31/B31*100 -> 4.660063 | F31: 7370 | G31: 7220 | H31: 150 | I31: =H31/F31*100 -> 2.0352782 | J31: 7220 | K31: 7143 | L31: 77 | M31: =L31/J31*100 -> 1.066482 | N31: 11881 | O31: 85 | P31: =D31+H31+L31+O31 -> 726 | Q31: =O31/N31*100 -> 0.71542799
A32: 45771 | B32: 9929 | C32: 6878 | D32: 1153 | E32: =D32/B32*100 -> 11.612448 | F32: 6878 | G32: 6755 | H32: 123 | I32: =H32/F32*100 -> 1.7883106 | J32: 6755 | K32: 6694 | L32: 61 | M32: =L32/J32*100 -> 0.90303479 | N32: 12095 | O32: 204 | P32: =D32+H32+L32+O32 -> 1541 | Q32: =O32/N32*100 -> 1.6866474
A33: 45772 | B33: 10020 | C33: 8614 | D33: 965 | E33: =D33/B33*100 -> 9.6307385 | F33: 8614 | G33: 8485 | H33: 129 | I33: =H33/F33*100 -> 1.4975621 | J33: 8485 | K33: 8425 | L33: 60 | M33: =L33/J33*100 -> 0.70713023 | N33: 8544 | O33: 49 | P33: =D33+H33+L33+O33 -> 1203 | Q33: =O33/N33*100 -> 0.57350187
A34: 45773 | B34: 8544 | C34: 5986 | D34: 1573 | E34: =D34/B34*100 -> 18.410581 | F34: 5986 | G34: 5937 | H34: 49 | I34: =H34/F34*100 -> 0.81857668 | J34: 5937 | K34: 5887 | L34: 58 | M34: =L34/J34*100 -> 0.97692437 | N34: 9758 | O34: 222 | P34: =D34+H34+L34+O34 -> 1902 | Q34: =O34/N34*100 -> 2.2750564
B35: =SUM(B29:B34) -> 46816 | C35: =SUM(C29:C34) -> 36129 | D35: =SUM(D29:D34) -> 4396 | E35: =D35/B35*100 -> 9.3899522 | F35: =SUM(F29:F34) -> 36129 | G35: =SUM(G29:G34) -> 35641 | H35: =SUM(H29:H34) -> 488 | I35: =H35/F35*100 -> 1.3507155 | J35: =SUM(J29:J34) -> 35641 | K35: =SUM(K29:K34) -> 35326 | L35: =SUM(L29:L34) -> 323 | M35: =L35/J35*100 -> 0.90625964 | N35: =SUM(N29:N34) -> 66355 | O35: =SUM(O29:O34) -> 1079 | P35: =SUM(P29:P34) -> 6286 | Q35: =O35/N35*100 -> 1.626102
A36: SUNDAY
A37: 45775 | B37: 9730 | C37: 8183 | D37: 926 | E37: =D37/B37*100 -> 9.5169579 | F37: 8183 | G37: 7955 | H37: 228 | I37: =H37/F37*100 -> 2.7862642 | J37: 7955 | K37: 7640 | L37: 315 | M37: =L37/J37*100 -> 3.9597737 | N37: 10039 | O37: 223 | P37: =D37+H37+L37+O37 -> 1692 | Q37: =O37/N37*100 -> 2.2213368 | R37: WEEK 5
A38: 45776 | B38: 9468 | C38: 8788 | D38: 354 | E38: =D38/B38*100 -> 3.73891 | F38: 8788 | G38: 8723 | H38: 65 | I38: =H38/F38*100 -> 0.73964497 | J38: 8723 | K38: 8597 | L38: 126 | M38: =L38/J38*100 -> 1.4444572 | N38: 10651 | O38: 88 | P38: =D38+H38+L38+O38 -> 633 | Q38: =O38/N38*100 -> 0.8262135 | R38: =SUM(B37:B39) -> 29447 | S38: =SUM(P37:P39) -> 4588 | T38: =S38/R38*100 -> 15.580535
A39: 45777 | B39: 10249 | C39: 7811 | D39: 1708 | E39: =D39/B39*100 -> 16.66504 | F39: 7811 | G39: 7698 | H39: 113 | I39: =H39/F39*100 -> 1.4466778 | J39: 7698 | K39: 7570 | L39: 128 | M39: =L39/J39*100 -> 1.6627696 | N39: 7570 | O39: 314 | P39: =D39+H39+L39+O39 -> 2263 | Q39: =O39/N39*100 -> 4.1479524
B40: =SUM(B37:B39) -> 29447 | C40: =SUM(C37:C39) -> 24782 | D40: =SUM(D37:D39) -> 2988 | E40: =D40/B40*100 -> 10.147044 | F40: =SUM(F37:F39) -> 24782 | G40: =SUM(G37:G39) -> 24376 | H40: =SUM(H37:H39) -> 406 | I40: =H40/F40*100 -> 1.6382859 | J40: =SUM(J37:J39) -> 24376 | K40: =SUM(K37:K39) -> 23807 | L40: =SUM(L37:L39) -> 569 | M40: =L40/J40*100 -> 2.3342632 | N40: =SUM(N37:N39) -> 28260 | O40: =SUM(O37:O39) -> 625 | P40: =SUM(P37:P39) -> 4588 | Q40: =O40/N40*100 -> 2.2116065
A41: Total | B41: =B40+B35+B27+B19+B11 -> 247767 | C41: =C40+C35+C27+C19+C11 -> 215796 | D41: =D40+D35+D27+D19+D11 -> 19271 | E41: =D41/B41*100 -> 7.777872 | F41: =F40+F35+F27+F19+F11 -> 216080 | G41: =G40+G35+G27+G19+G11 -> 214182 | H41: =H40+H35+H27+H19+H11 -> 1910 | I41: =H41/F41*100 -> 0.88393188 | J41: =J40+J35+J27+J19+J11 -> 214182 | K41: =K40+K35+K27+K19+K11 -> 207405 | L41: =L40+L35+L27+L19+L11 -> 6101 | M41: =L41/J41*100 -> 2.848512 | N41: =N40+N35+N27+N19+N11 -> 220895 | O41: =O40+O35+O27+O19+O11 -> 5900 | P41: =D41+H41+L41+O41 -> 33182 | Q41: =O41/N41*100 -> 2.6709523

Sheet MAY 25
C1: DISPOSAFE HEALTH AND LIFE CARE LIMITED Plot No.37A, Sector-06, Ballabgarh (Faridabad) Haryana India 121006
A3: ASSEMBLY SECTION DAILY REJECTION REPORT FOR MAY 25
A4: DATE | B4: VISUAL QTY | C4: VISUAL ACPT QTY | D4: REJ QTY | E4: REJ % | F4: BALLOON CHKD QTY | G4: BALLOON ACPT QTY | H4: REJ QTY | I4: REJ % | J4: VALVE INT CHKD QTY | K4: VALVE INTY ACPT QTY | L4: VALVE INTY REJ Qty | M4: REJ % | N4: FINAL CHECKED QTY | O4: FINAL REJECTION | P4: TOTAL REJ QTY | Q4: FINAL REJ % | R4: VISUAL CHECKED QTY | S4: VISUAL REJ QTY | T4: VISUAL REJ %
A6: 45778 | B6: 8346 | C6: 6229 | D6: 451 | E6: =D6/B6*100 -> 5.4037862 | F6: 6229 | G6: 6123 | H6: 106 | I6: =H6/F6*100 -> 1.7017178 | J6: 6123 | K6: 6000 | L6: 123 | M6: =L6/J6*100 -> 2.0088192 | N6: 6795 | O6: 56 | P6: =D6+H6+L6+O6 -> 736 | Q6: =O6/N6*100 -> 0.82413539 | R6: WEEK 1
A7: 45779 | B7: 4590 | C7: 4208 | D7: 193 | E7: =D7/B7*100 -> 4.204793 | F7: 4208 | G7: 4188 | H7: 20 | I7: =H7/F7*100 -> 0.47528517 | J7: 4188 | K7: 4138 | L7: 22 | M7: =L7/J7*100 -> 0.52531041 | N7: 5147 | O7: 66 | P7: =D7+H7+L7+O7 -> 301 | Q7: =O7/N7*100 -> 1.2823004 | R7: =SUM(B6:B8) -> 16560 | S7: =SUM(P6:P8) -> 1520 | T7: =S7/R7*100 -> 9.178744
A8: 45780 | B8: 3624 | C8: 2280 | D8: 356 | E8: =D8/B8*100 -> 9.8233996 | F8: 6642 | G8: 6591 | H8: 51 | I8: =H8/F8*100 -> 0.76784101 | J8: 6591 | K8: 6570 | L8: 21 | M8: =L8/J8*100 -> 0.31861629 | N8: 6603 | O8: 55 | P8: =D8+H8+L8+O8 -> 483 | Q8: =O8/N8*100 -> 0.83295472
B9: =SUM(B6:B8) -> 16560 | C9: =SUM(C6:C8) -> 12717 | D9: =SUM(D6:D8) -> 1000 | E9: =D9/B9*100 -> 6.0386473 | F9: =SUM(F6:F8) -> 17079 | G9: =SUM(G6:G8) -> 16902 | H9: =SUM(H6:H8) -> 177 | I9: =H9/F9*100 -> 1.0363604 | J9: =SUM(J6:J8) -> 16902 | K9: =SUM(K6:K8) -> 16708 | L9: =SUM(L6:L8) -> 166 | M9: =L9/J9*100 -> 0.98213229 | N9: =SUM(N6:N8) -> 18545 | O9: =SUM(O6:O8) -> 177 | P9: =SUM(P6:P8) -> 1520 | Q9: =O9/N9*100 -> 0.95443516
A10: SUNDAY
A11: 45782 | B11: 6924 | C11: 5847 | D11: 886 | E11: =D11/B11*100 -> 12.796072 | F11: 5847 | G11: 5698 | H11: 149 | I11: =H11/F11*100 -> 2.5483154 | J11: 5698 | K11: 5555 | L11: 143 | M11: =L11/J11*100 -> 2.5096525 | N11: 6034 | O11: 86 | P11: =D11+H11+L11+O11 -> 1264 | Q11: =O11/N11*100 -> 1.4252569 | R11: WEEK 2
A12: 45783 | B12: 7528 | C12: 6490 | D12: 823 | E12: =D12/B12*100 -> 10.932519 | F12: 6490 | G12: 6397 | H12: 93 | I12: =H12/F12*100 -> 1.4329738 | J12: 6397 | K12: 6243 | L12: 154 | M12: =L12/J12*100 -> 2.4073785 | N12: 6938 | O12: 229 | P12: =D12+H12+L12+O12 -> 1299 | Q12: =O12/N12*100 -> 3.300663 | R12: =SUM(B11:B16) -> 47279 | S12: =SUM(P11:P16) -> 6770 | T12: =S12/R12*100 -> 14.319254
A13: 45784 | B13: 8703 | C13: 7627 | D13: 833 | E13: =D13/B13*100 -> 9.5714122 | F13: 7268 | G13: 7164 | H13: 104 | I13: =H13/F13*100 -> 1.4309301 | J13: 7164 | K13: 7085 | L13: 79 | M13: =L13/J13*100 -> 1.1027359 | N13: 8000 | O13: 287 | P13: =D13+H13+L13+O13 -> 1303 | Q13: =O13/N13*100 -> 3.5875
A14: 45785 | B14: 9138 | C14: 7898 | D14: 682 | E14: =D14/B14*100 -> 7.4633399 | F14: 7808 | G14: 7747 | H14: 61 | I14: =H14/F14*100 -> 0.78125 | J14: 7747 | K14: 7666 | L14: 81 | M14: =L14/J14*100 -> 1.045566 | N14: 0 | O14: 824 | P14: =D14+H14+L14+O14 -> 1648 | Q14: 0
A15: 45786 | B15: 10611 | C15: 8845 | D15: 645 | E15: =D15/B15*100 -> 6.0785977 | F15: 7976 | G15: 7917 | H15: 59 | I15: =H15/F15*100 -> 0.73971916 | J15: 7917 | K15: 7879 | L15: 38 | M15: =L15/J15*100 -> 0.47997979 | N15: 6295 | O15: 125 | P15: =D15+H15+L15+O15 -> 867 | Q15: =O15/N15*100 -> 1.9857029
A16: 45787 | B16: 4375 | C16: 4110 | D16: 193 | E16: =D16/B16*100 -> 4.4114286 | F16: 9000 | G16: 8994 | H16: 6 | I16: =H16/F16*100 -> 0.066666667 | J16: 8994 | K16: 8992 | L16: 2 | M16: =L16/J16*100 -> 0.022237047 | N16: 8206 | O16: 188 | P16: =D16+H16+L16+O16 -> 389 | Q16: =O16/N16*100 -> 2.2910066
B17: =SUM(B11:B16) -> 47279 | C17: =SUM(C11:C16) -> 40817 | D17: =SUM(D11:D16) -> 4062 | E17: =D17/B17*100 -> 8.5915523 | F17: =SUM(F11:F16) -> 44389 | G17: =SUM(G11:G16) -> 43917 | H17: =SUM(H11:H16) -> 472 | I17: =H17/F17*100 -> 1.0633265 | J17: =SUM(J11:J16) -> 43917 | K17: =SUM(K11:K16) -> 43420 | L17: =SUM(L11:L16) -> 497 | M17: =L17/J17*100 -> 1.1316802 | N17: =SUM(N11:N16) -> 35473 | O17: =SUM(O11:O16) -> 1739 | P17: =SUM(P11:P16) -> 6770 | Q17: =O17/N17*100 -> 4.9023201
A18: SUNDAY
A19: 45789 | B19: 11451 | C19: 9915 | D19: 1239 | E19: =D19/B19*100 -> 10.820016 | F19: 8485 | G19: 8432 | H19: 53 | I19: =H19/F19*100 -> 0.6246317 | J19: 8432 | K19: 8382 | L19: 50 | M19: =L19/J19*100 -> 0.59297913 | N19: 10289 | O19: 67 | P19: =D19+H19+L19+O19 -> 1409 | Q19: =O19/N19*100 -> 0.65118087 | R19: WEEK 3
A20: 45790 | B20: 10602 | C20: 9560 | D20: 861 | E20: =D20/B20*100 -> 8.1211092 | F20: 10218 | G20: 10134 | H20: 84 | I20: =H20/F20*100 -> 0.82207868 | J20: 10134 | K20: 10076 | L20: 58 | M20: =L20/J20*100 -> 0.57233077 | N20: 9914 | O20: 76 | P20: =D20+H20+L20+O20 -> 1079 | Q20: =O20/N20*100 -> 0.7665927 | R20: =SUM(B19:B24) -> 65704 | S20: =SUM(P19:P24) -> 7031 | T20: =S20/R20*100 -> 10.701023
A21: 45791 | B21: 9696 | C21: 8825 | D21: 675 | E21: =D21/B21*100 -> 6.9616337 | F21: 10056 | G21: 9930 | H21: 126 | I21: =H21/F21*100 -> 1.2529833 | J21: 9930 | K21: 9786 | L21: 144 | M21: =L21/J21*100 -> 1.4501511 | N21: 6499 | O21: 124 | P21: =D21+H21+L21+O21 -> 1069 | Q21: =O21/N21*100 -> 1.9079858
A22: 45792 | B22: 9893 | C22: 8931 | D22: 689 | E22: =D22/B22*100 -> 6.9645204 | F22: 11144 | G22: 11047 | H22: 97 | I22: =H22/F22*100 -> 0.87042355 | J22: 11047 | K22: 10955 | L22: 92 | M22: =L22/J22*100 -> 0.83280529 | N22: 11513 | O22: 305 | P22: =D22+H22+L22+O22 -> 1183 | Q22: =O22/N22*100 -> 2.6491792
A23: 45793 | B23: 11608 | C23: 10757 | D23: 719 | E23: =D23/B23*100 -> 6.1940041 | F23: 10936 | G23: 10791 | H23: 145 | I23: =H23/F23*100 -> 1.3258961 | J23: 10791 | K23: 10651 | L23: 140 | M23: =L23/J23*100 -> 1.2973774 | N23: 9441 | O23: 376 | P23: =D23+H23+L23+O23 -> 1380 | Q23: =O23/N23*100 -> 3.982629
A24: 45794 | B24: 12454 | C24: 11708 | D24: 554 | E24: =D24/B24*100 -> 4.44837 | F24: 11780 | G24: 11702 | H24: 78 | I24: =H24/F24*100 -> 0.66213922 | J24: 11702 | K24: 11558 | L24: 144 | M24: =L24/J24*100 -> 1.2305589 | N24: 13307 | O24: 135 | P24: =D24+H24+L24+O24 -> 911 | Q24: =O24/N24*100 -> 1.0145036
B25: =SUM(B19:B24) -> 65704 | C25: =SUM(C19:C24) -> 59696 | D25: =SUM(D19:D24) -> 4737 | E25: =D25/B25*100 -> 7.2096067 | F25: =SUM(F19:F24) -> 62619 | G25: =SUM(G19:G24) -> 62036 | H25: =SUM(H19:H24) -> 583 | I25: =H25/F25*100 -> 0.93102732 | J25: =SUM(J19:J24) -> 62036 | K25: =SUM(K19:K24) -> 61408 | L25: =SUM(L19:L24) -> 628 | M25: =L25/J25*100 -> 1.0123154 | N25: =SUM(N19:N24) -> 60963 | O25: =SUM(O19:O24) -> 1083 | P25: =SUM(P19:P24) -> 7031 | Q25: =O25/N25*100 -> 1.7764874
A26: SUNDAY
A27: 45796 | B27: 12215 | C27: 11004 | D27: 895 | E27: =D27/B27*100 -> 7.3270569 | F27: 9892 | G27: 9889 | H27: 3 | I27: =H27/F27*100 -> 0.030327537 | J27: 9889 | K27: 9883 | L27: 6 | M27: =L27/J27*100 -> 0.060673476 | N27: 11962 | O27: 385 | P27: =D27+H27+L27+O27 -> 1289 | Q27: =O27/N27*100 -> 3.2185253 | R27: WEEK 4
A28: 45797 | B28: 11397 | C28: 10242 | D28: 892 | E28: =D28/B28*100 -> 7.826621 | F28: 11914 | G28: 11810 | H28: 104 | I28: =H28/F28*100 -> 0.87292261 | J28: 11810 | K28: 11737 | L28: 73 | M28: =L28/J28*100 -> 0.61812024 | N28: 11028 | O28: 816 | P28: =D28+H28+L28+O28 -> 1885 | Q28: =O28/N28*100 -> 7.3993471 | R28: =SUM(B27:B32) -> 71850 | S28: =SUM(P27:P32) -> 8450 | T28: =S28/R28*100 -> 11.760612
A29: 45798 | B29: 10437 | C29: 9557 | D29: 572 | E29: =D29/B29*100 -> 5.4805021 | F29: 10380 | G29: 10328 | H29: 52 | I29: =H29/F29*100 -> 0.50096339 | J29: 10328 | K29: 10287 | L29: 41 | M29: =L29/J29*100 -> 0.39697909 | N29: 12367 | O29: 394 | P29: =D29+H29+L29+O29 -> 1059 | Q29: =O29/N29*100 -> 3.185898
A30: 45799 | B30: 12008 | C30: 10736 | D30: 1074 | E30: =D30/B30*100 -> 8.9440373 | F30: 10200 | G30: 10080 | H30: 120 | I30: =H30/F30*100 -> 1.1764706 | J30: 10080 | K30: 10022 | L30: 58 | M30: =L30/J30*100 -> 0.57539683 | N30: 12549 | O30: 205 | P30: =D30+H30+L30+O30 -> 1457 | Q30: =O30/N30*100 -> 1.6335963
A31: 45800 | B31: 12477 | C31: 11464 | D31: 827 | E31: =D31/B31*100 -> 6.6281959 | F31: 10669 | G31: 10618 | H31: 51 | I31: =H31/F31*100 -> 0.47802043 | J31: 10618 | K31: 10548 | L31: 70 | M31: =L31/J31*100 -> 0.65925786 | N31: 9960 | O31: 186 | P31: =D31+H31+L31+O31 -> 1134 | Q31: =O31/N31*100 -> 1.8674699
A32: 45801 | B32: 13316 | C32: 11691 | D32: 1345 | E32: =D32/B32*100 -> 10.100631 | F32: 10423 | G32: 10360 | H32: 63 | I32: =H32/F32*100 -> 0.60443251 | J32: 10360 | K32: 10277 | L32: 83 | M32: =L32/J32*100 -> 0.8011583 | N32: 8087 | O32: 135 | P32: =D32+H32+L32+O32 -> 1626 | Q32: =O32/N32*100 -> 1.6693459
B33: =SUM(B27:B32) -> 71850 | C33: =SUM(C27:C32) -> 64694 | D33: =SUM(D27:D32) -> 5605 | E33: =D33/B33*100 -> 7.8009743 | F33: =SUM(F27:F32) -> 63478 | G33: =SUM(G27:G32) -> 63085 | H33: =SUM(H27:H32) -> 393 | I33: =H33/F33*100 -> 0.61911213 | J33: =SUM(J27:J32) -> 63085 | K33: =SUM(K27:K32) -> 62754 | L33: =SUM(L27:L32) -> 331 | M33: =L33/J33*100 -> 0.52468891 | N33: =SUM(N27:N32) -> 65953 | O33: =SUM(O27:O32) -> 2121 | P33: =SUM(P27:P32) -> 8450 | Q33: =O33/N33*100 -> 3.2159265
A34: SUNDAY
A35: 45803 | B35: 9199 | C35: 8559 | D35: 415 | E35: =D35/B35*100 -> 4.5113599 | F35: 10141 | G35: 10076 | H35: 65 | I35: =H35/F35*100 -> 0.64096243 | J35: 10076 | K35: 9979 | L35: 97 | M35: =L35/J35*100 -> 0.9626836 | N35: 9686 | O35: 137 | P35: =D35+H35+L35+O35 -> 714 | Q35: =O35/N35*100 -> 1.4144126 | R35: WEEK 5
A36: 45804 | B36: 10687 | C36: 9796 | D36: 610 | E36: =D36/B36*100 -> 5.7078694 | F36: 11162 | G36: 10925 | H36: 237 | I36: =H36/F36*100 -> 2.1232754 | J36: 10309 | K36: 10275 | L36: 34 | M36: =L36/J36*100 -> 0.3298089 | N36: 12118 | O36: 575 | P36: =D36+H36+L36+O36 -> 1456 | Q36: =O36/N36*100 -> 4.7450074 | R36: =SUM(B35:B40) -> 59476 | S36: =SUM(P35:P40) -> 8250 | T36: =S36/R36*100 -> 13.871141
A37: 45805 | B37: 10449 | C37: 9854 | D37: 341 | E37: =D37/B37*100 -> 3.2634702 | F37: 9310 | G37: 9305 | H37: 5 | I37: =H37/F37*100 -> 0.053705693 | J37: 11243 | K37: 11079 | L37: 164 | M37: =L37/J37*100 -> 1.4586854 | N37: 6202 | O37: 204 | P37: =D37+H37+L37+O37 -> 714 | Q37: =O37/N37*100 -> 3.2892615
A38: 45806 | B38: 10095 | C38: 9067 | D38: 651 | E38: =D38/B38*100 -> 6.448737 | F38: 9675 | G38: 9570 | H38: 105 | I38: =H38/F38*100 -> 1.0852713 | J38: 11354 | K38: 11211 | L38: 143 | M38: =L38/J38*100 -> 1.259468 | N38: 10157 | O38: 552 | P38: =D38+H38+L38+O38 -> 1451 | Q38: =O38/N38*100 -> 5.4346756
A39: 45807 | B39: 8512 | C39: 7543 | D39: 744 | E39: =D39/B39*100 -> 8.7406015 | F39: 10710 | G39: 10631 | H39: 79 | I39: =H39/F39*100 -> 0.73762838 | J39: 10524 | K39: 10393 | L39: 131 | M39: =L39/J39*100 -> 1.2447739 | N39: 13000 | O39: 1426 | P39: =D39+H39+L39+O39 -> 2380 | Q39: =O39/N39*100 -> 10.969231
A40: 45808 | B40: 10534 | C40: 9462 | D40: 633 | E40: =D40/B40*100 -> 6.0091133 | F40: 10299 | G40: 10234 | H40: 65 | I40: =H40/F40*100 -> 0.63112924 | J40: 10230 | K40: 9839 | L40: 391 | M40: =L40/J40*100 -> 3.8220919 | N40: 13914 | O40: 446 | P40: =D40+H40+L40+O40 -> 1535 | Q40: =O40/N40*100 -> 3.2054046
B41: =SUM(B35:B40) -> 59476 | C41: =SUM(C35:C40) -> 54281 | D41: =SUM(D35:D40) -> 3394 | E41: =D41/B41*100 -> 5.7065035 | F41: =SUM(F35:F40) -> 61297 | G41: =SUM(G35:G40) -> 60741 | H41: =SUM(H35:H40) -> 556 | I41: =H41/F41*100 -> 0.90705907 | J41: =SUM(J35:J40) -> 63736 | K41: =SUM(K35:K40) -> 62776 | L41: =SUM(L35:L40) -> 960 | M41: =L41/J41*100 -> 1.5062131 | N41: =SUM(N35:N40) -> 65077 | O41: =SUM(O35:O40) -> 3340 | P41: =SUM(P34:P40) -> 8250 | Q41: =O41/N41*100 -> 5.1323816
A42: Total | B42: =B41+B33+B25+B17+B9 -> 260869 | C42: =C41+C33+C25+C17+C9 -> 232205 | D42: =D41+D33+D25+D17+D9 -> 18798 | E42: =D42/B42*100 -> 7.2059156 | F42: =F41+F33+F25+F17+F9 -> 248862 | G42: =G41+G33+G25+G17+G9 -> 246681 | H42: =H41+H33+H25+H17+H9 -> 2181 | I42: =H42/F42*100 -> 0.87638932 | J42: =J41+J33+J25+J17+J9 -> 249676 | K42: =K41+K33+K25+K17+K9 -> 247066 | L42: =L41+L33+L25+L17+L9 -> 2582 | M42: =L42/J42*100 -> 1.0341402 | N42: =N41+N33+N25+N17+N9 -> 246011 | O42: =O41+O33+O25+O17+O9 -> 8460 | P42: =D42+H42+L42+O42 -> 32021 | Q42: =O42/N42*100 -> 3.4388706

Sheet JUNE 25
C1: DISPOSAFE HEALTH AND LIFE CARE LIMITED Plot No.37A, Sector-06, Ballabgarh (Faridabad) Haryana India 121006
A3: ASSEMBLY SECTION DAILY REJECTION REPORT FOR JUNE 25
A4: DATE | B4: VISUAL QTY | C4: VISUAL ACPT QTY | D4: REJ QTY | E4: REJ % | F4: BALLOON CHKD QTY | G4: BALLOON ACPT QTY | H4: REJ QTY | I4: REJ % | J4: VALVE INT CHKD QTY | K4: VALVE INTY ACPT QTY | L4: VALVE INTY REJ Qty | M4: REJ % | N4: FINAL CHECKED QTY | O4: FINAL REJECTION | P4: TOTAL REJ QTY | Q4: FINAL REJ % | R4: VISUAL CHECKED QTY | S4: VISUAL REJ QTY | T4: VISUAL REJ %
A6: 45809
A7: 45810 | B7: 10616 | C7: 8689 | D7: 345 | E7: =D7/B7*100 -> 3.2498116 | F7: 10047 | G7: 9713 | H7: 334 | I7: =H7/F7*100 -> 3.3243754 | J7: 10226 | K7: 10004 | L7: 222 | M7: =L7/J7*100 -> 2.1709368 | N7: 10346 | O7: 419 | P7: =D7+H7+L7+O7 -> 1320 | Q7: =O7/N7*100 -> 4.0498743 | R7: WEEK 1
A8: 45811 | B8: 7134 | C8: 6284 | D8: 545 | E8: =D8/B8*100 -> 7.6394729 | F8: 9465 | G8: 9361 | H8: 104 | I8: =H8/F8*100 -> 1.098785 | J8: 10626 | K8: 10477 | L8: 149 | M8: =L8/J8*100 -> 1.402221 | N8: 8448 | O8: 518 | P8: =D8+H8+L8+O8 -> 1316 | Q8: =O8/N8*100 -> 6.1316288 | R8: =SUM(B6:B12) -> 58931 | S8: =SUM(P6:P12) -> 8390 | T8: =S8/R8*100 -> 14.236989
A9: 45812 | B9: 8882 | C9: 7866 | D9: 717 | E9: =D9/B9*100 -> 8.0725062 | F9: 10582 | G9: 10541 | H9: 41 | I9: =H9/F9*100 -> 0.38745039 | J9: 9907 | K9: 9459 | L9: 448 | M9: =L9/J9*100 -> 4.5220551 | N9: 9850 | O9: 625 | P9: =D9+H9+L9+O9 -> 1831 | Q9: =O9/N9*100 -> 6.3451777
A10: 45813 | B10: 10963 | C10: 9942 | D10: 691 | E10: =D10/B10*100 -> 6.3030192 | F10: 9649 | G10: 9603 | H10: 46 | I10: =H10/F10*100 -> 0.47673334 | J10: 12699 | K10: 11918 | L10: 781 | M10: =L10/J10*100 -> 6.1500906 | N10: 11329 | O10: 115 | P10: =D10+H10+L10+O10 -> 1633 | Q10: =O10/N10*100 -> 1.015094
A11: 45814 | B11: 9576 | C11: 8635 | D11: 559 | E11: =D11/B11*100 -> 5.8375104 | F11: 10226 | G11: 10169 | H11: 57 | I11: =H11/F11*100 -> 0.5574027 | J11: 11489 | K11: 11272 | L11: 217 | M11: =L11/J11*100 -> 1.8887632 | N11: 12241 | O11: 137 | P11: =D11+H11+L11+O11 -> 970 | Q11: =O11/N11*100 -> 1.1191896
A12: 45815 | B12: 11760 | C12: 10625 | D12: 850 | E12: =D12/B12*100 -> 7.2278912 | F12: 10346 | G12: 10290 | H12: 56 | I12: =H12/F12*100 -> 0.54127199 | J12: 10290 | K12: 9979 | L12: 311 | M12: =L12/J12*100 -> 3.0223518 | N12: 11689 | O12: 103 | P12: =D12+H12+L12+O12 -> 1320 | Q12: =O12/N12*100 -> 0.88117033
A13: W. REPORT | B13: =SUM(B6:B12) -> 58931 | C13: =SUM(C6:C12) -> 52041 | D13: =SUM(D6:D12) -> 3707 | E13: =D13/B13*100 -> 6.2904074 | F13: =SUM(F6:F12) -> 60315 | G13: =SUM(G6:G12) -> 59677 | H13: =SUM(H6:H12) -> 638 | I13: =H13/F13*100 -> 1.05778 | J13: =SUM(J6:J12) -> 65237 | K13: =SUM(K6:K12) -> 63109 | L13: =SUM(L6:L12) -> 2128 | M13: =L13/J13*100 -> 3.2619526 | N13: =SUM(N7:N12) -> 63903 | O13: =SUM(O6:O12) -> 1917 | P13: =SUM(P6:P12) -> 8390 | Q13: =O13/N13*100 -> 2.9998592
A14: 45816
A15: 45817 | B15: 11133 | C15: 10220 | D15: 578 | E15: =D15/B15*100 -> 5.1917722 | F15: 10892 | G15: 10805 | H15: 87 | I15: =H15/F15*100 -> 0.79875138 | J15: 10805 | K15: 10679 | L15: 126 | M15: =L15/J15*100 -> 1.1661268 | N15: 9170 | O15: 63 | P15: =D15+H15+L15+O15 -> 854 | Q15: =O15/N15*100 -> 0.6870229 | R15: WEEK 2
A16: 45818 | B16: 10733 | C16: 9642 | D16: 547 | E16: =D16/B16*100 -> 5.0964316 | F16: 10481 | G16: 10065 | H16: 416 | I16: =H16/F16*100 -> 3.9690869 | J16: 10065 | K16: 9453 | L16: 612 | M16: =L16/J16*100 -> 6.0804769 | N16: 11040 | O16: 108 | P16: =D16+H16+L16+O16 -> 1683 | Q16: =O16/N16*100 -> 0.97826087 | R16: =SUM(B15:B20) -> 63488 | S16: =SUM(P15:P20) -> 7742 | T16: =S16/R16*100 -> 12.19443
A17: 45819 | B17: 11697 | C17: 10146 | D17: 1164 | E17: =D17/B17*100 -> 9.9512696 | F17: 10274 | G17: 10168 | H17: 106 | I17: =H17/F17*100 -> 1.0317306 | J17: 10168 | K17: 9882 | L17: 286 | M17: =L17/J17*100 -> 2.8127459 | N17: 9882 | O17: 175 | P17: =D17+H17+L17+O17 -> 1731 | Q17: =O17/N17*100 -> 1.7708966
A18: 45820 | B18: 10553 | C18: 10112 | D18: 415 | E18: =D18/B18*100 -> 3.932531 | F18: 10118 | G18: 10071 | H18: 47 | I18: =H18/F18*100 -> 0.46451868 | J18: 10071 | K18: 9696 | L18: 321 | M18: =L18/J18*100 -> 3.1873697 | N18: 9752 | O18: 153 | P18: =D18+H18+L18+O18 -> 936 | Q18: =O18/N18*100 -> 1.5689089
A19: 45821 | B19: 9505 | C19: 8630 | D19: 669 | E19: =D19/B19*100 -> 7.0384008 | F19: 10789 | G19: 10715 | H19: 74 | I19: =H19/F19*100 -> 0.68588377 | J19: 10715 | K19: 10386 | L19: 329 | M19: =L19/J19*100 -> 3.070462 | N19: 10386 | O19: 190 | P19: =D19+H19+L19+O19 -> 1262 | Q19: =O19/N19*100 -> 1.8293857
A20: 45822 | B20: 9867 | C20: 9319 | D20: 548 | E20: =D20/B20*100 -> 5.5538664 | F20: 10431 | G20: 10349 | H20: 82 | I20: =H20/F20*100 -> 0.7861183 | J20: 10349 | K20: 9878 | L20: 471 | M20: =L20/J20*100 -> 4.5511644 | N20: 9878 | O20: 175 | P20: =D20+H20+L20+O20 -> 1276 | Q20: =O20/N20*100 -> 1.7716137
A21: W. REPORT | B21: =SUM(B15:B20) -> 63488 | C21: =SUM(C15:C20) -> 58069 | D21: =SUM(D15:D20) -> 3921 | E21: =D21/B21*100 -> 6.1759703 | F21: =SUM(F15:F20) -> 62985 | G21: =SUM(G15:G20) -> 62173 | H21: =SUM(H15:H20) -> 812 | I21: =H21/F21*100 -> 1.2891958 | J21: =SUM(J15:J20) -> 62173 | K21: =SUM(K15:K20) -> 59974 | L21: =SUM(L15:L20) -> 2145 | M21: =L21/J21*100 -> 3.4500507 | N21: =SUM(N15:N20) -> 60108 | O21: =SUM(O15:O20) -> 864 | P21: =SUM(P15:P20) -> 7742 | Q21: =O21/N21*100 -> 1.4374127
A22: 45823
A23: 45824 | B23: 11497 | C23: 10483 | D23: 614 | E23: =D23/B23*100 -> 5.3405236 | F23: 10851 | G23: 10808 | H23: 43 | I23: =H23/F23*100 -> 0.39627684 | J23: 10808 | K23: 10613 | L23: 285 | M23: =L23/J23*100 -> 2.6369356 | N23: 10613 | O23: 119 | P23: =D23+H23+L23+O23 -> 1061 | Q23: =O23/N23*100 -> 1.1212664 | R23: WEEK 3
A24: 45825 | B24: 11226 | C24: 10107 | D24: 795 | E24: =D24/B24*100 -> 7.0817745 | F24: 9506 | G24: 9446 | H24: 60 | I24: =H24/F24*100 -> 0.63118031 | J24: 9446 | K24: 9179 | L24: 267 | M24: =L24/J24*100 -> 2.8265933 | N24: 9187 | O24: 138 | P24: =D24+H24+L24+O24 -> 1260 | Q24: =O24/N24*100 -> 1.5021226 | R24: =SUM(B23:B28) -> 64667 | S24: =SUM(P23:P28) -> 6600 | T24: =S24/R24*100 -> 10.206133
A25: 45826 | B25: 10787 | C25: 9862 | D25: 615 | E25: =D25/B25*100 -> 5.7013071 | F25: 10137 | G25: 10073 | H25: 64 | I25: =H25/F25*100 -> 0.6313505 | J25: 10073 | K25: 9846 | L25: 227 | M25: =L25/J25*100 -> 2.2535491 | N25: 11019 | O25: 148 | P25: =D25+H25+L25+O25 -> 1054 | Q25: =O25/N25*100 -> 1.3431346
A26: 45827 | B26: 11204 | C26: 10148 | D26: 532 | E26: =D26/B26*100 -> 4.7483042 | F26: 12684 | G26: 12635 | H26: 49 | I26: =H26/F26*100 -> 0.38631347 | J26: 12635 | K26: 12284 | L26: 351 | M26: =L26/J26*100 -> 2.7779976 | N26: 11111 | O26: 94 | P26: =D26+H26+L26+O26 -> 1026 | Q26: =O26/N26*100 -> 0.84600846
A27: 45828 | B27: 9384 | C27: 8614 | D27: 556 | E27: =D27/B27*100 -> 5.9249787 | F27: 11697 | G27: 11592 | H27: 105 | I27: =H27/F27*100 -> 0.89766607 | J27: 11592 | K27: 11114 | L27: 478 | M27: =L27/J27*100 -> 4.1235335 | N27: 9767 | O27: 133 | P27: =D27+H27+L27+O27 -> 1272 | Q27: =O27/N27*100 -> 1.3617283
A28: 45829 | B28: 10569 | C28: 9860 | D28: 450 | E28: =D28/B28*100 -> 4.2577349 | F28: 12405 | G28: 12340 | H28: 65 | I28: =H28/F28*100 -> 0.52398227 | J28: 12340 | K28: 12066 | L28: 274 | M28: =L28/J28*100 -> 2.2204214 | N28: 11117 | O28: 138 | P28: =D28+H28+L28+O28 -> 927 | Q28: =O28/N28*100 -> 1.2413421
A29: W. REPORT | B29: =SUM(B23:B28) -> 64667 | C29: =SUM(C23:C28) -> 59074 | D29: =SUM(D23:D28) -> 3562 | E29: =D29/B29*100 -> 5.508219 | F29: =SUM(F23:F28) -> 67280 | G29: =SUM(G23:G28) -> 66894 | H29: =SUM(H23:H28) -> 386 | I29: =H29/F29*100 -> 0.57372176 | J29: =SUM(J23:J28) -> 66894 | K29: =SUM(K23:K28) -> 65102 | L29: =SUM(L23:L28) -> 1882 | M29: =L29/J29*100 -> 2.8134063 | N29: =SUM(N23:N28) -> 62814 | O29: =SUM(O23:O28) -> 770 | P29: =SUM(P23:P28) -> 6600 | Q29: =O29/N29*100 -> 1.2258414
A30: 45830 | B30: 10013 | C30: 9544 | D30: 305 | E30: =D30/B30*100 -> 3.0460401 | F30: 10383 | G30: 10358 | H30: 25 | I30: =H30/F30*100 -> 0.2407782 | J30: 8140 | K30: 7625 | L30: 515 | M30: =L30/J30*100 -> 6.3267813 | N30: 8410 | O30: 146 | P30: =D30+H30+L30+O30 -> 991
A31: 45831 | B31: 12989 | C31: 12288 | D31: 383 | E31: =D31/B31*100 -> 2.9486489 | F31: 11300 | G31: 11240 | H31: 60 | I31: =H31/F31*100 -> 0.53097345 | J31: 12218 | K31: 11602 | L31: 616 | M31: =L31/J31*100 -> 5.0417417 | N31: 8410 | O31: 151 | P31: =D31+H31+L31+O31 -> 1210 | Q31: =O31/N31*100 -> 1.7954816 | R31: WEEK 4
A32: 45832 | B32: 11910 | C32: 10958 | D32: 703 | E32: =D32/B32*100 -> 5.9026029 | F32: 10261 | G32: 10218 | H32: 43 | I32: =H32/F32*100 -> 0.41906247 | J32: 10458 | K32: 10236 | L32: 222 | M32: =L32/J32*100 -> 2.1227768 | N32: 13221 | O32: 116 | P32: =D32+H32+L32+O32 -> 1084 | Q32: =O32/N32*100 -> 0.87739203 | R32: =SUM(B30:B36) -> 84222 | S32: =SUM(P30:P36) -> 7460 | T32: =S32/R32*100 -> 8.8575432
A33: 45833 | B33: 11260 | C33: 10404 | D33: 680 | E33: =D33/B33*100 -> 6.0390764 | F33: 10758 | G33: 10730 | H33: 28 | I33: =H33/F33*100 -> 0.26027143 | J33: 10745 | K33: 10624 | L33: 121 | M33: =L33/J33*100 -> 1.1261052 | N33: 9246 | O33: 276 | P33: =D33+H33+L33+O33 -> 1105 | Q33: =O33/N33*100 -> 2.9850746
A34: 45834 | B34: 12886 | C34: 12069 | D34: 587 | E34: =D34/B34*100 -> 4.5553314 | F34: 9518 | G34: 9497 | H34: 21 | I34: =H34/F34*100 -> 0.22063459 | J34: 10491 | K34: 10367 | L34: 124 | M34: =L34/J34*100 -> 1.1819655 | N34: 7324 | O34: 191 | P34: =D34+H34+L34+O34 -> 923 | Q34: =O34/N34*100 -> 2.6078646
A35: 45835 | B35: 11844 | C35: 11028 | D35: 656 | E35: =D35/B35*100 -> 5.5386694 | F35: 13746 | G35: 13720 | H35: 26 | I35: =H35/F35*100 -> 0.18914593 | J35: 12720 | K35: 12609 | L35: 111 | M35: =L35/J35*100 -> 0.87264151 | N35: 11894 | O35: 159 | P35: =D35+H35+L35+O35 -> 952 | Q35: =O35/N35*100 -> 1.3368085
A36: 45836 | B36: 13320 | C36: 12255 | D36: 832 | E36: =D36/B36*100 -> 6.2462462 | F36: 11974 | G36: 11940 | H36: 34 | I36: =H36/F36*100 -> 0.28394856 | J36: 11940 | K36: 11809 | L36: 131 | M36: =L36/J36*100 -> 1.0971524 | N36: 12796 | O36: 198 | P36: =D36+H36+L36+O36 -> 1195 | Q36: =O36/N36*100 -> 1.5473585
A37: W. REPORT | B37: =SUM(B30:B36) -> 84222 | C37: =SUM(C30:C36) -> 78546 | D37: =SUM(D30:D36) -> 4146 | E37: =D37/B37*100 -> 4.9227043 | F37: =SUM(F30:F36) -> 77940 | G37: =SUM(G30:G36) -> 77703 | H37: =SUM(H30:H36) -> 237 | I37: =H37/F37*100 -> 0.30408006 | J37: =SUM(J30:J36) -> 76712 | K37: =SUM(K30:K36) -> 74872 | L37: =SUM(L30:L36) -> 1840 | M37: =L37/J37*100 -> 2.3985817 | N37: =SUM(N30:N36) -> 71301 | O37: =SUM(O30:O36) -> 1237 | P37: =SUM(P30:P36) -> 7460 | Q37: =O37/N37*100 -> 1.7348985
A38: 45837
A39: 45838 | B39: 8224 | C39: 7455 | D39: 536 | E39: =D39/B39*100 -> 6.5175097 | F39: 12690 | G39: 12672 | H39: 18 | I39: =H39/F39*100 -> 0.14184397 | J39: 12888 | K39: 12790 | L39: 98 | M39: =L39/J39*100 -> 0.76039727 | N39: 8172 | O39: 110 | P39: =D39+H39+L39+O39 -> 762 | Q39: =O39/N39*100 -> 1.3460597 | R39: WEEK 5
A40: W. REPORT | B40: =SUM(B39:B39) -> 8224 | C40: =SUM(C39:C39) -> 7455 | D40: =SUM(D39:D39) -> 536 | E40: =D40/B40*100 -> 6.5175097 | F40: =SUM(F39:F39) -> 12690 | G40: =SUM(G39:G39) -> 12672 | H40: =SUM(H39:H39) -> 18 | I40: =H40/F40*100 -> 0.14184397 | J40: =SUM(J39:J39) -> 12888 | K40: =SUM(K39:K39) -> 12790 | L40: =SUM(L39:L39) -> 98 | M40: =L40/J40*100 -> 0.76039727 | N40: =N39 -> 8172 | O40: =SUM(O39:O39) -> 110 | P40: =SUM(P38:P39) -> 762 | Q40: =O40/N40*100 -> 1.3460597 | R40: =B39 -> 8224 | S40: =P39 -> 762 | T40: =S40/R40*100 -> 9.2655642
A41: Total | B41: =B40+B37+B29+B21+B13 -> 279532 | C41: =C40+C37+C29+C21+C13 -> 255185 | D41: =D40+D37+D29+D21+D13 -> 15872 | E41: =D41/B41*100 -> 5.6780619 | F41: =F40+F37+F29+F21+F13 -> 281210 | G41: =G40+G37+G29+G21+G13 -> 279119 | H41: =H40+H37+H29+H21+H13 -> 2091 | I41: =H41/F41*100 -> 0.74357242 | J41: =J40+J37+J29+J21+J13 -> 283904 | K41: =K40+K37+K29+K21+K13 -> 275847 | L41: =L40+L37+L29+L21+L13 -> 8093 | M41: =L41/J41*100 -> 2.8506115 | N41: =N40+N37+N29+N21+N13 -> 266298 | O41: =O40+O37+O29+O21+O13 -> 4898 | P41: =D41+H41+L41+O41 -> 30954 | Q41: =O41/N41*100 -> 1.8392928

Sheet JULY 25
C1: DISPOSAFE HEALTH AND LIFE CARE LIMITED Plot No.37A, Sector-06, Ballabgarh (Faridabad) Haryana India 121006
A3: ASSEMBLY SECTION DAILY REJECTION REPORT FOR JULY 25
A4: DATE | B4: VISUAL QTY | C4: VISUAL ACPT QTY | D4: REJ QTY | E4: REJ % | F4: BALLOON CHKD QTY | G4: BALLOON ACPT QTY | H4: REJ QTY | I4: REJ % | J4: VALVE INT CHKD QTY | K4: VALVE INTY ACPT QTY | L4: VALVE INTY REJ Qty | M4: REJ % | N4: FINAL CHECKED QTY | O4: FINAL REJECTION | P4: TOTAL REJ QTY | Q4: FINAL REJ % | R4: VISUAL CHECKED QTY | S4: VISUAL REJ QTY | T4: VISUAL REJ %
A6: 45839 | B6: 7482 | C6: 6049 | D6: 951 | E6: =D6/B6*100 -> 12.710505 | F6: 11448 | G6: 11387 | H6: 61 | I6: =H6/F6*100 -> 0.53284416 | J6: 12387 | K6: 12234 | L6: 153 | M6: =L6/J6*100 -> 1.2351659 | N6: 11653 | O6: 355 | P6: =D6+H6+L6+O6 -> 1520 | Q6: =O6/N6*100 -> 3.0464258 | R6: WEEK 1
A7: 45840 | B7: 13349 | C7: 11022 | D7: 975 | E7: =D7/B7*100 -> 7.3039179 | F7: 12083 | G7: 12049 | H7: 34 | I7: =H7/F7*100 -> 0.28138707 | J7: 12049 | K7: 11972 | L7: 77 | M7: =L7/J7*100 -> 0.63905718 | N7: 11916 | O7: 281 | P7: =D7+H7+L7+O7 -> 1367 | Q7: =O7/N7*100 -> 2.3581739 | R7: =SUM(B6:B10) -> 54720 | S7: =SUM(P6:P10) -> 6577 | T7: =S7/R7*100 -> 12.019371
A8: 45841 | B8: 10643 | C8: 9232 | D8: 992 | E8: =D8/B8*100 -> 9.3206803 | F8: 9565 | G8: 9498 | H8: 67 | I8: =H8/F8*100 -> 0.70047047 | J8: 9498 | K8: 9362 | L8: 136 | M8: =L8/J8*100 -> 1.4318804 | N8: 9904 | O8: 330 | P8: =D8+H8+L8+O8 -> 1525 | Q8: =O8/N8*100 -> 3.3319871
A9: 45842 | B9: 13078 | C9: 11892 | D9: 795 | E9: =D9/B9*100 -> 6.0789111 | F9: 11248 | G9: 11193 | H9: 55 | I9: =H9/F9*100 -> 0.48897582 | J9: 11193 | K9: 11002 | L9: 191 | M9: =L9/J9*100 -> 1.7064237 | N9: 11718 | O9: 351 | P9: =D9+H9+L9+O9 -> 1392 | Q9: =O9/N9*100 -> 2.9953917
A10: 45843 | B10: 10168 | C10: 9749 | D10: 561 | E10: =D10/B10*100 -> 5.5173092 | F10: 12619 | G10: 12578 | H10: 41 | I10: =H10/F10*100 -> 0.32490689 | J10: 12578 | K10: 12501 | L10: 77 | M10: =L10/J10*100 -> 0.61218 | N10: 10890 | O10: 94 | P10: =D10+H10+L10+O10 -> 773 | Q10: =O10/N10*100 -> 0.86317723
A11: W. REPORT | B11: =SUM(B6:B10) -> 54720 | C11: =SUM(C6:C10) -> 47944 | D11: =SUM(D6:D10) -> 4274 | E11: =D11/B11*100 -> 7.8106725 | F11: =SUM(F6:F10) -> 56963 | G11: =SUM(G6:G10) -> 56705 | H11: =SUM(H6:H10) -> 258 | I11: =H11/F11*100 -> 0.45292558 | J11: =SUM(J6:J10) -> 57705 | K11: =SUM(K6:K10) -> 57071 | L11: =SUM(L6:L10) -> 634 | M11: =L11/J11*100 -> 1.0986916 | N11: =SUM(N6:N10) -> 56081 | O11: =SUM(O6:O10) -> 1411 | P11: =SUM(P6:P10) -> 6577 | Q11: =O11/N11*100 -> 2.5160036
A12: 45844 | B12: 0 | C12: 0 | D12: 0 | E12: =D12/B12*100 -> #DIV/0! | F12: 0 | G12: 0 | H12: 0 | I12: =H12/F12*100 -> #DIV/0! | J12: 0 | K12: 0 | L12: 0 | M12: =L12/J12*100 -> #DIV/0! | N12: 0 | O12: 0 | P12: 0 | Q12: 0 | R12: WEEK 2
A13: 45845 | B13: 9058 | C13: 7949 | D13: 691 | E13: =D13/B13*100 -> 7.6286156 | F13: 11752 | G13: 11737 | H13: 15 | I13: =H13/F13*100 -> 0.12763785 | J13: 10644 | K13: 10578 | L13: 66 | M13: =L13/J13*100 -> 0.62006764 | N13: 7121 | O13: 157 | P13: =D13+H13+L13+O13 -> 929 | Q13: =O13/N13*100 -> 2.2047465 | R13: =SUM(B12:B18) -> 62326 | S13: =SUM(P12:P18) -> 5550 | T13: =S13/R13*100 -> 8.9047909
A14: 45846 | B14: 9811 | C14: 8359 | D14: 1093 | E14: =D14/B14*100 -> 11.140557 | F14: 11153 | G14: 11121 | H14: 32 | I14: =H14/F14*100 -> 0.28691832 | J14: 10945 | K14: 10902 | L14: 43 | M14: =L14/J14*100 -> 0.39287346 | N14: 8778 | O14: 147 | P14: =D14+H14+L14+O14 -> 1315 | Q14: =O14/N14*100 -> 1.6746411
A15: 45847 | B15: 11534 | C15: 10670 | D15: 674 | E15: =D15/B15*100 -> 5.8435929 | F15: 11394 | G15: 11364 | H15: 30 | I15: =H15/F15*100 -> 0.26329647 | J15: 10366 | K15: 10319 | L15: 47 | M15: =L15/J15*100 -> 0.45340536 | N15: 0 | O15: 0 | P15: =D15+H15+L15+O15 -> 751 | Q15: 0
A16: 45848 | B16: 10445 | C16: 9505 | D16: 773 | E16: =D16/B16*100 -> 7.4006702 | F16: 9652 | G16: 9611 | H16: 41 | I16: =H16/F16*100 -> 0.42478243 | J16: 8804 | K16: 8692 | L16: 102 | M16: =L16/J16*100 -> 1.1585643 | N16: 8804 | O16: 112 | P16: =D16+H16+L16+O16 -> 1028 | Q16: =O16/N16*100 -> 1.272149
A17: 45849 | B17: 10340 | C17: 9422 | D17: 590 | E17: =D17/B17*100 -> 5.7059961 | F17: 10694 | G17: 10661 | H17: 33 | I17: =H17/F17*100 -> 0.30858425 | J17: 10661 | K17: 10592 | L17: 69 | M17: =L17/J17*100 -> 0.64721884 | N17: 7581 | O17: 55 | P17: =D17+H17+L17+O17 -> 747 | Q17: =O17/N17*100 -> 0.72549796
A18: 45850 | B18: 11138 | C18: 10176 | D18: 612 | E18: =D18/B18*100 -> 5.4947028 | F18: 11488 | G18: 11447 | H18: 41 | I18: =H18/F18*100 -> 0.35689415 | J18: 11447 | K18: 11367 | L18: 80 | M18: =L18/J18*100 -> 0.69887307 | N18: 6929 | O18: 47 | P18: =D18+H18+L18+O18 -> 780 | Q18: =O18/N18*100 -> 0.67830856
A19: W. REPORT | B19: =SUM(B12:B18) -> 62326 | C19: =SUM(C12:C18) -> 56081 | D19: =SUM(D12:D18) -> 4433 | E19: =D19/B19*100 -> 7.1126015 | F19: =SUM(F12:F18) -> 66133 | G19: =SUM(G12:G18) -> 65941 | H19: =SUM(H12:H18) -> 192 | I19: =H19/F19*100 -> 0.29032404 | J19: =SUM(J12:J18) -> 62867 | K19: =SUM(K12:K18) -> 62450 | L19: =SUM(L12:L18) -> 407 | M19: =L19/J19*100 -> 0.64739848 | N19: =SUM(N13:N18) -> 39213 | O19: =SUM(O12:O18) -> 518 | P19: =SUM(P12:P18) -> 5550 | Q19: =O19/N19*100 -> 1.3209905
A20: 45851 | B20: 0 | C20: 0 | D20: 0 | E20: =D20/B20*100 -> #DIV/0! | F20: 0 | G20: 0 | H20: 0 | I20: =H20/F20*100 -> #DIV/0! | J20: 0 | K20: 0 | L20: 0 | M20: =L20/J20*100 -> #DIV/0! | N20: 0 | O20: 0 | P20: 0 | Q20: 0 | R20: WEEK 3
A21: 45852 | B21: 11290 | C21: 10305 | D21: 600 | E21: =D21/B21*100 -> 5.3144376 | F21: 9998 | G21: 9971 | H21: 27 | I21: =H21/F21*100 -> 0.27005401 | J21: 9971 | K21: 9948 | L21: 23 | M21: =L21/J21*100 -> 0.23066894 | N21: 11194 | O21: 365 | P21: =D21+H21+L21+O21 -> 1015 | Q21: =O21/N21*100 -> 3.2606754 | R21: =SUM(B20:B26) -> 67389 | S21: =SUM(P20:P26) -> 4956 | T21: =S21/R21*100 -> 7.354316
A22: 45853 | B22: 11943 | C22: 11116 | D22: 572 | E22: =D22/B22*100 -> 4.7894164 | F22: 10458 | G22: 10422 | H22: 36 | I22: =H22/F22*100 -> 0.34423408 | J22: 10422 | K22: 10371 | L22: 51 | M22: =L22/J22*100 -> 0.48934945 | N22: 9906 | O22: 92 | P22: =D22+H22+L22+O22 -> 751 | Q22: =O22/N22*100 -> 0.92873006
A23: 45854 | B23: 9674 | C23: 9005 | D23: 604 | E23: =D23/B23*100 -> 6.2435394 | F23: 10839 | G23: 10766 | H23: 73 | I23: =H23/F23*100 -> 0.67349386 | J23: 10766 | K23: 10686 | L23: 80 | M23: =L23/J23*100 -> 0.74308007 | N23: 12771 | O23: 88 | P23: =D23+H23+L23+O23 -> 845 | Q23: =O23/N23*100 -> 0.68906115
A24: 45855 | B24: 10096 | C24: 9429 | D24: 603 | E24: =D24/B24*100 -> 5.9726624 | F24: 12473 | G24: 12456 | H24: 17 | I24: =H24/F24*100 -> 0.1362944 | J24: 12456 | K24: 12381 | L24: 75 | M24: =L24/J24*100 -> 0.60211946 | N24: 8783 | O24: 91 | P24: =D24+H24+L24+O24 -> 786 | Q24: =O24/N24*100 -> 1.0360925
A25: 45856 | B25: 12103 | C25: 11421 | D25: 525 | E25: =D25/B25*100 -> 4.3377675 | F25: 11421 | G25: 11396 | H25: 25 | I25: =H25/F25*100 -> 0.21889502 | J25: 11396 | K25: 11378 | L25: 18 | M25: =L25/J25*100 -> 0.15795016 | N25: 13437 | O25: 195 | P25: =D25+H25+L25+O25 -> 763 | Q25: =O25/N25*100 -> 1.4512168
A26: 45857 | B26: 12283 | C26: 11507 | D26: 555 | E26: =D26/B26*100 -> 4.5184401 | F26: 10557 | G26: 10520 | H26: 37 | I26: =H26/F26*100 -> 0.35047836 | J26: 10520 | K26: 10500 | L26: 20 | M26: =L26/J26*100 -> 0.19011407 | N26: 9082 | O26: 184 | P26: =D26+H26+L26+O26 -> 796 | Q26: =O26/N26*100 -> 2.0259855
A27: W. REPORT | B27: =SUM(B20:B26) -> 67389 | C27: =SUM(C20:C26) -> 62783 | D27: =SUM(D20:D26) -> 3459 | E27: =D27/B27*100 -> 5.1328852 | F27: =SUM(F20:F26) -> 65746 | G27: =SUM(G20:G26) -> 65531 | H27: =SUM(H20:H26) -> 215 | I27: =H27/F27*100 -> 0.32701609 | J27: =SUM(J20:J26) -> 65531 | K27: =SUM(K20:K26) -> 65264 | L27: =SUM(L20:L26) -> 267 | M27: =L27/J27*100 -> 0.40744075 | N27: =SUM(N20:N26) -> 65173 | O27: =SUM(O20:O26) -> 1015 | P27: =SUM(P20:P26) -> 4956 | Q27: =O27/N27*100 -> 1.5573934
A28: 45858 | B28: 0 | C28: 0 | D28: 0 | E28: =D28/B28*100 -> #DIV/0! | F28: 0 | G28: 0 | H28: 0 | I28: =H28/F28*100 -> #DIV/0! | J28: 0 | K28: 0 | L28: 0 | M28: =L28/J28*100 -> #DIV/0! | N28: 0 | O28: 0 | P28: 0 | Q28: 0 | R28: WEEK 4
A29: 45859 | B29: 10884 | C29: 10120 | D29: 424 | E29: =D29/B29*100 -> 3.8956266 | F29: 11070 | G29: 11041 | H29: 29 | I29: =H29/F29*100 -> 0.26196929 | J29: 11041 | K29: 11012 | L29: 29 | M29: =L29/J29*100 -> 0.26265737 | N29: 9853 | O29: 102 | P29: =D29+H29+L29+O29 -> 584 | Q29: =O29/N29*100 -> 1.0352177 | R29: =SUM(B28:B34) -> 83377 | S29: =SUM(P28:P34) -> 4505 | T29: =S29/R29*100 -> 5.4031687
A30: 45860 | B30: 14229 | C30: 13366 | D30: 581 | E30: =D30/B30*100 -> 4.0832103 | F30: 13366 | G30: 13349 | H30: 17 | I30: =H30/F30*100 -> 0.12718839 | J30: 13349 | K30: 13260 | L30: 89 | M30: =L30/J30*100 -> 0.66671661 | N30: 11842 | O30: 177 | P30: =D30+H30+L30+O30 -> 864 | Q30: =O30/N30*100 -> 1.49468
A31: 45861 | B31: 14278 | C31: 13291 | D31: 645 | E31: =D31/B31*100 -> 4.5174394 | F31: 13505 | G31: 13479 | H31: 26 | I31: =H31/F31*100 -> 0.19252129 | J31: 13479 | K31: 13469 | L31: 10 | M31: =L31/J31*100 -> 0.07418948 | N31: 13840 | O31: 134 | P31: =D31+H31+L31+O31 -> 815 | Q31: =O31/N31*100 -> 0.96820809
A32: 45862 | B32: 15795 | C32: 14843 | D32: 509 | E32: =D32/B32*100 -> 3.2225388 | F32: 11893 | G32: 11869 | H32: 24 | I32: =H32/F32*100 -> 0.20179938 | J32: 11869 | K32: 11860 | L32: 9 | M32: =L32/J32*100 -> 0.075827787 | N32: 13333 | O32: 105 | P32: =D32+H32+L32+O32 -> 647 | Q32: =O32/N32*100 -> 0.78751969
A33: 45863 | B33: 13114 | C33: 12280 | D33: 561 | E33: =D33/B33*100 -> 4.277871 | F33: 13520 | G33: 13488 | H33: 32 | I33: =H33/F33*100 -> 0.23668639 | J33: 13488 | K33: 13473 | L33: 15 | M33: =L33/J33*100 -> 0.11120996 | N33: 16037 | O33: 198 | P33: =D33+H33+L33+O33 -> 806 | Q33: =O33/N33*100 -> 1.2346449
A34: 45864 | B34: 15077 | C34: 13476 | D34: 615 | E34: =D34/B34*100 -> 4.0790608 | F34: 12451 | G34: 12410 | H34: 41 | I34: =H34/F34*100 -> 0.32929082 | J34: 12410 | K34: 12400 | L34: 10 | M34: =L34/J34*100 -> 0.080580177 | N34: 10422 | O34: 123 | P34: =D34+H34+L34+O34 -> 789 | Q34: =O34/N34*100 -> 1.1801957
A35: W. REPORT | B35: =SUM(B28:B34) -> 83377 | C35: =SUM(C28:C34) -> 77376 | D35: =SUM(D28:D34) -> 3335 | E35: =D35/B35*100 -> 3.9999041 | F35: =SUM(F28:F34) -> 75805 | G35: =SUM(G28:G34) -> 75636 | H35: =SUM(H28:H34) -> 169 | I35: =H35/F35*100 -> 0.22294044 | J35: =SUM(J28:J34) -> 75636 | K35: =SUM(K28:K34) -> 75474 | L35: =SUM(L28:L34) -> 162 | M35: =L35/J35*100 -> 0.21418372 | N35: =SUM(N28:N34) -> 75327 | O35: =SUM(O28:O34) -> 839 | P35: =SUM(P28:P34) -> 4505 | Q35: =O35/N35*100 -> 1.1138105
A36: 45865 | B36: 0 | C36: 0 | D36: 0 | E36: =D36/B36*100 -> #DIV/0! | F36: 0 | G36: 0 | H36: 0 | I36: =H36/F36*100 -> #DIV/0! | J36: 0 | K36: 0 | L36: 0 | M36: =L36/J36*100 -> #DIV/0! | N36: 0 | O36: 0 | P36: 0 | Q36: 0 | R36: WEEK 5
A37: 45866 | B37: 11225 | C37: 10388 | D37: 622 | E37: =D37/B37*100 -> 5.5412027 | F37: 11082 | G37: 11068 | H37: 14 | I37: =H37/F37*100 -> 0.12633099 | J37: 11074 | K37: 11061 | L37: 13 | M37: =L37/J37*100 -> 0.11739209 | N37: 12645 | O37: 83 | P37: =D37+H37+L37+O37 -> 732 | Q37: =O37/N37*100 -> 0.65638592 | R37: =SUM(B36:B40) -> 51019 | S37: =SUM(P36:P40) -> 2925 | T37: =S37/R37*100 -> 5.7331582
A38: 45867 | B38: 13015 | C38: 11973 | D38: 320 | E38: =D38/B38*100 -> 2.4587015 | F38: 13451 | G38: 13422 | H38: 29 | I38: =H38/F38*100 -> 0.21559735 | J38: 13416 | K38: 13369 | L38: 47 | M38: =L38/J38*100 -> 0.35032797 | N38: 13923 | O38: 140 | P38: =D38+H38+L38+O38 -> 536 | Q38: =O38/N38*100 -> 1.0055304
A39: 45868 | B39: 13137 | C39: 12242 | D39: 578 | E39: =D39/B39*100 -> 4.3997869 | F39: 9594 | G39: 9571 | H39: 23 | I39: =H39/F39*100 -> 0.23973317 | J39: 9571 | K39: 9532 | L39: 39 | M39: =L39/J39*100 -> 0.40748093 | N39: 14215 | O39: 184 | P39: =D39+H39+L39+O39 -> 824 | Q39: =O39/N39*100 -> 1.2944073
A40: 45869 | B40: 13642 | C40: 12822 | D40: 541 | E40: =D40/B40*100 -> 3.9656942 | F40: 14970 | G40: 14945 | H40: 25 | I40: =H40/F40*100 -> 0.16700067 | J40: 14945 | K40: 14939 | L40: 6 | M40: =L40/J40*100 -> 0.040147206 | N40: 14180 | O40: 261 | P40: =D40+H40+L40+O40 -> 833 | Q40: =O40/N40*100 -> 1.8406206
A41: W. REPORT | B41: =SUM(B36:B40) -> 51019 | C41: =SUM(C36:C40) -> 47425 | D41: =SUM(D36:D40) -> 2061 | E41: =D41/B41*100 -> 4.0396715 | F41: =SUM(F36:F40) -> 49097 | G41: =SUM(G36:G40) -> 49006 | H41: =SUM(H36:H40) -> 91 | I41: =H41/F41*100 -> 0.18534737 | J41: =SUM(J36:J40) -> 49006 | K41: =SUM(K36:K40) -> 48901 | L41: =SUM(L36:L40) -> 105 | M41: =L41/J41*100 -> 0.21425948 | N41: =SUM(N37:N40) -> 54963 | O41: =SUM(O36:O40) -> 668 | P41: =SUM(P36:P40) -> 2925 | Q41: =O41/N41*100 -> 1.2153631
A42: Total | B42: =B41+B35+B27+B19+B11 -> 318831 | C42: =C41+C35+C27+C19+C11 -> 291609 | D42: =D41+D35+D27+D19+D11 -> 17562 | E42: =D42/B42*100 -> 5.5082473 | F42: =F41+F35+F27+F19+F11 -> 313744 | G42: =G41+G35+G27+G19+G11 -> 312819 | H42: =H41+H35+H27+H19+H11 -> 925 | I42: =H42/F42*100 -> 0.29482636 | J42: =J41+J35+J27+J19+J11 -> 310745 | K42: =K41+K35+K27+K19+K11 -> 309160 | L42: =L41+L35+L27+L19+L11 -> 1575 | M42: =L42/J42*100 -> 0.50684645 | N42: =N41+N35+N27+N19+N11 -> 290757 | O42: =O41+O35+O27+O19+O11 -> 4451 | P42: =D42+H42+L42+O42 -> 24513 | Q42: =P42/B42*100 -> 7.6883992

Sheet AUGUST 25
C1: DISPOSAFE HEALTH AND LIFE CARE LIMITED Plot No.37A, Sector-06, Ballabgarh (Faridabad) Haryana India 121006
A3: ASSEMBLY SECTION DAILY REJECTION REPORT FOR AUGUST 2025
A4: DATE | B4: VISUAL QTY | C4: VISUAL ACPT QTY | D4: REJ QTY | E4: REJ % | F4: BALLOON CHKD QTY | G4: BALLOON ACPT QTY | H4: REJ QTY | I4: REJ % | J4: VALVE INT CHKD QTY | K4: VALVE INTY ACPT QTY | L4: VALVE INTY REJ Qty | M4: REJ % | N4: FINAL CHECKED QTY | O4: FINAL REJECTION | P4: TOTAL REJ QTY | Q4: Final Rej % | R4: VISUAL CHECKED QTY | S4: VISUAL REJ QTY | T4: VISUAL REJ %
A6: 45870 | B6: 14332 | C6: 13483 | D6: 437 | E6: =D6/B6*100 -> 3.0491208 | F6: 11911 | G6: 11886 | H6: 25 | I6: =H6/F6*100 -> 0.20989002 | J6: 11886 | K6: 11845 | L6: 41 | M6: =L6/J6*100 -> 0.34494363 | N6: 15047 | O6: 96 | P6: =D6+H6+L6+O6 -> 599 | Q6: =O6/N6*100 -> 0.63800093 | R6: WEEK 1
A7: 45871 | B7: 11884 | C7: 11771 | D7: 423 | E7: =D7/B7*100 -> 3.5594076 | F7: 11156 | G7: 11146 | H7: 13 | I7: =H7/F7*100 -> 0.11652922 | J7: 9783 | K7: 9746 | L7: 32 | M7: =L7/J7*100 -> 0.32709803 | N7: 11710 | O7: 131 | P7: =D7+H7+L7+O7 -> 599 | Q7: =O7/N7*100 -> 1.118702 | R7: =SUM(B6:B8) -> 26216 | S7: =SUM(P6:P8) -> 1198 | T7: =S7/R7*100 -> 4.5697284
A8: 45872
A9: W. REPORT | B9: =SUM(B6:B8) -> 26216 | C9: =SUM(C6:C8) -> 25254 | D9: =SUM(D6:D8) -> 860 | E9: =D9/B9*100 -> 3.2804394 | F9: =SUM(F6:F8) -> 23067 | G9: =SUM(G6:G8) -> 23032 | H9: =SUM(H6:H8) -> 38 | I9: =H9/F9*100 -> 0.1647375 | J9: =SUM(J6:J8) -> 21669 | K9: =SUM(K6:K8) -> 21591 | L9: =SUM(L6:L8) -> 73 | M9: =L9/J9*100 -> 0.3368868 | N9: =SUM(N6:N7) -> 26757 | O9: =SUM(O6:O8) -> 227 | P9: =SUM(P6:P8) -> 1198
A10: 45873 | B10: 9697 | C10: 8890 | D10: 281 | E10: =D10/B10*100 -> 2.8978034 | F10: 11108 | G10: 11103 | H10: 5 | I10: =H10/F10*100 -> 0.045012604 | J10: 8103 | K10: 8080 | L10: 23 | M10: =L10/J10*100 -> 0.28384549 | N10: 5999 | O10: 184 | P10: =D10+H10+L10+O10 -> 493 | Q10: =O10/N10*100 -> 3.0671779 | R10: WEEK 2
A11: 45874 | B11: 12170 | C11: 10928 | D11: 537 | E11: =D11/B11*100 -> 4.4124897 | F11: 11104 | G11: 11050 | H11: 54 | I11: =H11/F11*100 -> 0.48631124 | J11: 9136 | K11: 8717 | L11: 419 | M11: =L11/J11*100 -> 4.5862522 | N11: 14575 | O11: 301 | P11: =D11+H11+L11+O11 -> 1311 | Q11: =O11/N11*100 -> 2.0651801 | R11: =SUM(B10:B16) -> 51425 | S11: =SUM(P10:P16) -> 4434 | T11: =S11/R11*100 -> 8.6222654
A12: 45875 | B12: 9162 | C12: 8596 | D12: 291 | E12: =D12/B12*100 -> 3.1761624 | F12: 9696 | G12: 9682 | H12: 14 | I12: =H12/F12*100 -> 0.14438944 | J12: 13059 | K12: 13036 | L12: 23 | M12: =L12/J12*100 -> 0.17612375 | N12: 11666 | O12: 295 | P12: =D12+H12+L12+O12 -> 623 | Q12: =O12/N12*100 -> 2.5287159
A13: 45876 | B13: 11553 | C13: 9762 | D13: 584 | E13: =D13/B13*100 -> 5.0549641 | F13: 10891 | G13: 10881 | H13: 10 | I13: =H13/F13*100 -> 0.091818933 | J13: 12418 | K13: 12396 | L13: 22 | M13: =L13/J13*100 -> 0.17716218 | N13: 13772 | O13: 275 | P13: =D13+H13+L13+O13 -> 891 | Q13: =O13/N13*100 -> 1.9968051
A14: 45877 | B14: 8843 | C14: 6765 | D14: 737 | E14: =D14/B14*100 -> 8.3342757 | F14: 8078 | G14: 8049 | H14: 9 | I14: =H14/F14*100 -> 0.11141372 | J14: 8049 | K14: 8028 | L14: 21 | M14: =L14/J14*100 -> 0.26090198 | N14: 13500 | O14: 349 | P14: =D14+H14+L14+O14 -> 1116 | Q14: =O14/N14*100 -> 2.5851852
A15: 45878 | B15: HOLIDAY
A16: 45879
A17: W. REPORT | B17: =SUM(B10:B16) -> 51425 | C17: =SUM(C10:C16) -> 44941 | D17: =SUM(D10:D16) -> 2430 | E17: =D17/B17*100 -> 4.7253281 | F17: =SUM(F10:F16) -> 50877 | G17: =SUM(G10:G16) -> 50765 | H17: =SUM(H10:H16) -> 92 | I17: =H17/F17*100 -> 0.18082827 | J17: =SUM(J10:J16) -> 50765 | K17: =SUM(K10:K16) -> 50257 | L17: =SUM(L10:L16) -> 508 | M17: =L17/J17*100 -> 1.0006895 | N17: =SUM(N10:N16) -> 59512 | O17: =SUM(O10:O16) -> 1404 | P17: =SUM(P10:P16) -> 4434
A18: 45880 | B18: 10488 | C18: 9678 | D18: 656 | E18: =D18/B18*100 -> 6.2547674 | F18: 9570 | G18: 9558 | H18: 12 | I18: =H18/F18*100 -> 0.12539185 | J18: 7217 | K18: 7181 | L18: 36 | M18: =L18/J18*100 -> 0.49882223 | N18: 10079 | O18: 32 | P18: =D18+H18+L18+O18 -> 736 | Q18: =O18/N18*100 -> 0.31749181 | R18: WEEK 3
A19: 45881 | B19: 7782 | C19: 6410 | D19: 629 | E19: =D19/B19*100 -> 8.0827551 | F19: 7334 | G19: 7255 | H19: 79 | I19: =H19/F19*100 -> 1.0771748 | J19: 9069 | K19: 9032 | L19: 37 | M19: =L19/J19*100 -> 0.40798324 | N19: 10673 | O19: 64 | P19: =D19+H19+L19+O19 -> 809 | Q19: =O19/N19*100 -> 0.59964396 | R19: =SUM(B18:B24) -> 45370 | S19: =SUM(P18:P24) -> 3024 | T19: =S19/R19*100 -> 6.6651973
A20: 45882 | B20: 9961 | C20: 8888 | D20: 461 | E20: =D20/B20*100 -> 4.6280494 | F20: 8183 | G20: 8080 | H20: 49 | I20: =H20/F20*100 -> 0.5988024 | J20: 8048 | K20: 8032 | L20: 16 | M20: =L20/J20*100 -> 0.19880716 | N20: 8213 | O20: 61 | P20: =D20+H20+L20+O20 -> 587 | Q20: =O20/N20*100 -> 0.74272495
A21: 45883 | B21: 8592 | C21: 7888 | D21: 343 | E21: =D21/B21*100 -> 3.9920857 | F21: 8455 | G21: 8408 | H21: 47 | I21: =H21/F21*100 -> 0.55588409 | J21: 8887 | K21: 8869 | L21: 18 | M21: =L21/J21*100 -> 0.20254304 | N21: 4204 | O21: 176 | P21: =D21+H21+L21+O21 -> 584 | Q21: =O21/N21*100 -> 4.1864891
A22: 45884 | B22: HOLIDAY
A23: 45885 | B23: HOLIDAY
A24: 45886 | B24: 8547 | C24: 8242 | D24: 219 | E24: =D24/B24*100 -> 2.5623026 | F24: 8242 | G24: 8209 | H24: 33 | I24: =H24/F24*100 -> 0.40038826 | J24: 5929 | K24: 5886 | L24: 23 | M24: =L24/J24*100 -> 0.38792376 | N24: 3752 | O24: 33 | P24: =D24+H24+L24+O24 -> 308 | Q24: =O24/N24*100 -> 0.87953092
A25: W. REPORT | B25: =SUM(B18:B24) -> 45370 | C25: =SUM(C18:C24) -> 41106 | D25: =SUM(D18:D24) -> 2308 | E25: =D25/B25*100 -> 5.0870619 | F25: =SUM(F18:F24) -> 41784 | G25: =SUM(G18:G24) -> 41510 | H25: =SUM(H18:H24) -> 220 | I25: =H25/F25*100 -> 0.52651733 | J25: =SUM(J18:J24) -> 39150 | K25: =SUM(K18:K24) -> 39000 | L25: =SUM(L18:L24) -> 130 | M25: =L25/J25*100 -> 0.33205619 | N25: =SUM(N18:N24) -> 36921 | O25: =SUM(O18:O24) -> 366 | P25: =SUM(P18:P24) -> 3024
A26: 45887 | B26: 6890 | C26: 6696 | D26: 105 | E26: =D26/B26*100 -> 1.5239478 | F26: 7808 | G26: 7776 | H26: 32 | I26: =H26/F26*100 -> 0.40983607 | J26: 10056 | K26: 10037 | L26: 19 | M26: =L26/J26*100 -> 0.18894193 | N26: 8023 | O26: 191 | P26: =D26+H26+L26+O26 -> 347 | Q26: =O26/N26*100 -> 2.3806556 | R26: WEEK 4
A27: 45888 | B27: 11334 | C27: 10733 | D27: 527 | E27: =D27/B27*100 -> 4.6497265 | F27: 13121 | G27: 13098 | H27: 23 | I27: =H27/F27*100 -> 0.17529152 | J27: 7690 | K27: 7623 | L27: 67 | M27: =L27/J27*100 -> 0.87126138 | N27: 13237 | O27: 81 | P27: =D27+H27+L27+O27 -> 698 | Q27: =O27/N27*100 -> 0.61192113 | R27: =SUM(B26:B32) -> 68039 | S27: =SUM(P26:P32) -> 3822 | T27: =S27/R27*100 -> 5.6173665
A28: 45889 | B28: 12010 | C28: 11516 | D28: 449 | E28: =D28/B28*100 -> 3.7385512 | F28: 12865 | G28: 12827 | H28: 38 | I28: =H28/F28*100 -> 0.29537505 | J28: 10848 | K28: 10704 | L28: 144 | M28: =L28/J28*100 -> 1.3274336 | N28: 10765 | O28: 48 | P28: =D28+H28+L28+O28 -> 679 | Q28: =O28/N28*100 -> 0.44588946
A29: 45890 | B29: 12150 | C29: 11422 | D29: 524 | E29: =D29/B29*100 -> 4.3127572 | F29: 11422 | G29: 11393 | H29: 29 | I29: =H29/F29*100 -> 0.25389599 | J29: 10788 | K29: 10715 | L29: 73 | M29: =L29/J29*100 -> 0.67667779 | N29: 8501 | O29: 119 | P29: =D29+H29+L29+O29 -> 745 | Q29: =O29/N29*100 -> 1.3998353
A30: 45891 | B30: 11276 | C30: 10723 | D30: 282 | E30: =D30/B30*100 -> 2.5008868 | F30: 10571 | G30: 10544 | H30: 27 | I30: =H30/F30*100 -> 0.25541576 | J30: 11557 | K30: 11140 | L30: 417 | M30: =L30/J30*100 -> 3.6082028 | N30: 13945 | O30: 44 | P30: =D30+H30+L30+O30 -> 770 | Q30: =O30/N30*100 -> 0.31552528
A31: 45892 | B31: 14379 | C31: 13789 | D31: 278 | E31: =D31/B31*100 -> 1.9333751 | F31: 13789 | G31: 13776 | H31: 13 | I31: =H31/F31*100 -> 0.094278048 | J31: 13944 | K31: 13830 | L31: 114 | M31: =L31/J31*100 -> 0.81755594 | N31: 15605 | O31: 178 | P31: =D31+H31+L31+O31 -> 583 | Q31: =O31/N31*100 -> 1.14066
A32: 45893
A33: W. REPORT | B33: =SUM(B26:B32) -> 68039 | C33: =SUM(C26:C32) -> 64879 | D33: =SUM(D26:D32) -> 2165 | E33: =D33/B33*100 -> 3.1819986 | F33: =SUM(F26:F32) -> 69576 | G33: =SUM(G26:G32) -> 69414 | H33: =SUM(H26:H32) -> 162 | I33: =H33/F33*100 -> 0.23283891 | J33: =SUM(J26:J32) -> 64883 | K33: =SUM(K26:K32) -> 64049 | L33: =SUM(L26:L32) -> 834 | M33: =L33/J33*100 -> 1.2853906 | N33: =SUM(N26:N32) -> 70076 | O33: =SUM(O26:O32) -> 661 | P33: =SUM(P26:P32) -> 3822
A34: 45894 | B34: 15717 | C34: 14501 | D34: 912 | E34: =D34/B34*100 -> 5.8026341 | F34: 10091 | G34: 10078 | H34: 13 | I34: =H34/F34*100 -> 0.12882767 | J34: 11115 | K34: 10524 | L34: 861 | M34: =L34/J34*100 -> 7.7462888 | N34: 16596 | O34: 178 | P34: =D34+H34+L34+O34 -> 1964 | Q34: =O34/N34*100 -> 1.0725476 | R34: WEEK 5
A35: 45895 | B35: 12685 | C35: 12156 | D35: 417 | E35: =D35/B35*100 -> 3.2873473 | F35: 11695 | G35: 11666 | H35: 29 | I35: =H35/F35*100 -> 0.24796922 | J35: 13991 | K35: 13724 | L35: 267 | M35: =L35/J35*100 -> 1.9083697 | N35: 9808 | O35: 127 | P35: =D35+H35+L35+O35 -> 840 | Q35: =O35/N35*100 -> 1.2948613 | R35: =SUM(B34:B40) -> 76129 | S35: =SUM(P34:P40) -> 6158 | T35: =S35/R35*100 -> 8.0889017
A36: 45896 | B36: 13285 | C36: 12221 | D36: 649 | E36: =D36/B36*100 -> 4.8852089 | F36: 9025 | G36: 8972 | H36: 53 | I36: =H36/F36*100 -> 0.58725762 | J36: 12422 | K36: 12162 | L36: 166 | M36: =L36/J36*100 -> 1.3363388 | N36: 15308 | O36: 166 | P36: =D36+H36+L36+O36 -> 1034 | Q36: =O36/N36*100 -> 1.0844003
A37: 45897 | B37: 12634 | C37: 11597 | D37: 836 | E37: =D37/B37*100 -> 6.6170651 | F37: 11884 | G37: 11864 | H37: 20 | I37: =H37/F37*100 -> 0.1682935 | J37: 11864 | K37: 11833 | L37: 31 | M37: =L37/J37*100 -> 0.26129467 | N37: 9800 | O37: 85 | P37: =D37+H37+L37+O37 -> 972 | Q37: =O37/N37*100 -> 0.86734694
A38: 45898 | B38: 12518 | C38: 11773 | D38: 400 | E38: =D38/B38*100 -> 3.1953986 | F38: 12461 | G38: 12426 | H38: 35 | I38: =H38/F38*100 -> 0.28087633 | J38: 12426 | K38: 12108 | L38: 318 | M38: =L38/J38*100 -> 2.5591502 | N38: 14328 | O38: 91 | P38: =D38+H38+L38+O38 -> 844 | Q38: =O38/N38*100 -> 0.63512004
A39: 45899 | B39: 9290 | C39: 8841 | D39: 319 | E39: =D39/B39*100 -> 3.4337998 | F39: 12947 | G39: 12922 | H39: 25 | I39: =H39/F39*100 -> 0.19309493 | J39: 11439 | K39: 11387 | L39: 52 | M39: =L39/J39*100 -> 0.45458519 | N39: 12952 | O39: 108 | P39: =D39+H39+L39+O39 -> 504 | Q39: =O39/N39*100 -> 0.83384805
A40: 45900
