Workbook

Sheet APRIL 25
C1: DISPOSAFE HEALTH AND LIFE CARE LIMITED Plot No.37A, Sector-06, Ballabgarh (Faridabad) Haryana India 121006 | V1: Doc. No : | X1: F/ASSEM/03:00
V3: Supersedes : | X3: None
V4: Effective Date : | X4: 45633
C5: BALLOON & VALVE INTEGRITY REPORT | V5: Page: 1 of 1
A7: BALLOON ISPECTION REPORT - P17 | N7: VALVE INTEGRITY
A8: DATE | C8: CHECKED QTY | D8: ACCEPT QTY | E8: HOLD QTY | F8: REJ. QTY | G8: REJ. % | H8: STRUCK BALLOON | I8: BALLOOM BRUST | J8: LEAKAGE | K8: OTHERS | L8: Remarks | N8: CHECKED QTY | O8: ACCEPT QTY | P8: HOLD QTY | Q8: REJ. QTY | R8: REJ. % | S8: LEAKAGE | T8: 90/10 | U8: BUBBLE | V8: THIN SPOD | W8: OTHERS | Y8: Remarks
A11: 45748 | C11: 9612 | D11: 9612 | F11: 15 | G11: =F11/C11*100 -> 0.15605493 | H11: 11 | I11: 1 | J11: 3 | N11: 9612 | O11: 9483 | Q11: 129 | R11: =Q11/N11*100 -> 1.3420724 | S11: 21 | T11: 64 | V11: 28 | W11: 16
A12: 45749 | C12: 9907 | D12: 9858 | F12: 49 | G12: =F12/C12*100 -> 0.49459978 | H12: 27 | I12: 3 | J12: 19 | N12: 9858 | O12: 9767 | Q12: 91 | R12: =Q12/N12*100 -> 0.92310814 | S12: 55 | T12: 12 | V12: 22 | W12: 2
A13: 45750 | C13: 10746 | D13: 10683 | F13: 63 | G13: =F13/C13*100 -> 0.58626466 | H13: 46 | I13: 10 | J13: 7 | N13: 10683 | O13: 10632 | Q13: 51 | R13: =Q13/N13*100 -> 0.47739399 | S13: 27 | T13: 4 | V13: 20
A14: 45751 | C14: 9573 | D14: 9555 | F14: 18 | G14: =F14/C14*100 -> 0.18802883 | H14: 12 | I14: 2 | J14: 4 | N14: 9555 | O14: 9481 | Q14: 74 | R14: =Q14/N14*100 -> 0.77446363 | S14: 33 | T14: 19 | V14: 22
A15: 45752 | C15: 7038 | D15: 7018 | F15: 20 | G15: =F15/C15*100 -> 0.28417164 | H15: 8 | I15: 1 | J15: 11 | N15: 7018 | O15: 6963 | P15: 1 | Q15: 55 | R15: =Q15/N15*100 -> 0.78369906 | S15: 27 | T15: 17 | V15: 11
A16: 45754 | C16: 4553 | D16: 4498 | F16: 55 | G16: =F16/C16*100 -> 1.2079947 | H16: 27 | I16: 12 | J16: 16 | N16: 4498 | O16: 4443 | Q16: =N16-(O16+P16) -> 55 | R16: =Q16/N16*100 -> 1.2227657 | S16: 22 | T16: 19 | V16: 14
A17: 45755 | C17: 9400 | D17: 9326 | F17: 71 | G17: =F17/C17*100 -> 0.75531915 | H17: 28 | I17: 17 | J17: 26 | N17: 9326 | O17: 9100 | Q17: 226 | R17: =Q17/N17*100 -> 2.4233326 | S17: 140 | T17: 75 | V17: 11
A18: 45756 | C18: 8912 | D18: 8886 | F18: 26 | G18: =F18/C18*100 -> 0.29174147 | H18: 10 | J18: 16 | N18: 8886 | O18: 8820 | Q18: 66 | R18: =Q18/N18*100 -> 0.74274139 | S18: 61 | V18: 5
A19: 45757 | C19: 10350 | D19: 10279 | F19: 71 | G19: =F19/C19*100 -> 0.68599034 | H19: 16 | I19: 8 | J19: 47 | N19: 10279 | O19: 10159 | Q19: 120 | R19: =Q19/N19*100 -> 1.1674287 | S19: 102 | T19: 4 | V19: 14
A20: 45758 | C20: 12214 | D20: 12114 | F20: 100 | G20: =F20/C20*100 -> 0.8187326 | H20: 61 | I20: 2 | J20: 37 | N20: 12114 | O20: 1208 | Q20: 56 | R20: =Q20/N20*100 -> 0.46227505 | S20: 20 | T20: 15 | V20: 21
A21: 45759 | C21: 7250 | D21: 7214 | F21: 36 | G21: =F21/C21*100 -> 0.49655172 | H21: 5 | I21: 3 | J21: 28 | N21: 7214 | O21: 7148 | Q21: 66 | R21: =Q21/N21*100 -> 0.91488772 | S21: 50 | V21: 16
A22: 45761 | C22: 6182 | D22: 6088 | F22: 94 | G22: =F22/C22*100 -> 1.5205435 | H22: 69 | I22: 4 | J22: 21 | N22: 6088 | O22: 5967 | Q22: 121 | R22: =Q22/N22*100 -> 1.9875164 | S22: 22 | T22: 52 | V22: 47
A23: 45762 | C23: 11557 | D23: 11479 | F23: 78 | G23: =F23/C23*100 -> 0.67491564 | H23: 39 | I23: 10 | J23: 29 | N23: 11479 | O23: 11376 | Q23: 103 | R23: =Q23/N23*100 -> 0.8972907 | S23: 56 | T23: 6 | V23: 41
A24: 45763 | C24: 8339 | D24: 8267 | F24: 57 | G24: =F24/C24*100 -> 0.6835352 | H24: 32 | I24: 7 | J24: 18 | N24: 8267 | O24: 7477 | Q24: 790 | R24: =Q24/N24*100 -> 9.5560663 | S24: 56 | V24: 734
A25: 45764 | C25: 10209 | D25: 10104 | F25: 105 | G25: =F25/C25*100 -> 1.0285043 | H25: 65 | I25: 6 | J25: 34 | N25: 10104 | O25: 8874 | Q25: 1230 | R25: =Q25/N25*100 -> 12.173397 | S25: 90 | V25: 1140
A26: 45765 | C26: 8453 | D26: 8390 | F26: 63 | G26: =F26/C26*100 -> 0.74529753 | H26: 35 | I26: 1 | J26: 27 | N26: 8390 | O26: 6557 | P26: 1794 | Q26: 39 | R26: =Q26/N26*100 -> 0.46483909 | S26: 39
A27: 45766 | C27: 10889 | D27: 10794 | F27: 95 | G27: =F27/C27*100 -> 0.87244008 | H27: 59 | I27: 2 | J27: 34 | N27: 10794 | O27: 9967 | P27: 684 | Q27: 143 | R27: =Q27/N27*100 -> 1.3248101 | S27: 85 | V27: 58
A28: 45768 | G28: =F28/C28*100 -> #DIV/0! | R28: =Q28/N28*100 -> #DIV/0!
A29: 45769 | C29: 7281 | D29: 7244 | F29: 37 | G29: =F29/C29*100 -> 0.50817195 | H29: 23 | I29: 1 | J29: 13 | N29: 7244 | O29: 7177 | P29: 1867 | Q29: 67 | R29: =Q29/N29*100 -> 0.92490337 | S29: 55 | T29: 12
A30: 45770 | C30: 7370 | D30: 7220 | F30: 150 | G30: =F30/C30*100 -> 2.0352782 | H30: 108 | I30: 2 | J30: 40 | N30: 7220 | O30: 7143 | P30: 1100 | Q30: 77 | R30: =Q30/N30*100 -> 1.066482 | S30: 76 | T30: 1
A31: 45771 | C31: 6878 | D31: 6755 | F31: 123 | G31: =F31/C31*100 -> 1.7883106 | H31: 95 | I31: 4 | J31: 24 | N31: 6755 | O31: 6694 | P31: 1855 | Q31: 61 | R31: =Q31/N31*100 -> 0.90303479 | S31: 61
A32: 45772 | C32: 8614 | D32: 8485 | F32: 129 | G32: =F32/C32*100 -> 1.4975621 | H32: 115 | I32: 4 | J32: 10 | N32: 8485 | O32: 8425 | P32: 331 | Q32: 60 | R32: =Q32/N32*100 -> 0.70713023 | S32: 34 | V32: 26
A33: 45773 | C33: 5986 | D33: 5937 | F33: 49 | G33: =F33/C33*100 -> 0.81857668 | H33: 44 | I33: 2 | J33: 3 | N33: 5937 | O33: 5887 | P33: 985 | Q33: 58 | R33: =Q33/N33*100 -> 0.97692437 | S33: 36 | T33: 5 | V33: 16
A34: 45775 | C34: 8183 | D34: 7955 | F34: 228 | G34: =F34/C34*100 -> 2.7862642 | H34: 50 | I34: 17 | J34: 161 | N34: 7955 | O34: 7640 | P34: 481 | Q34: 315 | R34: =Q34/N34*100 -> 3.9597737 | S34: 237 | V34: 78
A35: 45776 | C35: 8788 | D35: 8723 | F35: 65 | G35: =F35/C35*100 -> 0.73964497 | H35: 22 | I35: 16 | J35: 27 | N35: 8723 | O35: 8597 | P35: 126 | R35: =Q35/N35*100 -> 0 | S35: 73 | V35: 53
A36: 45777 | C36: 7811 | D36: 7698 | F36: 113 | G36: =F36/C36*100 -> 1.4466778 | H36: 57 | I36: 6 | J36: 50 | N36: 7698 | O36: 7570 | P36: 612 | Q36: 128 | R36: =Q36/N36*100 -> 1.6627696 | S36: 88 | V36: 40
A37: TOTAL | C37: =SUM(C11:C36) -> 216095 | D37: =SUM(D11:D36) -> 214182 | F37: =SUM(F11:F36) -> 1910 | H37: =SUM(H11:H36) -> 1064 | I37: =SUM(I11:I36) -> 141 | J37: =SUM(J11:J36) -> 705 | N37: =SUM(N11:N36) -> 214182 | O37: =SUM(O11:O36) -> 196555 | P37: =SUM(P11:P36) -> 9836 | Q37: =SUM(Q11:Q36) -> 4181 | S37: =SUM(S11:S36) -> 1566 | T37: =SUM(T11:T36) -> 305 | U37: =SUM(U11:U36) -> 0 | V37: =SUM(V11:V36) -> 2417 | W37: =SUM(W11:W36) -> 18
A38: TOTAL % | D38: =D37/C37*100 -> 99.114741 | F38: =F37/C37*100 -> 0.88387052 | H38: =H37/C37*100 -> 0.49237604 | I38: =I37/C37*100 -> 0.06524908 | J38: =J37/C37*100 -> 0.3262454 | O38: =O37/N37*100 -> 91.770083 | P38: =P37/N37*100 -> 4.592356 | Q38: =Q37/N37*100 -> 1.9520781 | S38: =S37/N37*100 -> 0.73115388 | T38: =T37/N37*100 -> 0.14240226 | U38: =U37/N37*100 -> 0 | W38: =W37/N37*100 -> 0.0084040676
B47: BALLOON INS. REPORT
B48: STRUCK BALLOON | C48: =H37 -> 1064
B49: BALLOON BRUST | C49: =I37 -> 141
B50: LEAKAGE | C50: =J37 -> 705
B51: REJ QTY | C51: =SUM(C48:C50) -> 1910
B53: VALV INTEGRITY
...

Sheet  MAY 25
C1: DISPOSAFE HEALTH AND LIFE CARE LIMITED Plot No.37A, Sector-06, Ballabgarh (Faridabad) Haryana India 121006 | X1: Doc. No : | Z1: F/ASSEM/03:00
X3: Supersedes : | Z3: None
X4: Effective Date : | Z4: 45633
C5: DAILY BALLOON & VALVE INTEGRITY REPORT | X5: Page: 1 of 1
A7: BALLOON ISPECTION REPORT - P17 | O7: VALVE INTEGRITY
A8: DATE | C8: CHECKED QTY | E8: ACCEPT QTY | F8: HOLD QTY | G8: REJ. QTY | H8: REJ. % | I8: STRUCK BALLOON | J8: BALLOOM BRUST | K8: LEAKAGE | L8: OTHERS | M8: Remarks | O8: CHECKED QTY | Q8: ACCEPT QTY | R8: HOLD QTY | S8: REJ. QTY | T8: REJ. % | U8: LEAKAGE | V8: 90/10 | W8: BUBBLE | X8: THIN SPOD | Y8: OTHERS | AA8: Remarks
A11: 45778 | C11: 6229 | E11: 6123 | G11: 106 | H11: =G11/C11*100 -> 1.7017178 | I11: 78 | J11: 2 | K11: 26 | O11: 6125 | Q11: 6000 | R11: 1633 | S11: 123 | T11: =S11/O11*100 -> 2.0081633 | U11: 95 | V11: 11 | X11: 17
A12: 45779 | C12: 4208 | E12: 4188 | G12: 20 | H12: =G12/C12*100 -> 0.47528517 | I12: 15 | J12: 1 | K12: 4 | O12: 4188 | Q12: 4138 | R12: 18 | S12: 22 | T12: =S12/O12*100 -> 0.52531041 | U12: 9 | X12: 13
A13: 45780 | C13: 6642 | E13: 6591 | G13: 51 | H13: =G13/C13*100 -> 0.76784101 | I13: 35 | J13: 8 | K13: 8 | O13: 6591 | Q13: 6570 | R13: 968 | S13: 21 | T13: =S13/O13*100 -> 0.31861629 | U13: 9 | X13: 12
A14: 45781 | C14: SUNDAY
A15: 45782 | C15: 5847 | E15: 5698 | G15: 149 | H15: =G15/C15*100 -> 2.5483154 | I15: 79 | J15: 24 | K15: 46 | O15: 5698 | Q15: 5555 | S15: 143 | T15: =S15/O15*100 -> 2.5096525 | U15: 96 | X15: 47
A16: 45783 | C16: 6490 | E16: 6397 | G16: 93 | H16: =G16/C16*100 -> 1.4329738 | I16: 52 | J16: 18 | K16: 23 | O16: 6397 | Q16: 6243 | S16: 154 | T16: =S16/O16*100 -> 2.4073785 | U16: 78 | X16: 61 | Y16: 15
A17: 45784 | C17: 7268 | E17: 7164 | G17: 104 | H17: =G17/C17*100 -> 1.4309301 | I17: 70 | J17: 2 | K17: 32 | O17: 7164 | Q17: 7025 | S17: 79 | T17: =S17/O17*100 -> 1.1027359 | U17: 55 | X17: 24
A18: 45785 | C18: 7808 | E18: 7747 | G18: 61 | H18: =G18/C18*100 -> 0.78125 | I18: 39 | J18: 12 | K18: 10 | O18: 7747 | Q18: 7666 | S18: 81 | T18: =S18/O18*100 -> 1.045566 | U18: 60 | X18: 21
A19: 45786 | C19: 7976 | E19: 7917 | G19: 59 | H19: =G19/C19*100 -> 0.73971916 | I19: 43 | J19: 10 | K19: 6 | O19: 7917 | Q19: 7879 | S19: 38 | T19: =S19/O19*100 -> 0.47997979 | U19: 24 | V19: 4 | X19: 19
A20: 45787 | C20: 9000 | E20: 8994 | G20: 6 | H20: =G20/C20*100 -> 0.066666667 | I20: 5 | K20: 1 | O20: 8994 | Q20: 8992 | S20: 2 | T20: =S20/O20*100 -> 0.022237047 | U20: 2
A21: 45789 | C21: 8485 | E21: 8432 | G21: 53 | H21: =G21/C21*100 -> 0.6246317 | I21: 29 | J21: 15 | K21: 9 | O21: 8432 | Q21: 8382 | S21: 50 | T21: =S21/O21*100 -> 0.59297913 | X21: 50
A22: 45790 | C22: 10218 | E22: 10134 | G22: 84 | H22: =G22/C22*100 -> 0.82207868 | I22: 46 | J22: 32 | K22: 6 | O22: 10134 | Q22: 10076 | S22: 58 | T22: =S22/O22*100 -> 0.57233077 | U22: 51 | X22: 7
A23: 45791 | C23: 10056 | E23: 9930 | G23: 126 | H23: =G23/C23*100 -> 1.2529833 | I23: 101 | J23: 9 | K23: 16 | O23: 9930 | Q23: 9786 | S23: 144 | T23: =S23/O23*100 -> 1.4501511 | U23: 56 | X23: 88
A24: 45792 | C24: 11144 | E24: 11047 | G24: 97 | H24: =G24/C24*100 -> 0.87042355 | I24: 68 | J24: 4 | K24: 25 | O24: 11047 | Q24: 10955 | S24: 92 | T24: =S24/O24*100 -> 0.83280529 | U24: 39 | X24: 53
A25: 45793 | C25: 10936 | E25: 10791 | G25: 145 | H25: =G25/C25*100 -> 1.3258961 | I25: 108 | J25: 2 | K25: 35 | O25: 10791 | Q25: 10651 | S25: 140 | T25: =S25/O25*100 -> 1.2973774 | U25: 27 | X25: 113
A26: 45794 | C26: 11780 | E26: 11702 | G26: 78 | H26: =G26/C26*100 -> 0.66213922 | I26: 38 | J26: 26 | K26: 16 | O26: 11702 | Q26: 11558 | S26: 144 | T26: =S26/O26*100 -> 1.2305589 | U26: 69 | X26: 75
A27: 45796 | C27: 9892 | E27: 9889 | G27: 3 | H27: =G27/C27*100 -> 0.030327537 | I27: 2 | K27: 1 | O27: 9889 | Q27: 9883 | S27: 6 | T27: =S27/O27*100 -> 0.060673476 | U27: 4 | X27: 2
A28: 45797 | C28: 11914 | E28: 11810 | G28: 104 | H28: =G28/C28*100 -> 0.87292261 | I28: 69 | J28: 10 | K28: 25 | O28: 11810 | Q28: 11737 | S28: 73 | T28: =S28/O28*100 -> 0.61812024 | U28: 32 | X28: 41
A29: 45798 | C29: 10380 | E29: 10328 | G29: 52 | H29: =G29/C29*100 -> 0.50096339 | I29: 20 | J29: 29 | K29: 3 | O29: 10328 | Q29: 10287 | S29: 41 | T29: =S29/O29*100 -> 0.39697909 | U29: 14 | X29: 27
A30: 45799 | C30: 10200 | E30: 10080 | G30: 120 | H30: =G30/C30*100 -> 1.1764706 | I30: 82 | J30: 34 | K30: 4 | O30: 10080 | Q30: 10022 | S30: 58 | T30: =S30/O30*100 -> 0.57539683 | U30: 21 | X30: 37
A31: 45800 | C31: 10669 | E31: 10618 | G31: 51 | H31: =G31/C31*100 -> 0.47802043 | I31: 32 | J31: 7 | K31: 12 | O31: 10618 | Q31: 10548 | S31: 70 | T31: =S31/O31*100 -> 0.65925786 | U31: 20 | X31: 50
A32: 45801 | C32: 10423 | E32: 10360 | G32: 63 | H32: =G32/C32*100 -> 0.60443251 | I32: 50 | J32: 10 | K32: 3 | O32: 10360 | Q32: 10277 | S32: 83 | T32: =S32/O32*100 -> 0.8011583 | U32: 36 | X32: 47
A33: 45802 | C33: 10141 | E33: 10076 | G33: 65 | H33: =G33/C33*100 -> 0.64096243 | I33: 34 | J33: 17 | K33: 14 | O33: 10076 | Q33: 9979 | S33: 97 | T33: =S33/O33*100 -> 0.9626836 | U33: 61 | X33: 36
A34: 45803 | C34: 10141 | E34: 10076 | G34: 65 | H34: =G34/C34*100 -> 0.64096243 | I34: 34 | J34: 17 | K34: 14 | O34: 10076 | Q34: 9979 | S34: 97 | T34: =S34/O34*100 -> 0.9626836 | U34: 61 | X34: 36
A35: 45804 | C35: 11162 | E35: 10925 | G35: 237 | H35: =G35/C35*100 -> 2.1232754 | I35: 146 | J35: 91 | O35: 10309 | Q35: 10275 | S35: 34 | T35: =S35/O35*100 -> 0.3298089 | U35: 20 | V35: 3 | X35: 11
A36: 45805 | C36: 9310 | E36: 9305 | G36: 5 | H36: =G36/C36*100 -> 0.053705693 | I36: 2 | K36: 3 | O36: 11243 | Q36: 11079 | S36: 164 | T36: =S36/O36*100 -> 1.4586854 | U36: 63 | X36: 101
A37: 45806 | C37: 9675 | E37: 9570 | G37: 105 | H37: =G37/C37*100 -> 1.0852713 | I37: 78 | J37: 21 | K37: 6 | O37: 11354 | Q37: 11211 | S37: 143 | T37: =S37/O37*100 -> 1.259468 | U37: 64 | X37: 66 | Y37: 13
A38: 45807 | C38: 10710 | E38: 10631 | G38: 79 | H38: =G38/C38*100 -> 0.73762838 | I38: 39 | J38: 28 | K38: 12 | O38: 10524 | Q38: 10393 | S38: 131 | T38: =S38/O38*100 -> 1.2447739 | U38: 42 | X38: 31 | Y38: 58
A39: 45808 | H39: =G39/C39*100 -> #DIV/0! | T39: =S39/O39*100 -> #DIV/0!
A40: TOTAL | C40: =SUM(C11:D39) -> 248704 | E40: =SUM(E11:E39) -> 246523 | G40: =SUM(G11:G39) -> 2181 | I40: =SUM(I11:I39) -> 1394 | J40: =SUM(J11:J39) -> 429 | K40: =SUM(K11:K39) -> 360 | O40: TOTAL | P40: =SUM(O11:P39) -> 249524 | Q40: =SUM(Q11:Q39) -> 247146 | R40: =SUM(R11:R39) -> 2619 | S40: =SUM(S11:S39) -> 2288 | U40: =SUM(U11:U39) -> 1108 | V40: =SUM(V11:V39) -> 18 | W40: =SUM(W11:W39) -> 0 | X40: =SUM(X11:X39) -> 1085 | Y40: =SUM(Y11:Y39) -> 86
A41: TOTAL % | E41: =E40/C40*100 -> 99.123054 | G41: =G40/C40*100 -> 0.87694609 | I41: =I40/C40*100 -> 0.56050566 | J41: =J40/C40*100 -> 0.17249421 | K41: =K40/C40*100 -> 0.14475039 | O41: TOTAL % | Q41: =Q40/P40*100 -> 99.046985 | R41: =R40/P40*100 -> 1.0495984 | S41: =S40/P40*100 -> 0.91694586 | U41: =U40/P40*100 -> 0.44404546 | V41: =V40/P40*100 -> 0.007213735 | W41: =W40/P40*100 -> 0 | Y41: =Y40/P40*100 -> 0.034465623
B50: BALLOON INS. REPORT
B51: STRUCK BALLOON | D51: =I40 -> 1394
B52: BALLOON BRUST | D52: =J40 -> 429
...

Sheet JUNE 2025
C1: DISPOSAFE HEALTH AND LIFE CARE LIMITED Plot No.37A, Sector-06, Ballabgarh (Faridabad) Haryana India 121006 | X1: Doc. No : | Z1: F/ASSEM/03:00
X3: Supersedes : | Z3: None
X4: Effective Date : | Z4: 45633
C5: DAILY BALLOON & VALVE INTEGRITY REPORT | X5: Page: 1 of 1
A7: BALLOON ISPECTION REPORT - P17 | O7: VALVE INTEGRITY
A8: DATE | C8: CHECKED QTY | E8: ACCEPT QTY | F8: HOLD QTY | G8: REJ. QTY | H8: REJ. % | I8: STRUCK BALLOON | J8: BALLOOM BRUST | K8: LEAKAGE | L8: OTHERS | M8: Remarks | O8: CHECKED QTY | Q8: ACCEPT QTY | R8: HOLD QTY | S8: REJ. QTY | T8: REJ. % | U8: LEAKAGE | V8: 90/10 | W8: BUBBLE | X8: THIN SPOD | Y8: OTHERS | AA8: Remarks
A11: 45809 | C11: SUNDAY
A12: 45810 | C12: 10047 | E12: 9713 | G12: 334 | H12: =G12/C12*100 -> 3.3243754 | I12: 58 | J12: 126 | K12: 150 | O12: 10226 | Q12: 10004 | S12: 222 | T12: =S12/O12*100 -> 2.1709368 | U12: 74 | X12: 117 | Y12: 31
A13: 45811 | C13: 9465 | E13: 9361 | G13: 104 | H13: =G13/C13*100 -> 1.098785 | I13: 73 | J13: 16 | K13: 12 | O13: 10626 | Q13: 10479 | S13: 149 | T13: =S13/O13*100 -> 1.402221 | U13: 69 | X13: 54 | Y13: 26
A14: 45812 | C14: 10582 | E14: 10541 | G14: 41 | H14: =G14/C14*100 -> 0.38745039 | I14: 22 | J14: 15 | K14: 4 | O14: 9907 | Q14: 9459 | S14: 448 | T14: =S14/O14*100 -> 4.5220551 | U14: 72 | X14: 331 | Y14: 45
A15: 45813 | C15: 9649 | E15: 9603 | G15: 46 | H15: =G15/C15*100 -> 0.47673334 | I15: 29 | J15: 19 | O15: 12699 | Q15: 11918 | S15: 781 | T15: =S15/O15*100 -> 6.1500906 | U15: 54 | X15: 586 | Y15: 141
A16: 45814 | C16: 10226 | E16: 10169 | G16: 67 | H16: =G16/C16*100 -> 0.65519265 | I16: 39 | J16: 16 | K16: 2 | O16: 11489 | Q16: 11272 | S16: 217 | T16: =S16/O16*100 -> 1.8887632 | U16: 64 | X16: 75 | Y16: 78
A17: 45815 | C17: 10346 | E17: 10290 | G17: 56 | H17: =G17/C17*100 -> 0.54127199 | I17: 36 | J17: 15 | K17: 5 | O17: 10290 | Q17: 9979 | S17: 311 | T17: =S17/O17*100 -> 3.0223518 | U17: 31 | X17: 45 | Y17: 235
A18: 45816 | C18: SUNDAY
A19: 45817 | C19: 10892 | E19: 10805 | G19: 87 | H19: =G19/C19*100 -> 0.79875138 | I19: 6 | J19: 8 | K19: 73 | O19: 10805 | Q19: 10679 | S19: 126 | T19: =S19/O19*100 -> 1.1661268 | U19: 55 | X19: 34 | Y19: 37
A20: 45818 | C20: 10481 | E20: 10065 | G20: 416 | H20: =G20/C20*100 -> 3.9690869 | I20: 10 | J20: 25 | K20: 381 | O20: 10065 | Q20: 9453 | S20: 612 | T20: =S20/O20*100 -> 6.0804769 | U20: 313 | X20: 257 | Y20: 42
A21: 45819 | C21: 10274 | E21: 10168 | G21: 106 | H21: =G21/C21*100 -> 1.0317306 | I21: 29 | J21: 4 | K21: 73 | O21: 10168 | Q21: 9882 | S21: 286 | T21: =S21/O21*100 -> 2.8127459 | U21: 76 | X21: 99 | Y21: 111
A22: 45820 | C22: 10118 | E22: 10071 | G22: 47 | H22: =G22/C22*100 -> 0.46451868 | I22: 24 | J22: 8 | K22: 15 | O22: 10071 | Q22: 9696 | S22: 329 | T22: =S22/O22*100 -> 3.2668057 | U22: 102 | V22: 7 | X22: 11 | Y22: 201
A23: 45821 | C23: 10789 | E23: 10715 | G23: 74 | H23: =G23/C23*100 -> 0.68588377 | I23: 22 | J23: 31 | K23: 21 | O23: 10715 | Q23: 10386 | S23: 329 | T23: =S23/O23*100 -> 3.070462 | U23: 204 | W23: 2 | X23: 35 | Y23: 88
A24: 45822 | C24: 10431 | E24: 10349 | G24: 82 | H24: =G24/C24*100 -> 0.7861183 | I24: 48 | J24: 24 | K24: 10 | O24: 10349 | Q24: 9878 | S24: 471 | T24: =S24/O24*100 -> 4.5511644 | U24: 164 | X24: 229 | Y24: 78
A25: 45823 | C25: SUNDAY
A26: 45824 | C26: 10851 | E26: 10808 | G26: 43 | H26: =G26/C26*100 -> 0.39627684 | I26: 23 | J26: 13 | K26: 7 | O26: 10808 | Q26: 10613 | S26: 285 | T26: =S26/O26*100 -> 2.6369356 | U26: 130 | X26: 35 | Y26: 120
A27: 45825 | C27: 9506 | E27: 9446 | G27: 60 | H27: =G27/C27*100 -> 0.63118031 | I27: 35 | J27: 11 | K27: 14 | O27: 9446 | Q27: 9179 | S27: 267 | T27: =S27/O27*100 -> 2.8265933 | U27: 71 | X27: 82 | Y27: 114
A28: 45826 | C28: 10137 | E28: 10073 | G28: 64 | H28: =G28/C28*100 -> 0.6313505 | I28: 40 | J28: 16 | K28: 8 | O28: 10073 | Q28: 9846 | S28: 227 | T28: =S28/O28*100 -> 2.2535491 | U28: 120 | X28: 18 | Y28: 89
A29: 45827 | C29: 12684 | E29: 12635 | G29: 49 | H29: =G29/C29*100 -> 0.38631347 | I29: 27 | J29: 8 | K29: 14 | O29: 12635 | Q29: 12284 | S29: 351 | T29: =S29/O29*100 -> 2.7779976 | U29: 140 | X29: 16 | Y29: 145
A30: 45828 | C30: 11697 | E30: 11592 | G30: 105 | H30: =G30/C30*100 -> 0.89766607 | I30: 53 | J30: 46 | K30: 6 | O30: 11592 | Q30: 11114 | S30: 478 | T30: =S30/O30*100 -> 4.1235335 | U30: 151 | X30: 189 | Y30: 138
A31: 45829 | C31: 12405 | E31: 12340 | G31: 65 | H31: =G31/C31*100 -> 0.52398227 | I31: 47 | J31: 13 | K31: 5 | O31: 12340 | Q31: 12066 | S31: 274 | T31: =S31/O31*100 -> 2.2204214 | U31: 46 | X31: 56 | Y31: 172
A32: 45830 | C32: 10383 | E32: 10358 | G32: 25 | H32: =G32/C32*100 -> 0.2407782 | I32: 17 | J32: 3 | K32: 5 | O32: 8140 | Q32: 7625 | S32: 515 | T32: =S32/O32*100 -> 6.3267813 | U32: 27 | V32: 2 | X32: 104 | Y32: 382
A33: 45831 | C33: 11300 | E33: 11240 | G33: 60 | H33: =G33/C33*100 -> 0.53097345 | I33: 60 | O33: 12218 | Q33: 11602 | S33: 616 | T33: =S33/O33*100 -> 5.0417417 | U33: 98 | X33: 197 | Y33: 321
A34: 45832 | C34: 10261 | E34: 10218 | G34: 43 | H34: =G34/C34*100 -> 0.41906247 | I34: 7 | J34: 18 | K34: 18 | O34: 10458 | Q34: 10236 | S34: 222 | T34: =S34/O34*100 -> 2.1227768 | U34: 112 | X34: 30 | Y34: 80
A35: 45833 | C35: 10758 | E35: 10730 | G35: 28 | H35: =G35/C35*100 -> 0.26027143 | I35: 19 | J35: 6 | K35: 3 | O35: 10745 | Q35: 10624 | S35: 121 | T35: =S35/O35*100 -> 1.1261052 | U35: 43 | X35: 17 | Y35: 61
A36: 45834 | C36: 9518 | E36: 9497 | G36: 21 | H36: =G36/C36*100 -> 0.22063459 | I36: 12 | J36: 6 | K36: 3 | O36: 10491 | Q36: 10367 | S36: 124 | T36: =S36/O36*100 -> 1.1819655 | U36: 50 | X36: 9 | Y36: 65
A37: 45835 | C37: 13746 | E37: 13720 | G37: 26 | H37: =G37/C37*100 -> 0.18914593 | I37: 12 | J37: 9 | K37: 5 | O37: 12720 | Q37: 12609 | S37: 111 | T37: =S37/O37*100 -> 0.87264151 | U37: 80 | X37: 24 | Y37: 7
A38: 45836 | C38: 11974 | E38: 11940 | G38: 34 | H38: =G38/C38*100 -> 0.28394856 | I38: 24 | K38: 10 | O38: 11940 | Q38: 11809 | S38: 131 | T38: =S38/O38*100 -> 1.0971524 | U38: 113 | X38: 18
A39: 45837 | C39: SUNDAY
A40: 45838 | C40: 12690 | E40: 12672 | G40: 18 | H40: =G40/C40*100 -> 0.14184397 | I40: 13 | J40: 1 | K40: 4 | O40: 12888 | Q40: 12790 | S40: 98 | T40: =S40/O40*100 -> 0.76039727 | U40: 81 | X40: 17
A41: TOTAL | C41: =SUM(C11:D40) -> 281210 | E41: =SUM(E11:E40) -> 279119 | G41: =SUM(G11:G40) -> 2101 | I41: =SUM(I11:I40) -> 785 | J41: =SUM(J11:J40) -> 457 | K41: =SUM(K11:K40) -> 848 | O41: =SUM(O11:P40) -> 283904 | Q41: =SUM(Q11:Q40) -> 275849 | R41: =SUM(R11:R40) -> 0 | S41: =SUM(S11:S40) -> 8101 | U41: =SUM(U11:U40) -> 2540 | V41: =SUM(V11:V40) -> 9 | W41: =SUM(W11:W40) -> 2 | X41: =SUM(X11:X40) -> 2685 | Y41: =SUM(Y11:Y40) -> 2807
A42: TOTAL % | E42: =E41/C41*100 -> 99.256428 | G42: =G41/C41*100 -> 0.74712848 | I42: =I41/C41*100 -> 0.27915081 | J42: =J41/C41*100 -> 0.162512 | K42: =K41/C41*100 -> 0.301554 | O42: TOTAL % | Q42: =Q41/O41*100 -> 97.162773 | R42: =R41/O41*100 -> 0 | S42: =S41/O41*100 -> 2.8534293 | U42: =U41/O41*100 -> 0.89466862 | V42: =V41/O41*100 -> 0.0031700857 | W42: =W41/O41*100 -> 0.00070446348 | Y42: =Y41/O41*100 -> 0.9887145
B51: BALLOON INS. REPORT
B52: STRUCK BALLOON | D52: =I41 -> 785
...

Sheet JULY 2025
C1: DISPOSAFE HEALTH AND LIFE CARE LIMITED Plot No.37A, Sector-06, Ballabgarh (Faridabad) Haryana India 121006 | X1: Doc. No : | Z1: F/ASSEM/03:00
X3: Supersedes : | Z3: 00
X4: Effective Date : | Z4: 45607
C5: DAILY BALLOON & VALVE INTEGRITY REPORT | X5: Page: 1 of 1
A7: BALLOON ISPECTION REPORT - P17 | O7: VALVE INTEGRITY
A8: DATE | C8: CHECKED QTY | E8: ACCEPT QTY | F8: HOLD QTY | G8: REJ. QTY | H8: REJ. % | I8: STRUCK BALLOON | J8: BALLOOM BRUST | K8: LEAKAGE | L8: OTHERS | M8: Remarks | O8: CHECKED QTY | Q8: ACCEPT QTY | R8: HOLD QTY | S8: REJ. QTY | T8: REJ. % | U8: LEAKAGE | V8: 90/10 | W8: BUBBLE | X8: THIN SPOD | Y8: OTHERS | AA8: Remarks
A11: 45839 | C11: 11448 | E11: 11387 | G11: 61 | H11: =G11/C11*100 -> 0.53284416 | I11: 49 | J11: 1 | K11: 11 | O11: 12387 | Q11: 12234 | S11: 153 | T11: =S11/O11*100 -> 1.2351659 | U11: 54 | X11: 94 | Y11: 5
A12: 45840 | C12: 12083 | E12: 12049 | G12: 34 | H12: =G12/C12*100 -> 0.28138707 | I12: 13 | J12: 9 | K12: 12 | O12: 12049 | Q12: 11972 | S12: 77 | T12: =S12/O12*100 -> 0.63905718 | U12: 66 | V12: 1 | X12: 8 | Y12: 3
A13: 45841 | C13: 9565 | E13: 9498 | G13: 67 | H13: =G13/C13*100 -> 0.70047047 | I13: 10 | J13: 17 | K13: 40 | O13: 9498 | Q13: 9362 | S13: 136 | T13: =S13/O13*100 -> 1.4318804 | U13: 58 | V13: 14 | X13: 52 | Y13: 12
A14: 45842 | C14: 11248 | E14: 11193 | G14: 55 | H14: =G14/C14*100 -> 0.48897582 | I14: 27 | J14: 2 | K14: 26 | O14: 11193 | Q14: 11002 | S14: 191 | T14: =S14/O14*100 -> 1.7064237 | U14: 91 | X14: 65 | Y14: 35
A15: 45843 | C15: 12619 | E15: 12578 | G15: 41 | H15: =G15/C15*100 -> 0.32490689 | I15: 16 | J15: 4 | K15: 21 | O15: 12578 | Q15: 12501 | S15: 77 | T15: =S15/O15*100 -> 0.61218 | U15: 56 | V15: 4 | X15: 8 | Y15: 9
A16: WEEKLY | C16: =SUM(C11:D15) -> 56963 | E16: =SUM(E11:E15) -> 56705 | F16: =SUM(F11:F15) -> 0 | G16: =SUM(G11:G15) -> 258 | H16: =G16/C16*100 -> 0.45292558 | I16: =SUM(I11:I15) -> 115 | J16: =SUM(J11:J15) -> 33 | K16: =SUM(K11:K15) -> 110 | L16: =SUM(L11:L15) -> 0 | M16: =SUM(M11:M15) -> 0 | O16: =SUM(O11:P15) -> 57705 | Q16: =SUM(Q11:Q15) -> 57071 | R16: =SUM(R11:R15) -> 0 | S16: =SUM(S11:S15) -> 634 | T16: =S16/O16*100 -> 1.0986916 | U16: =SUM(U11:U15) -> 325 | V16: =SUM(V11:V15) -> 19 | W16: =SUM(W11:W15) -> 0 | X16: =SUM(X11:X15) -> 227 | Y16: =SUM(Y11:Z15) -> 64 | AA16: =SUM(AA11:AA15) -> 0
A17: 45844 | T17: =S17/O17*100 -> #DIV/0!
A18: 45845 | C18: 11752 | E18: 11737 | G18: 15 | H18: =G18/C18*100 -> 0.12763785 | I18: 12 | K18: 3 | O18: 10644 | Q18: 10578 | S18: 66 | T18: =S18/O18*100 -> 0.62006764 | U18: 53 | X18: 5 | Y18: 8
A19: 45846 | C19: 11153 | E19: 11121 | G19: 32 | H19: =G19/C19*100 -> 0.28691832 | I19: 26 | J19: 2 | K19: 4 | O19: 10945 | Q19: 10902 | S19: 43 | T19: =S19/O19*100 -> 0.39287346 | U19: 36 | X19: 5 | Y19: 2
A20: 45847 | C20: 11394 | E20: 11364 | G20: 30 | H20: =G20/C20*100 -> 0.26329647 | I20: 19 | J20: 2 | K20: 9 | O20: 10366 | Q20: 10319 | S20: 47 | T20: =S20/O20*100 -> 0.45340536 | U20: 28 | X20: 11 | Y20: 8
A21: 45848 | C21: 9652 | E21: 9611 | G21: 41 | H21: =G21/C21*100 -> 0.42478243 | I21: 27 | J21: 14 | O21: 9611 | Q21: 9509 | S21: 102 | T21: =S21/O21*100 -> 1.0612839 | U21: 64 | X21: 21 | Y21: 17
A22: 45849 | C22: 10694 | E22: 10661 | G22: 33 | H22: =G22/C22*100 -> 0.30858425 | I22: 16 | J22: 10 | K22: 7 | O22: 10661 | Q22: 10592 | S22: 69 | T22: =S22/O22*100 -> 0.64721884 | U22: 44 | X22: 17 | Y22: 8
A23: 45850 | C23: 11488 | E23: 11447 | G23: 41 | H23: =G23/C23*100 -> 0.35689415 | I23: 33 | J23: 6 | K23: 2 | O23: 11447 | Q23: 11367 | S23: 80 | T23: =S23/O23*100 -> 0.69887307 | U23: 69 | X23: 9 | Y23: 2
A24: WEEKLY 1 | C24: =SUM(C18:D23) -> 66133 | E24: =SUM(E18:E23) -> 65941 | F24: =SUM(F18:F23) -> 0 | G24: =SUM(G18:G23) -> 192 | H24: =G24/C24*100 -> 0.29032404 | I24: =SUM(I18:I23) -> 133 | J24: =SUM(J18:J23) -> 34 | K24: =SUM(K18:K23) -> 25 | L24: =SUM(L18:L23) -> 0 | M24: =SUM(M18:M23) -> 0 | O24: =SUM(O17:P23) -> 63674 | Q24: =SUM(Q18:Q23) -> 63267 | R24: =SUM(R18:R23) -> 0 | S24: =SUM(S18:S23) -> 407 | T24: =S24/O24*100 -> 0.63919339 | U24: =SUM(U18:U23) -> 294 | V24: =SUM(V18:V23) -> 0 | W24: =SUM(W18:W23) -> 0 | X24: =SUM(X18:X23) -> 68 | Y24: =SUM(Y18:Z23) -> 45 | AA24: =SUM(AA18:AA23) -> 0
A25: 45851 | C25: SUNDAY
A26: 45852 | C26: 9998 | E26: 9971 | G26: 27 | H26: =G26/C26*100 -> 0.27005401 | I26: 27 | O26: 9971 | Q26: 9948 | S26: 23 | T26: =S26/O26*100 -> 0.23066894 | U26: 17 | X26: 4 | Y26: 2
A27: 45853 | C27: 10458 | E27: 10422 | G27: 36 | H27: =G27/C27*100 -> 0.34423408 | I27: 36 | O27: 10422 | Q27: 10371 | S27: 51 | T27: =S27/O27*100 -> 0.48934945 | U27: 44 | V27: 1 | X27: 3 | Y27: 3
A28: 45854 | C28: 10839 | E28: 10766 | G28: 73 | H28: =G28/C28*100 -> 0.67349386 | I28: 69 | K28: 4 | O28: 10766 | Q28: 10686 | S28: 80 | T28: =S28/O28*100 -> 0.74308007 | U28: 44 | V28: 7 | X28: 8 | Y28: 21
A29: 45855 | C29: 12473 | E29: 12456 | G29: 17 | H29: =G29/C29*100 -> 0.1362944 | I29: 17 | O29: 12456 | Q29: 12381 | S29: 75 | T29: =S29/O29*100 -> 0.60211946 | U29: 52 | X29: 4 | Y29: 19
A30: 45856 | C30: 11421 | E30: 11396 | G30: 25 | H30: =G30/C30*100 -> 0.21889502 | I30: 22 | K30: 3 | O30: 11396 | Q30: 11378 | S30: 18 | T30: =S30/O30*100 -> 0.15795016 | U30: 9 | V30: 1 | W30: 1 | X30: 5 | Y30: 2
A31: 45857 | C31: 10557 | E31: 10520 | G31: 37 | H31: =G31/C31*100 -> 0.35047836 | I31: 37 | O31: 10520 | Q31: 10500 | S31: 20 | T31: =S31/O31*100 -> 0.19011407 | U31: 16 | W31: 1 | X31: 3
A32: WEEKLY 2 | C32: =SUM(C26:D31) -> 65746 | E32: =SUM(E26:E31) -> 65531 | F32: =SUM(F26:F31) -> 0 | G32: =SUM(G26:G31) -> 215 | H32: =G32/C32*100 -> 0.32701609 | I32: =SUM(I26:I31) -> 208 | J32: =SUM(J26:J31) -> 0 | K32: =SUM(K26:K31) -> 7 | L32: =SUM(L26:L31) -> 0 | M32: =SUM(M26:M31) -> 0 | O32: =SUM(O26:P31) -> 65531 | Q32: =SUM(Q26:Q31) -> 65264 | R32: =SUM(R26:R31) -> 0 | S32: =SUM(S26:S31) -> 267 | T32: =S32/O32*100 -> 0.40744075 | U32: =SUM(U26:U31) -> 182 | V32: =SUM(V26:V31) -> 9 | W32: =SUM(W26:W31) -> 2 | X32: =SUM(X26:X31) -> 27 | Y32: =SUM(Y26:Z31) -> 47 | AA32: =SUM(AA26:AA31) -> 0
A33: 45858 | C33: SUNDAY
A34: 45859 | C34: 11070 | E34: 11041 | G34: 29 | H34: =G34/C34*100 -> 0.26196929 | I34: 25 | J34: 4 | O34: 11041 | Q34: 11012 | S34: 29 | T34: =S34/O34*100 -> 0.26265737 | U34: 29
A35: 45860 | C35: 13366 | E35: 13340 | G35: 17 | H35: =G35/C35*100 -> 0.12718839 | I35: 13 | J35: 4 | O35: 13340 | Q35: 13260 | S35: 89 | T35: =S35/O35*100 -> 0.66716642 | U35: 72 | X35: 15 | Y35: 2
A36: 45861 | C36: 13505 | E36: 13479 | G36: 26 | H36: =G36/C36*100 -> 0.19252129 | I36: 26 | O36: 13479 | Q36: 13469 | S36: 10 | T36: =S36/O36*100 -> 0.07418948 | U36: 6 | X36: 3 | Y36: 1
A37: 45862 | C37: 11893 | E37: 11869 | G37: 24 | H37: =G37/C37*100 -> 0.20179938 | I37: 21 | J37: 2 | K37: 1 | O37: 11869 | Q37: 11860 | S37: 9 | T37: =S37/O37*100 -> 0.075827787 | U37: 5 | X37: 4
A38: 45863 | C38: 13520 | E38: 13488 | G38: 32 | H38: =G38/C38*100 -> 0.23668639 | I38: 2 | O38: 13488 | Q38: 13473 | S38: 15 | T38: =S38/O38*100 -> 0.11120996 | U38: 7 | X38: 8
A39: 45864 | C39: 12451 | E39: 12410 | G39: 41 | H39: =G39/C39*100 -> 0.32929082 | I39: 41 | O39: 12410 | Q39: 12400 | S39: 10 | T39: =S39/O39*100 -> 0.080580177 | U39: 4 | X39: 1 | Y39: 5
A40: WEEKLY 3 | C40: =SUM(C34:D39) -> 75805 | E40: =SUM(E34:E39) -> 75627 | F40: =SUM(F34:F39) -> 0 | G40: =SUM(G34:G39) -> 169 | H40: =G40/C40*100 -> 0.22294044 | I40: =SUM(I34:I39) -> 128 | J40: =SUM(J34:J39) -> 10 | K40: =SUM(K34:K39) -> 1 | L40: =SUM(L34:L39) -> 0 | M40: =SUM(M34:M39) -> 0 | O40: =SUM(O34:P39) -> 75627 | Q40: =SUM(Q34:Q39) -> 75474 | R40: =SUM(R34:R39) -> 0 | S40: =SUM(S34:S39) -> 162 | T40: =S40/O40*100 -> 0.21420921 | U40: =SUM(U34:U39) -> 123 | V40: =SUM(V34:V39) -> 0 | W40: =SUM(W34:W39) -> 0 | X40: =SUM(X34:X39) -> 31 | Y40: =SUM(Y34:Z39) -> 8 | AA40: =SUM(AA34:AA39) -> 0
A41: 45865 | C41: SUNDAY
A42: 45866 | C42: 11082 | E42: 11068 | G42: 14 | H42: =G42/C42*100 -> 0.12633099 | I42: 13 | J42: 1 | O42: 11074 | Q42: 11061 | S42: 13 | T42: =S42/O42*100 -> 0.11739209 | U42: 10 | X42: 3
A43: 45867 | C43: 13451 | E43: 13422 | G43: 29 | H43: =G43/C43*100 -> 0.21559735 | I43: 29 | O43: 13416 | Q43: 13369 | S43: 47 | T43: =S43/O43*100 -> 0.35032797 | U43: 46 | X43: 1
A44: 45868 | C44: 9594 | E44: 9571 | G44: 23 | H44: =G44/C44*100 -> 0.23973317 | I44: 20 | J44: 2 | K44: 1 | O44: 9571 | Q44: 9532 | S44: 39 | T44: =S44/O44*100 -> 0.40748093 | U44: 7 | X44: 25 | Y44: 7
...

Sheet AUGUST 2025
C1: DISPOSAFE HEALTH AND LIFE CARE LIMITED Plot No.37A, Sector-06, Ballabgarh (Faridabad) Haryana India 121006 | X1: Doc. No : | Z1: F/ASSEM/03:00
X3: Supersedes : | Z3: 00
X4: Effective Date : | Z4: 45607
C5: DAILY BALLOON & VALVE INTEGRITY REPORT | X5: Page: 1 of 1
A7: BALLOON ISPECTION REPORT - P17 | O7: VALVE INTEGRITY
A8: DATE | C8: CHECKED QTY | E8: ACCEPT QTY | F8: HOLD QTY | G8: REJ. QTY | H8: REJ. % | I8: STRUCK BALLOON | J8: BALLOOM BRUST | K8: LEAKAGE | L8: OTHERS | M8: Remarks | O8: CHECKED QTY | Q8: ACCEPT QTY | R8: HOLD QTY | S8: REJ. QTY | T8: REJ. % | U8: LEAKAGE | V8: 90/10 | W8: BUBBLE | X8: THIN SPOD | Y8: OTHERS | AA8: Remarks
A11: 45870 | C11: 11911 | E11: 11886 | G11: 25 | H11: =G11/C11*100 -> 0.20989002 | I11: 24 | J11: 1 | O11: 11886 | Q11: 11845 | S11: 41 | T11: =S11/O11*100 -> 0.34494363 | U11: 30 | X11: 6 | Y11: 5
A12: 45871 | C12: 11330 | E12: 11154 | G12: 10 | H12: =G12/C12*100 -> 0.088261253 | I12: 4 | J12: 6 | O12: 11149 | Q12: 11109 | S12: 40 | T12: =S12/O12*100 -> 0.35877657 | U12: 36 | X12: 4
A13: WEEKLY 1 | C13: =SUM(C11:D12) -> 23241 | E13: =SUM(E11:E12) -> 23040 | F13: =SUM(F11:F12) -> 0 | G13: =SUM(G11:G12) -> 35 | H13: =G13/C13*100 -> 0.15059593 | I13: =SUM(I11:I12) -> 28 | J13: =SUM(J11:J12) -> 7 | K13: =SUM(K11:K12) -> 0 | L13: =SUM(L11:L12) -> 0 | M13: =SUM(M11:M12) -> 0 | O13: =SUM(O11:P12) -> 23035 | Q13: =SUM(Q11:Q12) -> 22954 | R13: =SUM(R11:R12) -> 0 | S13: =SUM(S11:S12) -> 81 | T13: =S13/O13*100 -> 0.35163881 | U13: =SUM(U11:U12) -> 66 | V13: =SUM(V11:V12) -> 0 | W13: =SUM(W11:W12) -> 0 | X13: =SUM(X11:X12) -> 10 | Y13: =SUM(Y11:Z12) -> 5 | AA13: =SUM(AA11:AA12) -> 0
A14: 45872 | H14: =G14/C14*100 -> #DIV/0! | T14: =S14/O14*100 -> #DIV/0!
A15: 45873 | C15: 11108 | E15: 11103 | G15: 5 | H15: =G15/C15*100 -> 0.045012604 | I15: 5 | O15: 8103 | Q15: 8080 | S15: 23 | T15: =S15/O15*100 -> 0.28384549 | U15: 7 | X15: 16
A16: 45874 | C16: 11104 | E16: 1105 | G16: 54 | H16: =G16/C16*100 -> 0.48631124 | I16: 12 | J16: 7 | K16: 35 | O16: 9136 | Q16: 8717 | S16: 419 | T16: =S16/O16*100 -> 4.5862522 | U16: 80 | X16: 235 | Y16: 104
A17: 45875 | C17: 9696 | E17: 9682 | G17: 14 | H17: =G17/C17*100 -> 0.14438944 | I17: 14 | O17: 13059 | Q17: 13036 | S17: 23 | T17: =S17/O17*100 -> 0.17612375 | U17: 10 | V17: 1 | W17: 2 | X17: 2 | Y17: 8
A18: 45876 | C18: 10891 | E18: 10881 | G18: 10 | H18: =G18/C18*100 -> 0.091818933 | I18: 10 | O18: 12418 | Q18: 12396 | S18: 22 | T18: =S18/O18*100 -> 0.17716218 | U18: 20 | X18: 2
A19: 45877 | C19: 8078 | E19: 8049 | G19: 9 | H19: =G19/C19*100 -> 0.11141372 | I19: 9 | O19: 8049 | Q19: 8028 | S19: 21 | T19: =S19/O19*100 -> 0.26090198 | U19: 14 | X19: 7
A20: 45878 | C20: HOLIDAY | H20: =G20/C20*100 -> #VALUE! | T20: =S20/O20*100 -> #DIV/0!
A21: WEEKLY 2 | C21: =SUM(C14:D20) -> 50877 | E21: =SUM(E14:E20) -> 40820 | F21: =SUM(F14:F20) -> 0 | G21: =SUM(G14:G20) -> 92 | H21: =G21/C21*100 -> 0.18082827 | I21: =SUM(I14:I20) -> 50 | J21: =SUM(J14:J20) -> 7 | K21: =SUM(K14:K20) -> 35 | L21: =SUM(L14:L20) -> 0 | M21: =SUM(M14:M20) -> 0 | O21: =SUM(O14:P20) -> 50765 | Q21: =SUM(Q15:Q20) -> 50257 | R21: =SUM(R15:R20) -> 0 | S21: =SUM(S15:S20) -> 508 | T21: =S21/O21*100 -> 1.0006895 | U21: =SUM(U15:U20) -> 131 | V21: =SUM(V15:V20) -> 1 | W21: =SUM(W15:W20) -> 2 | X21: =SUM(X15:X20) -> 262 | Y21: =SUM(Y15:Y20) -> 112 | AA21: =SUM(AA15:AA20) -> 0
A22: 45879 | H22: =G22/C22*100 -> #DIV/0! | T22: =S22/O22*100 -> #DIV/0!
A23: 45880 | C23: 9570 | E23: 9558 | G23: 12 | H23: =G23/C23*100 -> 0.12539185 | I23: 12 | O23: 7217 | Q23: 7181 | S23: 36 | T23: =S23/O23*100 -> 0.49882223 | U23: 29 | W23: 6 | X23: 1
A24: 45881 | C24: 7334 | E24: 7255 | G24: 79 | H24: =G24/C24*100 -> 1.0771748 | I24: 50 | K24: 29 | O24: 9069 | Q24: 9032 | S24: 37 | T24: =S24/O24*100 -> 0.40798324 | U24: 34 | W24: 1 | Y24: 2
A25: 45882 | C25: 8183 | E25: 8080 | G25: 49 | H25: =G25/C25*100 -> 0.5988024 | O25: 8048 | Q25: 8032 | S25: 16 | T25: =S25/O25*100 -> 0.19880716 | U25: 15 | Y25: 1
A26: 45883 | C26: 8455 | E26: 8408 | G26: 47 | H26: =G26/C26*100 -> 0.55588409 | I26: 46 | J26: 1 | O26: 8887 | Q26: 8869 | S26: 18 | T26: =S26/O26*100 -> 0.20254304 | U26: 17 | X26: 1
A27: 45884 | C27: HOLIDAY
A28: 45885 | C28: HOLIDAY
A29: WEEKLY 3 | C29: =SUM(C22:D28) -> 33542 | E29: =SUM(E22:E28) -> 33301 | F29: =SUM(F22:F28) -> 0 | G29: =SUM(G22:G28) -> 187 | H29: =G29/C29*100 -> 0.55750999 | I29: =SUM(I22:I28) -> 108 | J29: =SUM(J22:J28) -> 1 | K29: =SUM(K22:K28) -> 29 | L29: =SUM(L22:L28) -> 0 | M29: =SUM(M22:M28) -> 0 | O29: =SUM(O22:P28) -> 33221 | Q29: =SUM(Q23:Q28) -> 33114 | R29: =SUM(R23:R28) -> 0 | S29: =SUM(S23:S28) -> 107 | T29: =S29/O29*100 -> 0.32208543 | U29: =SUM(U23:U28) -> 95 | V29: =SUM(V23:V28) -> 0 | W29: =SUM(W23:W28) -> 7 | X29: =SUM(X23:X28) -> 2 | Y29: =SUM(Y23:Y28) -> 3 | AA29: =SUM(AA23:AA28) -> 0
A30: 45886 | C30: 8240 | E30: 8209 | G30: 33 | H30: =G30/C30*100 -> 0.40048544 | I30: 33 | O30: 5929 | Q30: 5886 | S30: 23 | T30: =S30/O30*100 -> 0.38792376 | U30: 21 | X30: 2
A31: 45887 | C31: 7808 | E31: 7776 | G31: 32 | H31: =G31/C31*100 -> 0.40983607 | I31: 32 | O31: 100561 | Q31: 10037 | S31: 19 | T31: =S31/O31*100 -> 0.018894005 | U31: 19
A32: 45888 | C32: 13121 | E32: 13098 | G32: 23 | H32: =G32/C32*100 -> 0.17529152 | I32: 22 | J32: 1 | O32: 7690 | Q32: 703 | S32: 67 | T32: =S32/O32*100 -> 0.87126138 | U32: 14 | X32: 53
A33: 45889 | C33: 12865 | E33: 12822 | G33: 38 | H33: =G33/C33*100 -> 0.29537505 | I33: 38 | O33: 10848 | Q33: 10704 | S33: 144 | T33: =S33/O33*100 -> 1.3274336 | U33: 9 | X33: 135
A34: 45890 | C34: 11422 | E34: 11393 | G34: 29 | H34: =G34/C34*100 -> 0.25389599 | I34: 3 | J34: 26 | O34: 10788 | Q34: 10715 | S34: 73 | T34: =S34/O34*100 -> 0.67667779 | U34: 9 | X34: 62 | Y34: 2
A35: 45891 | C35: 10571 | E35: 10544 | G35: 27 | H35: =G35/C35*100 -> 0.25541576 | I35: 27 | O35: 11557 | Q35: 11140 | S35: 417 | T35: =S35/O35*100 -> 3.6082028 | U35: 59 | X35: 339 | Y35: 19
A36: 45892 | C36: 13789 | E36: 13776 | G36: 13 | H36: =G36/C36*100 -> 0.094278048 | I36: 10 | J36: 3 | O36: 13944 | Q36: 13830 | S36: 114 | T36: =S36/O36*100 -> 0.81755594 | U36: 50 | X36: 46 | Y36: 18
A37: WEEKLY 4 | C37: =SUM(C30:D36) -> 77816 | E37: =SUM(E30:E36) -> 77618 | F37: =SUM(F30:F36) -> 0 | G37: =SUM(G30:G36) -> 195 | H37: =G37/C37*100 -> 0.25059114 | I37: =SUM(I30:I36) -> 165 | J37: =SUM(J30:J36) -> 30 | K37: =SUM(K30:K36) -> 0 | L37: =SUM(L30:L36) -> 0 | M37: =SUM(M30:M36) -> 0 | O37: =SUM(O30:P36) -> 161317 | Q37: =SUM(Q30:Q36) -> 63015 | R37: =SUM(R30:R36) -> 0 | S37: =SUM(S30:S36) -> 857 | T37: =S37/O37*100 -> 0.53125213 | U37: =SUM(U30:U36) -> 181 | V37: =SUM(V30:V36) -> 0 | W37: =SUM(W30:W36) -> 0 | X37: =SUM(X30:X36) -> 637 | Y37: =SUM(Y30:Z36) -> 39 | AA37: =SUM(AA30:AA36) -> 0
A38: 45893 | H38: =G38/C38*100 -> #DIV/0! | T38: =S38/O38*100 -> #DIV/0!
A39: 45894 | C39: 10091 | E39: 10078 | G39: 13 | H39: =G39/C39*100 -> 0.12882767 | I39: 13 | O39: 11115 | Q39: 10524 | S39: 861 | T39: =S39/O39*100 -> 7.7462888 | U39: 12 | X39: 833 | Y39: 16
A40: 45895 | C40: 11695 | E40: 11666 | G40: 29 | H40: =G40/C40*100 -> 0.24796922 | I40: 21 | J40: 6 | K40: 2 | O40: 13991 | Q40: 13724 | S40: 267 | T40: =S40/O40*100 -> 1.9083697 | U40: 25 | W40: 1 | X40: 175 | Y40: 66
A41: 45896 | C41: 9025 | E41: 8972 | G41: 53 | H41: =G41/C41*100 -> 0.58725762 | I41: 43 | J41: 10 | O41: 12422 | Q41: 12162 | S41: 260 | T41: =S41/O41*100 -> 2.0930607 | U41: 28 | X41: 202 | Y41: 30
A42: 45897 | C42: 11884 | E42: 11864 | G42: 20 | H42: =G42/C42*100 -> 0.1682935 | J42: 20 | O42: 11864 | Q42: 11833 | S42: 31 | T42: =S42/O42*100 -> 0.26129467 | U42: 5 | X42: 25 | Y42: 1
A43: 45898 | C43: 12461 | E43: 12426 | G43: 35 | H43: =G43/C43*100 -> 0.28087633 | I43: 31 | J43: 4 | O43: 12426 | Q43: 12108 | S43: 318 | T43: =S43/O43*100 -> 2.5591502 | U43: 21 | X43: 291 | Y43: 6
A44: 45899 | C44: 12947 | E44: 12922 | G44: 25 | H44: =G44/C44*100 -> 0.19309493 | I44: 9 | J44: 16 | O44: 11439 | Q44: 11387 | S44: 52 | T44: =S44/O44*100 -> 0.45458519 | U44: 3 | X44: 45 | Y44: 4
...

Sheet SEPTEMBER 2025
C1: DISPOSAFE HEALTH AND LIFE CARE LIMITED Plot No.37A, Sector-06, Ballabgarh (Faridabad) Haryana India 121006 | W1: Doc. No : | Y1: F/ASSEM/03:00
W3: Supersedes : | Y3: 00
W4: Effective Date : | Y4: 45607
C5: DAILY BALLOON & VALVE INTEGRITY REPORT | W5: Page: 1 of 1
A7: BALLOON ISPECTION REPORT - P17 | N7: VALVE INTEGRITY
A8: DATE | C8: CHECKED QTY | D8: ACCEPT QTY | E8: HOLD QTY | F8: REJ. QTY | G8: REJ. % | H8: STRUCK BALLOON | I8: BALLOOM BRUST | J8: LEAKAGE | K8: OTHERS | L8: Remarks | N8: CHECKED QTY | P8: ACCEPT QTY | Q8: HOLD QTY | R8: REJ. QTY | S8: REJ. % | T8: LEAKAGE | U8: 90/10 | V8: BUBBLE | W8: THIN SPOD | X8: OTHERS | Z8: Remarks
A11: 45901 | C11: 10967 | D11: 10930 | F11: 37 | G11: =F11/C11*100 -> 0.33737576 | H11: 17 | I11: 9 | J11: 11 | N11: 11477 | P11: 11397 | R11: 80 | S11: =R11/N11*100 -> 0.69704627 | T11: 9 | W11: 67 | X11: 4
A12: 45902 | C12: 11858 | D12: 11817 | F12: 46 | G12: =F12/C12*100 -> 0.38792376 | H12: 38 | I12: 5 | J12: 3 | N12: 12748 | P12: 12495 | R12: 253 | S12: =R12/N12*100 -> 1.984625 | T12: 132 | W12: 83 | X12: 38
A13: 45903 | C13: 11554 | D13: 11529 | F13: 25 | G13: =F13/C13*100 -> 0.21637528 | H13: 17 | I13: 8 | N13: 11529 | P13: 11363 | R13: 166 | S13: =R13/N13*100 -> 1.4398473 | T13: 25 | W13: 95 | X13: 46
A14: 45904 | C14: 14519 | D14: 14508 | F14: 11 | G14: =F14/C14*100 -> 0.075762794 | H14: 10 | I14: 1 | N14: 8798 | P14: 8791 | R14: 7 | S14: =R14/N14*100 -> 0.079563537 | W14: 3 | X14: 4
A15: 45905 | C15: 12736 | D15: 12730 | F15: 6 | G15: =F15/C15*100 -> 0.047110553 | H15: 6 | N15: 13192 | P15: 13180 | R15: 12 | S15: =R15/N15*100 -> 0.090964221 | T15: 2 | W15: 5 | X15: 5
A16: 45906 | C16: 11786 | D16: 11782 | F16: 4 | G16: =F16/C16*100 -> 0.033938571 | H16: 4 | N16: 13029 | P16: 12997 | R16: 32 | S16: =R16/N16*100 -> 0.24560596 | T16: 3 | W16: 21 | X16: 8
A17: WEEKLY 1 | C17: =SUM(C11:C16) -> 73420 | D17: =SUM(D11:D16) -> 73296 | E17: =SUM(E11:E16) -> 0 | F17: =SUM(F11:F16) -> 129 | G17: =F17/C17*100 -> 0.17570144 | H17: =SUM(H11:H16) -> 92 | I17: =SUM(I11:I16) -> 23 | J17: =SUM(J11:J16) -> 14 | K17: =SUM(K11:K16) -> 0 | L17: =SUM(L11:L16) -> 0 | N17: =SUM(N11:O16) -> 70773 | P17: =SUM(P11:P16) -> 70223 | Q17: =SUM(Q11:Q16) -> 0 | R17: =SUM(R11:R16) -> 550 | S17: =R17/N17*100 -> 0.77713252 | T17: =SUM(T11:T16) -> 171 | U17: =SUM(U11:U16) -> 0 | V17: =SUM(V11:V16) -> 0 | W17: =SUM(W11:W16) -> 274 | X17: =SUM(X11:Y16) -> 105 | Z17: =SUM(Z11:Z16) -> 0
A18: 45907 | G18: =F18/C18*100 -> #DIV/0! | S18: =R18/N18*100 -> #DIV/0!
A19: 45908 | C19: 13650 | D19: 13642 | F19: 8 | G19: =F19/C19*100 -> 0.058608059 | H19: 7 | I19: 1 | N19: 14640 | P19: 14625 | R19: 15 | S19: =R19/N19*100 -> 0.10245902 | T19: 1 | W19: 12 | X19: 2
A20: 45909 | C20: 12705 | D20: 12675 | F20: 30 | G20: =F20/C20*100 -> 0.23612751 | H20: 28 | I20: 2 | N20: 11915 | P20: 11905 | R20: 10 | S20: =R20/N20*100 -> 0.083927822 | T20: 6 | W20: 4
A21: 45910 | C21: 13817 | D21: 13779 | F21: 38 | G21: =F21/C21*100 -> 0.27502352 | H21: 37 | I21: 1 | N21: 13545 | P21: 13494 | R21: 51 | S21: =R21/N21*100 -> 0.3765227 | T21: 3 | W21: 41 | X21: 7
A22: 45911 | C22: 10444 | D22: 10426 | F22: 18 | G22: =F22/C22*100 -> 0.17234776 | H22: 14 | I22: 4 | N22: 12423 | P22: 12364 | R22: 59 | S22: =R22/N22*100 -> 0.47492554 | T22: 6 | V22: 1 | W22: 41 | X22: 11
A23: 45912 | C23: 11328 | D23: 11296 | F23: 32 | G23: =F23/C23*100 -> 0.28248588 | H23: 20 | I23: 12 | N23: 11012 | P23: 10651 | R23: 361 | S23: =R23/N23*100 -> 3.2782419 | T23: 8 | W23: 312 | X23: 41
A24: 45913 | C24: 9586 | D24: 9529 | F24: 57 | G24: =F24/C24*100 -> 0.59461715 | H24: 57 | N24: 11816 | P24: 11634 | R24: 182 | S24: =R24/N24*100 -> 1.5402844 | T24: 42 | W24: 55 | X24: 85
A25: WEEKLY 2 | C25: =SUM(C18:C24) -> 71530 | D25: =SUM(D18:D24) -> 71347 | E25: =SUM(E18:E24) -> 0 | F25: =SUM(F18:F24) -> 183 | G25: =F25/C25*100 -> 0.25583671 | H25: =SUM(H18:H24) -> 163 | I25: =SUM(I18:I24) -> 20 | J25: =SUM(J18:J24) -> 0 | K25: =SUM(K18:K24) -> 0 | L25: =SUM(L18:L24) -> 0 | N25: =SUM(N18:O24) -> 75351 | P25: =SUM(P18:P24) -> 74673 | Q25: =SUM(Q18:Q24) -> 0 | R25: =SUM(R18:R24) -> 678 | S25: =R25/N25*100 -> 0.89978899 | T25: =SUM(T18:T24) -> 66 | U25: =SUM(U18:U24) -> 0 | V25: =SUM(V18:V24) -> 1 | W25: =SUM(W18:W24) -> 465 | X25: =SUM(X18:Y24) -> 146 | Z25: =SUM(Z18:Z24) -> 0
A26: 45914 | G26: =F26/C26*100 -> #DIV/0! | S26: =R26/N26*100 -> #DIV/0!
A27: 45915 | C27: 11571 | D27: 11502 | F27: 64 | G27: =F27/C27*100 -> 0.55310691 | H27: 62 | I27: 2 | N27: 10753 | P27: 10604 | R27: 149 | S27: =R27/N27*100 -> 1.3856598 | T27: 15 | W27: 113 | X27: 21
A28: 45916 | C28: 10972 | D28: 10941 | F28: 31 | G28: =F28/C28*100 -> 0.28253737 | H28: 29 | I28: 2 | N28: 11715 | P28: 11684 | R28: 31 | S28: =R28/N28*100 -> 0.26461801 | T28: 6 | W28: 25
A29: 45917 | C29: 10508 | D29: 10459 | F29: 49 | G29: =F29/C29*100 -> 0.46631138 | H29: 44 | I29: 5 | N29: 10459 | P29: 10399 | R29: 60 | S29: =R29/N29*100 -> 0.57366861 | T29: 15 | W29: 37 | X29: 8
A30: 45918 | C30: 16601 | D30: 16554 | F30: 47 | G30: =F30/C30*100 -> 0.28311547 | H30: 47 | N30: 16554 | P30: 16481 | R30: 73 | S30: =R30/N30*100 -> 0.44098103 | T30: 28 | W30: 43 | X30: 2
A31: 45919 | C31: 9729 | D31: 9640 | F31: 89 | G31: =F31/C31*100 -> 0.91479083 | H31: 66 | I31: 23 | N31: 9640 | P31: 9332 | R31: 308 | S31: =R31/N31*100 -> 3.1950207 | T31: 44 | W31: 186 | X31: 78
A32: 45920 | C32: 14316 | D32: 14292 | F32: 24 | G32: =F32/C32*100 -> 0.16764459 | H32: 22 | I32: 2 | N32: 13443 | P32: 13371 | R32: 72 | S32: =R32/N32*100 -> 0.53559473 | T32: 4 | W32: 66 | X32: 2
A33: WEEKLY 3 | C33: =SUM(C26:C32) -> 73697 | D33: =SUM(D26:D32) -> 73388 | E33: =SUM(E26:E32) -> 0 | F33: =SUM(F26:F32) -> 304 | G33: =F33/C33*100 -> 0.41249983 | H33: =SUM(H26:H32) -> 270 | I33: =SUM(I26:I32) -> 34 | J33: =SUM(J26:J32) -> 0 | K33: =SUM(K26:K32) -> 0 | L33: =SUM(L26:L32) -> 0 | N33: =SUM(N26:O32) -> 72564 | P33: =SUM(P27:P32) -> 71871 | Q33: =SUM(Q27:Q32) -> 0 | R33: =SUM(R27:R32) -> 693 | S33: =R33/N33*100 -> 0.95501902 | T33: =SUM(T27:T32) -> 112 | U33: =SUM(U27:U32) -> 0 | V33: =SUM(V27:V32) -> 0 | W33: =SUM(W27:W32) -> 470 | X33: =SUM(X27:X32) -> 111 | Z33: =SUM(Z27:Z32) -> 0
A34: 45921 | G34: =F34/C34*100 -> #DIV/0! | S34: =R34/N34*100 -> #DIV/0!
A35: 45922 | C35: 10523 | D35: 10486 | F35: 37 | G35: =F35/C35*100 -> 0.35161076 | H35: 28 | I35: 9 | N35: 1335 | P35: 11168 | R35: 167 | S35: =R35/N35*100 -> 12.509363 | T35: 10 | W35: 144 | X35: 13
A36: 45923 | C36: 14259 | D36: 14228 | F36: 31 | G36: =F36/C36*100 -> 0.21740655 | H36: 27 | I36: 4 | N36: 14225 | P36: 14127 | R36: 101 | S36: =R36/N36*100 -> 0.71001757 | T36: 7 | U36: 3 | V36: 1 | W36: 90
A37: 45924 | C37: 12251 | D37: 12238 | F37: 31 | G37: =F37/C37*100 -> 0.25304057 | H37: 11 | I37: 1 | J37: 1 | N37: 11453 | P37: 11290 | R37: 163 | S37: =R37/N37*100 -> 1.4232079 | T37: 12 | W37: 151
A38: 45925 | C38: 12536 | D38: 12500 | F38: 36 | G38: =F38/C38*100 -> 0.28717294 | H38: 22 | I38: 14 | N38: 13285 | P38: 13202 | R38: 83 | S38: =R38/N38*100 -> 0.62476477 | T38: 2 | W38: 74 | X38: 7
A39: 45926 | C39: 11079 | D39: 11030 | F39: 49 | G39: =F39/C39*100 -> 0.44227818 | H39: 29 | I39: 8 | J39: 12 | N39: 9564 | P39: 8271 | R39: 1293 | S39: =R39/N39*100 -> 13.519448 | T39: 12 | U39: 899 | W39: 370 | X39: 12
A40: 45927 | C40: 11094 | D40: 10971 | F40: 123 | G40: =F40/C40*100 -> 1.1087074 | H40: 87 | I40: 21 | J40: 15 | N40: 12434 | P40: 11232 | R40: 1202 | S40: =R40/N40*100 -> 9.667042 | T40: 109 | U40: 658 | V40: 1 | W40: 412 | X40: 22
A41: WEEKLY 4 | C41: =SUM(C34:C40) -> 71742 | D41: =SUM(D34:D40) -> 71453 | E41: =SUM(E34:E40) -> 0 | F41: =SUM(F34:F40) -> 307 | G41: =F41/C41*100 -> 0.42792228 | H41: =SUM(H34:H40) -> 204 | I41: =SUM(I34:I40) -> 57 | J41: =SUM(J34:J40) -> 28 | K41: =SUM(K34:K40) -> 0 | L41: =SUM(L34:L40) -> 0 | N41: =SUM(N34:O40) -> 62296 | P41: =SUM(P34:P40) -> 69290 | Q41: =SUM(Q34:Q40) -> 0 | R41: =SUM(R34:R40) -> 3009 | S41: =R41/N41*100 -> 4.8301657 | T41: =SUM(T34:T40) -> 152 | U41: =SUM(U34:U40) -> 1560 | V41: =SUM(V34:V40) -> 2 | W41: =SUM(W34:W40) -> 1241 | X41: =SUM(X34:Y40) -> 54 | Z41: =SUM(Z34:Z40) -> 0
A42: 45928 | G42: =F42/C42*100 -> #DIV/0! | S42: =R42/N42*100 -> #DIV/0!
A43: 45929 | C43: 12630 | D43: 12591 | F43: 38 | G43: =F43/C43*100 -> 0.30087094 | H43: 36 | I43: 3 | N43: 10021 | P43: 9883 | R43: 138 | S43: =R43/N43*100 -> 1.3771081 | T43: 9 | W43: 129
A44: 45930 | C44: 8894 | D44: 8876 | F44: 18 | G44: =F44/C44*100 -> 0.20238363 | H44: 18 | N44: 8914 | P44: 8592 | R44: 322 | S44: =R44/N44*100 -> 3.6122953 | T44: 5 | W44: 254 | X44: 63
...

Sheet OCTOBER 2025
C1: DISPOSAFE HEALTH AND LIFE CARE LIMITED Plot No.37A, Sector-06, Ballabgarh (Faridabad) Haryana India 121006 | W1: Doc. No : | Y1: F/ASSEM/03:00
W3: Supersedes : | Y3: 00
W4: Effective Date : | Y4: 45607
C5: DAILY BALLOON & VALVE INTEGRITY REPORT | W5: Page: 1 of 1
A7: BALLOON ISPECTION REPORT - P17 | N7: VALVE INTEGRITY
A8: DATE | C8: CHECKED QTY | D8: ACCEPT QTY | E8: HOLD QTY | F8: REJ. QTY | G8: REJ. % | H8: STRUCK BALLOON | I8: BALLOOM BRUST | J8: LEAKAGE | K8: OTHERS | L8: Remarks | N8: CHECKED QTY | P8: ACCEPT QTY | Q8: HOLD QTY | R8: REJ. QTY | S8: REJ. % | T8: LEAKAGE | U8: 90/10 | V8: BUBBLE | W8: THIN SPOD | X8: OTHERS | Z8: Remarks
A11: 45931 | C11: 9602 | D11: 9427 | F11: 175 | G11: =F11/C11*100 -> 1.822537 | H11: 55 | I11: 100 | J11: 20 | N11: 12019 | P11: 11157 | R11: 62 | S11: =R11/N11*100 -> 0.5158499 | T11: 6 | W11: 55 | X11: 1
A12: 45932 | C12: VIJAYA DASHMI
A13: 45933 | C13: 11083 | D13: 11011 | F13: 72 | G13: =F13/C13*100 -> 0.6496436 | H13: 70 | I13: 2 | N13: 11019 | P13: 10857 | R13: 162 | S13: =R13/N13*100 -> 1.4701879 | T13: 7 | U13: 53 | W13: 102
A14: 45934 | C14: 10522 | D14: 10377 | F14: 145 | G14: =F14/C14*100 -> 1.378065 | H14: 142 | I14: 1 | N14: 10377 | P14: 10345 | R14: 32 | S14: =R14/N14*100 -> 0.30837429 | U14: 2 | W14: 30
A15: WEEKLY 1 | C15: =SUM(C11:C14) -> 31207 | D15: =SUM(D11:D14) -> 30815 | E15: =SUM(E11:E14) -> 0 | F15: =SUM(F11:F14) -> 392 | G15: =F15/C15*100 -> 1.2561284 | H15: =SUM(H11:H14) -> 267 | I15: =SUM(I11:I14) -> 103 | J15: =SUM(J11:J14) -> 20 | K15: =SUM(K11:K14) -> 0 | L15: =SUM(L11:L14) -> 0 | N15: =SUM(N11:O14) -> 33415 | P15: =SUM(P11:P14) -> 32359 | Q15: =SUM(Q11:Q14) -> 0 | R15: =SUM(R11:R14) -> 256 | S15: =R15/N15*100 -> 0.766123 | T15: =SUM(T11:T14) -> 13 | U15: =SUM(U11:U14) -> 55 | V15: =SUM(V11:V14) -> 0 | W15: =SUM(W11:W14) -> 187 | X15: =SUM(X11:Y14) -> 1 | Z15: =SUM(Z11:Z14) -> 0
A16: 45935 | G16: =F16/C16*100 -> #DIV/0! | S16: =R16/N16*100 -> #DIV/0!
A17: 45936 | C17: 10913 | D17: 10724 | F17: 189 | G17: =F17/C17*100 -> 1.7318794 | H17: 182 | I17: 7 | N17: 10724 | P17: 10677 | R17: 47 | S17: =R17/N17*100 -> 0.4382693 | T17: 18 | U17: 4 | V17: 2 | W17: 23
A18: 45937 | C18: 9571 | D18: 9230 | F18: 69 | G18: =F18/C18*100 -> 0.7209278 | H18: 67 | I18: 2 | N18: 9230 | P18: 9217 | R18: 13 | S18: =R18/N18*100 -> 0.14084507 | W18: 12 | X18: 1
A19: 45938 | C19: 7944 | D19: 7841 | F19: 103 | G19: =F19/C19*100 -> 1.296576 | H19: 78 | I19: 23 | J19: 2 | N19: 7841 | P19: 7723 | R19: 118 | S19: =R19/N19*100 -> 1.5049101 | T19: 56 | V19: 1 | W19: 59 | X19: 2
A20: 45939 | C20: 7894 | D20: 7688 | F20: 206 | G20: =F20/C20*100 -> 2.6095769 | H20: 85 | I20: 93 | J20: 28 | N20: 7707 | P20: 7394 | R20: 313 | S20: =R20/N20*100 -> 4.061243 | T20: 191 | W20: 122
A21: 45940 | C21: 7181 | D21: 7065 | F21: 116 | G21: =F21/C21*100 -> 1.6153739 | H21: 114 | J21: 2 | N21: 7046 | P21: 6996 | R21: 50 | S21: =R21/N21*100 -> 0.70962248 | T21: 18 | W21: 31 | X21: 1
A22: 45941 | C22: 7578 | D22: 7479 | F22: 99 | G22: =F22/C22*100 -> 1.3064133 | H22: 86 | I22: 8 | J22: 5 | N22: 7479 | P22: 7361 | R22: 118 | S22: =R22/N22*100 -> 1.577751 | W22: 74 | X22: 44
A23: WEEKLY 2 | C23: =SUM(C16:C22) -> 51081 | D23: =SUM(D16:D22) -> 50027 | E23: =SUM(E16:E22) -> 0 | F23: =SUM(F16:F22) -> 782 | G23: =F23/C23*100 -> 1.5309019 | H23: =SUM(H16:H22) -> 612 | I23: =SUM(I16:I22) -> 133 | J23: =SUM(J16:J22) -> 37 | K23: =SUM(K16:K22) -> 0 | L23: =SUM(L16:L22) -> 0 | N23: =SUM(N16:O22) -> 50027 | P23: =SUM(P16:P22) -> 49368 | Q23: =SUM(Q16:Q22) -> 0 | R23: =SUM(R16:R22) -> 659 | S23: =R23/N23*100 -> 1.3172887 | T23: =SUM(T16:T22) -> 283 | U23: =SUM(U16:U22) -> 4 | V23: =SUM(V16:V22) -> 3 | W23: =SUM(W16:W22) -> 321 | X23: =SUM(X16:Y22) -> 48 | Z23: =SUM(Z16:Z22) -> 0
A24: 45942 | G24: =F24/C24*100 -> #DIV/0! | S24: =R24/N24*100 -> #DIV/0!
A25: 45943 | C25: 8993 | D25: 8884 | F25: 109 | G25: =F25/C25*100 -> 1.2120538 | H25: 97 | I25: 12 | N25: 8506 | P25: 8402 | R25: 104 | S25: =R25/N25*100 -> 1.2226664 | T25: 2 | W25: 102
A26: 45944 | C26: 7687 | D26: 7546 | F26: 141 | G26: =F26/C26*100 -> 1.8342656 | H26: 111 | I26: 28 | J26: 2 | N26: 7924 | P26: 7812 | R26: 112 | S26: =R26/N26*100 -> 1.4134276 | T26: 24 | W26: 88
A27: 45945 | C27: 7324 | D27: 7272 | F27: 52 | G27: =F27/C27*100 -> 0.70999454 | H27: 46 | I27: 6 | N27: 7298 | P27: 6897 | R27: 401 | S27: =R27/N27*100 -> 5.4946561 | T27: 45 | W27: 356
A28: 45946 | C28: 6783 | D28: 6749 | F28: 34 | G28: =F28/C28*100 -> 0.50125313 | H28: 31 | I28: 3 | N28: 6749 | P28: 6709 | R28: 40 | S28: =R28/N28*100 -> 0.5926804 | W28: 40
A29: 45947 | C29: 6974 | D29: 6909 | F29: 65 | G29: =F29/C29*100 -> 0.93203327 | H29: 35 | I29: 14 | J29: 16 | N29: 6909 | P29: 6867 | R29: 42 | S29: =R29/N29*100 -> 0.60790274 | T29: 9 | W29: 33
A30: 45948 | C30: 4728 | D30: 4679 | F30: 49 | G30: =F30/C30*100 -> 1.036379 | H30: 14 | I30: 35 | N30: 4679 | P30: 4630 | R30: 40 | S30: =R30/N30*100 -> 0.85488352 | W30: 40
A31: WEEKLY 3 | C31: =SUM(C24:C30) -> 42489 | D31: =SUM(D24:D30) -> 42039 | E31: =SUM(E24:E30) -> 0 | F31: =SUM(F24:F30) -> 450 | G31: =F31/C31*100 -> 1.0590976 | H31: =SUM(H24:H30) -> 334 | I31: =SUM(I24:I30) -> 98 | J31: =SUM(J24:J30) -> 18 | K31: =SUM(K24:K30) -> 0 | L31: =SUM(L24:L30) -> 0 | N31: =SUM(N24:O30) -> 42065 | P31: =SUM(P25:P30) -> 41317 | Q31: =SUM(Q25:Q30) -> 0 | R31: =SUM(R25:R30) -> 739 | S31: =R31/N31*100 -> 1.7568049 | T31: =SUM(T24:T30) -> 80 | U31: =SUM(U24:U30) -> 0 | V31: =SUM(V24:V30) -> 0 | W31: =SUM(W24:W30) -> 659 | X31: =SUM(X24:Y30) -> 0 | Z31: =SUM(Z24:Z30) -> 0
A32: 45949 | C32: 3100 | D32: 3092 | F32: 8 | G32: =F32/C32*100 -> 0.25806452 | H32: 4 | J32: 4 | N32: 3092 | P32: 3069 | R32: 23 | S32: =R32/N32*100 -> 0.74385511 | U32: 2 | W32: 21
A33: 45950 | C33: HAPPY DIWALI
A34: 45951
A35: 45952
A36: 45953
A37: 45954 | G37: =F37/C37*100 -> #DIV/0! | S37: =R37/N37*100 -> #DIV/0!
A38: 45955 | G38: =F38/C38*100 -> #DIV/0! | S38: =R38/N38*100 -> #DIV/0!
A39: WEEKLY 4 | C39: =SUM(C32:C38) -> 3100 | D39: =SUM(D32:D38) -> 3092 | E39: =SUM(E32:E38) -> 0 | F39: =SUM(F32:F38) -> 8 | G39: =F39/C39*100 -> 0.25806452 | H39: =SUM(H32:H38) -> 4 | I39: =SUM(I32:I38) -> 0 | J39: =SUM(J32:J38) -> 4 | K39: =SUM(K32:K38) -> 0 | L39: =SUM(L32:L38) -> 0 | N39: =SUM(N32:O38) -> 3092 | P39: =SUM(P32:P38) -> 3069 | Q39: =SUM(Q32:Q38) -> 0 | R39: =SUM(R32:R38) -> 23 | S39: =R39/N39*100 -> 0.74385511 | T39: =SUM(T32:T38) -> 0 | U39: =SUM(U32:U38) -> 2 | V39: =SUM(V32:V38) -> 0 | W39: =SUM(W32:W38) -> 21 | X39: =SUM(X32:Y38) -> 0 | Z39: =SUM(Z32:Z38) -> 0
A40: 45956 | G40: =F40/C40*100 -> #DIV/0! | S40: =R40/N40*100 -> #DIV/0!
A41: 45957 | G41: =F41/C41*100 -> #DIV/0! | S41: =R41/N41*100 -> #DIV/0!
A42: 45958 | G42: =F42/C42*100 -> #DIV/0! | S42: =R42/N42*100 -> #DIV/0!
A43: 45959 | G43: =F43/C43*100 -> #DIV/0! | S43: =R43/N43*100 -> #DIV/0!
A44: 45960 | G44: =F44/C44*100 -> #DIV/0! | S44: =R44/N44*100 -> #DIV/0!
...

Sheet NOVEMBER 2025
C1: DISPOSAFE HEALTH AND LIFE CARE LIMITED Plot No.37A, Sector-06, Ballabgarh (Faridabad) Haryana India 121006 | V1: Doc. No :
V3: Supersedes :
V4: Effective Date :
C5: DAILY BALLOON & VALVE INTEGRITY REPORT | V5: Page: 1 of 1
A7: BALLOON ISPECTION REPORT - P17 | N7: VALVE INTEGRITY
A8: DATE | C8: CHECKED QTY | D8: ACCEPT QTY | E8: HOLD QTY | F8: REJ. QTY | G8: REJ. % | H8: STRUCK BALLOON | I8: BALLOOM BRUST | J8: LEAKAGE | K8: OTHERS | L8: Remarks | N8: CHECKED QTY | O8: ACCEPT QTY | P8: HOLD QTY | Q8: REJ. QTY | R8: REJ. % | S8: LEAKAGE | T8: 90/10 | U8: BUBBLE | V8: THIN SPOD | W8: OTHERS | X8: Remarks
A11: 45962 | C11: 3064 | D11: 3043 | F11: 21 | G11: =F11/C11*100 -> 0.68537859 | H11: 16 | I11: 5 | N11: 3043 | O11: 3024 | Q11: 19 | R11: =Q11/N11*100 -> 0.62438383 | V11: 19
A12: WEEKLY 1 | C12: =SUM(C11:C11) -> 3064 | D12: =SUM(D11:D11) -> 3043 | E12: =SUM(E11:E11) -> 0 | F12: =SUM(F11:F11) -> 21 | G12: =F12/C12*100 -> 0.68537859 | H12: =SUM(H11:H11) -> 16 | I12: =SUM(I11:I11) -> 5 | J12: =SUM(J11:J11) -> 0 | K12: =SUM(K11:K11) -> 0 | L12: =SUM(L11:L11) -> 0 | N12: =SUM(N11:N11) -> 3043 | O12: =SUM(O11:O11) -> 3024 | P12: =SUM(P11:P11) -> 0 | Q12: =SUM(Q11:Q11) -> 19 | R12: =Q12/N12*100 -> 0.62438383 | S12: =SUM(S11:S11) -> 0 | T12: =SUM(T11:T11) -> 0 | U12: =SUM(U11:U11) -> 0 | V12: =SUM(V11:V11) -> 19 | W12: =SUM(W11:W11) -> 0 | X12: =SUM(X11:X11) -> 0
A13: 45963 | G13: =F13/C13*100 -> #DIV/0! | R13: =Q13/N13*100 -> #DIV/0!
A14: 45964 | C14: 6681 | D14: 6670 | F14: 11 | G14: =F14/C14*100 -> 0.16464601 | H14: 10 | I14: 1 | N14: 6670 | O14: 6650 | Q14: 20 | R14: =Q14/N14*100 -> 0.29985007 | S14: 2 | V14: 18
A15: 45965 | C15: 10796 | D15: 10751 | F15: 43 | G15: =F15/C15*100 -> 0.39829567 | H15: 2 | N15: 10751 | O15: 10709 | Q15: 42 | R15: =Q15/N15*100 -> 0.39066133 | S15: 2 | V15: 38 | W15: 2
A16: 45966 | C16: 8738 | D16: 8712 | F16: 26 | G16: =F16/C16*100 -> 0.29755093 | H16: 26 | N16: 8712 | O16: 8702 | Q16: 10 | R16: =Q16/N16*100 -> 0.11478421 | V16: 9 | W16: 1
A17: 45967 | C17: 8862 | D17: 8843 | F17: 19 | G17: =F17/C17*100 -> 0.21439856 | H17: 16 | I17: 1 | J17: 2 | N17: 8843 | O17: 8820 | Q17: 23 | R17: =Q17/N17*100 -> 0.26009273 | V17: 23
A18: 45968 | C18: 11854 | D18: 11833 | F18: 21 | G18: =F18/C18*100 -> 0.17715539 | H18: 19 | I18: 2 | N18: 11833 | O18: 11800 | Q18: 33 | R18: =Q18/N18*100 -> 0.2788811 | S18: 1 | V18: 32
A19: 45969 | C19: 7646 | D19: 7554 | F19: 92 | G19: =F19/C19*100 -> 1.2032435 | H19: 61 | I19: 30 | J19: 1 | N19: 7554 | O19: 7463 | Q19: 91 | R19: =Q19/N19*100 -> 1.2046598 | S19: 10 | V19: 76 | W19: 5
A20: WEEKLY 2 | C20: =SUM(C13:C19) -> 54577 | D20: =SUM(D13:D19) -> 54363 | E20: =SUM(E13:E19) -> 0 | F20: =SUM(F13:F19) -> 212 | G20: =F20/C20*100 -> 0.38844202 | H20: =SUM(H13:H19) -> 134 | I20: =SUM(I13:I19) -> 34 | J20: =SUM(J13:J19) -> 3 | K20: =SUM(K13:K19) -> 0 | L20: =SUM(L13:L19) -> 0 | N20: =SUM(N13:N19) -> 54363 | O20: =SUM(O13:O19) -> 54144 | P20: =SUM(P13:P19) -> 0 | Q20: =SUM(Q13:Q19) -> 219 | R20: =Q20/N20*100 -> 0.40284752 | S20: =SUM(S13:S19) -> 15 | T20: =SUM(T13:T19) -> 0 | U20: =SUM(U13:U19) -> 0 | V20: =SUM(V13:V19) -> 196 | W20: =SUM(W13:W19) -> 8 | X20: =SUM(X13:X19) -> 0
A21: 45970 | G21: =F21/C21*100 -> #DIV/0! | R21: =Q21/N21*100 -> #DIV/0!
A22: 45971 | C22: 6315 | D22: 6063 | F22: 252 | G22: =F22/C22*100 -> 3.9904988 | H22: 195 | I22: 57 | N22: 6063 | O22: 5885 | Q22: 178 | R22: =Q22/N22*100 -> 2.9358403 | S22: 126 | V22: 50 | W22: 2
A23: 45972 | C23: 5600 | D23: 5095 | F23: 500 | G23: =F23/C23*100 -> 8.9285714 | H23: 7 | I23: 107 | J23: 386 | N23: 5095 | O23: 4836 | Q23: 311 | R23: =Q23/N23*100 -> 6.1040236 | S23: 244 | V23: 67
A24: 45973 | C24: 7442 | D24: 7438 | F24: 4 | G24: =F24/C24*100 -> 0.053748992 | H24: 1 | I24: 3 | N24: 7438 | O24: 7360 | Q24: 78 | R24: =Q24/N24*100 -> 1.048669 | S24: 15 | V24: 63
A25: 45974 | C25: 7475 | D25: 7466 | F25: 9 | G25: =F25/C25*100 -> 0.12040134 | I25: 9 | N25: 7466 | O25: 7338 | Q25: 128 | R25: =Q25/N25*100 -> 1.7144388 | S25: 71 | V25: 57
A26: 45975 | C26: 8216 | D26: 7965 | F26: 251 | G26: =F26/C26*100 -> 3.0550146 | I26: 15 | J26: 21 | K26: 215 | N26: 7965 | O26: 7709 | Q26: 256 | R26: =Q26/N26*100 -> 3.2140615 | S26: 161 | V26: 95
A27: 45976 | C27: 7661 | D27: 9637 | F27: 24 | G27: =F27/C27*100 -> 0.31327503 | I27: 11 | J27: 13 | N27: 9637 | O27: 9533 | Q27: 104 | R27: =Q27/N27*100 -> 1.079174 | S27: 29 | V27: 75
A28: WEEKLY 3 | C28: =SUM(C21:C27) -> 42709 | D28: =SUM(D21:D27) -> 43664 | E28: =SUM(E21:E27) -> 0 | F28: =SUM(F21:F27) -> 1040 | G28: =F28/C28*100 -> 2.4350839 | H28: =SUM(H21:H27) -> 203 | I28: =SUM(I21:I27) -> 202 | J28: =SUM(J21:J27) -> 420 | K28: =SUM(K21:K27) -> 215 | L28: =SUM(L21:L27) -> 0 | N28: =SUM(N21:N27) -> 43664 | O28: =SUM(O22:O27) -> 42661 | P28: =SUM(P22:P27) -> 0 | Q28: =SUM(Q22:Q27) -> 1055 | R28: =Q28/N28*100 -> 2.4161781 | S28: =SUM(S21:S27) -> 646 | T28: =SUM(T21:T27) -> 0 | U28: =SUM(U21:U27) -> 0 | V28: =SUM(V21:V27) -> 407 | W28: =SUM(W21:W27) -> 2 | X28: =SUM(X21:X27) -> 0
A29: 45977 | G29: =F29/C29*100 -> #DIV/0! | R29: =Q29/N29*100 -> #DIV/0!
A30: 45978 | C30: 10482 | D30: 10434 | F30: 48 | G30: =F30/C30*100 -> 0.45792788 | I30: 2 | J30: 9 | K30: 37 | N30: 10434 | O30: 10337 | Q30: 97 | R30: =Q30/N30*100 -> 0.92965306 | S30: 30 | V30: 67
A31: 45979 | C31: 10449 | D31: 10437 | F31: 12 | G31: =F31/C31*100 -> 0.11484353 | I31: 2 | J31: 8 | N31: 10437 | O31: 10390 | Q31: 47 | R31: =Q31/N31*100 -> 0.45032097 | S31: 26 | V31: 21
A32: 45980 | C32: 11093 | D32: 11074 | F32: 19 | G32: =F32/C32*100 -> 0.17127919 | H32: 5 | I32: 2 | J32: 12 | N32: 11074 | O32: 11027 | Q32: 47 | R32: =Q32/N32*100 -> 0.42441755 | S32: 10 | V32: 37
A33: 45981 | C33: 10233 | D33: 10226 | F33: 7 | G33: =F33/C33*100 -> 0.068406137 | I33: 2 | J33: 5 | N33: 10233 | O33: 10208 | Q33: 25 | R33: =Q33/N33*100 -> 0.24430763 | S33: 8 | V33: 17
A34: 45982 | C34: 8584 | D34: 8566 | F34: 18 | G34: =F34/C34*100 -> 0.20969245 | H34: 7 | I34: 1 | J34: 10 | N34: 8566 | O34: 8503 | Q34: 63 | R34: =Q34/N34*100 -> 0.7354658 | S34: 11 | V34: 52
A35: 45983 | C35: 4382 | D35: 4367 | F35: 15 | G35: =F35/C35*100 -> 0.34230945 | H35: 2 | I35: 9 | J35: 4 | N35: 4367 | O35: 4262 | Q35: 105 | R35: =Q35/N35*100 -> 2.4043966 | S35: 50 | V35: 55
A36: WEEKLY 4 | C36: =SUM(C29:C35) -> 55223 | D36: =SUM(D29:D35) -> 55104 | E36: =SUM(E29:E35) -> 0 | F36: =SUM(F29:F35) -> 119 | G36: =F36/C36*100 -> 0.21548992 | H36: =SUM(H29:H35) -> 14 | I36: =SUM(I29:I35) -> 18 | J36: =SUM(J29:J35) -> 48 | K36: =SUM(K29:K35) -> 37 | L36: =SUM(L29:L35) -> 0 | N36: =SUM(N29:N35) -> 55111 | O36: =SUM(O29:O35) -> 54727 | P36: =SUM(P29:P35) -> 0 | Q36: =SUM(Q29:Q35) -> 384 | R36: =Q36/N36*100 -> 0.6967756 | S36: =SUM(S29:S35) -> 135 | T36: =SUM(T29:T35) -> 0 | U36: =SUM(U29:U35) -> 0 | V36: =SUM(V29:V35) -> 249 | W36: =SUM(W29:W35) -> 0 | X36: =SUM(X29:X35) -> 0
