Workbook

Sheet FORMATE
C1: DISPOSAFE HEALTH AND LIFE CARE LIMITED Plot No.37A, Sector-06, Ballabgarh (Faridabad) Haryana India 121006 | X1: Doc. No. : | AA1: F/ASSEM/02:00
X2: Supersedes : | AA2: None
X3: Effective Date: | AA3: 07- 1 2-2024
C4: DAILY VISUAL INSPECTION REPORT | X4: Page 1 of 1
A6: DATE:
A7: B.NO | B7: SIZE | C7: REC. QTY | D7: ACCEPT QTY | E7: HOLD QTY | F7: HOLD % | G7: REJ. QTY | H7: REJ % | I7: REASON FOR REJECTION
I8: 1 | J8: 2 | K8: 3 | L8: 4 | M8: 5 | N8: 6 | O8: 7 | P8: 8 | Q8: 9 | R8: 10 | S8: 11 | T8: 12 | U8: 13 | V8: 14 | W8: 15 | X8: 16 | Y8: 17 | Z8: 18 | AA8: 19 | AB8: 20 | AC8: 21
I9: COAG | J9: SD | K9: TT | L9: BL | M9: PS | N9: SB | O9: PW | P9: FP | Q9: RW | R9: BEP | S9: DEC | T9: BM | U9: WEB | V9: BT | W9: SF | X9: BIC | Y9: WK | Z9: BMP | AA9: TF | AB9: PH | AC9: BST
A23: TOTAL
A24: TOTAL IN %
A25: COAG COAGULUM | D25: SD SURFACE DEFECT | G25: TT THIN TIP | J25: BL BLISTER | M25: PS PLY SEPARATION | R25: SB STEP BALLOON | V25: PW PROJECTED WIRE
A26: RW RAISED WIRE | D26: BEP BAD EYE PUNCHING | G26: DEC DECOLORISATION | J26: BM BLACK MARK | N26: WEB WEBBING | R26: BT BAD TRIMMING | W26: SF SHORT FUNNEL
A27: WK WRINKLE | D27: BP BUMP | G27: TF TORN FUNNEL | J27: PH PIN HOLE | N27: BST BAD STRIPPING | S27: BIC BEND IN CATHETER | X27: FP FOREIGN PARTICLE

Sheet 4-2-25
A1: DISPOSAFE HEALTH AND LIFE CARE LIMITED PLOT NO 37/A, SECTOR-6, FARIDABAD 121006. HARYANA(INDIA) DAILY VISUAL INSPECTION REPORT
A4: DATE: | B4: 45692
A5: B.NO | B5: SIZE | C5: REC. QTY | D5: A GRADE | E5: HOLD | F5: LOCAL GRADE | G5: REJ. QTY | H5: REJ % | I5: REASON FOR REJECTION
I6: 1 | J6: 2 | K6: 3 | L6: 4 | M6: 5 | N6: 6 | O6: 7 | P6: 8 | Q6: 9 | R6: 10 | S6: 11 | T6: 12 | U6: 13 | V6: 14 | W6: 15 | X6: 16 | Y6: 17 | Z6: 18 | AA6: 19 | AB6: 20 | AC6: 21
I7: COAG | J7: SD | K7: TT | L7: BL | M7: PS | N7: SB | O7: PW | P7: FP | Q7: RW | R7: BEP | S7: DEC | T7: BM | U7: WEB | V7: BT | W7: SF | X7: BIC | Y7: WK | Z7: BMP | AA7: TF | AB7: PH | AC7: BST
A8: 25A28 | B8: 16FR | C8: 2374 | D8: 2173 | E8: 140 | G8: 61 | H8: =G8/C8*100 -> 2.5695029
A9: 25A30 | B9: 16FR | C9: 3174 | D9: 3094 | E9: 44 | G9: 36 | H9: =G9/C9*100 -> 1.1342155
A10: 25A29 | B10: 16FR | C10: 790 | D10: 500 | E10: 258 | G10: 32 | H10: =G10/C10*100 -> 4.0506329
A21: TOTAL | C21: =SUM(C8:C10) -> 6338 | D21: =SUM(D8:D10) -> 5767 | E21: =SUM(E8:E10) -> 442 | G21: =SUM(G8:G10) -> 129 | H21: =SUM(H8:H10) -> 7.7543514
A22: TOTAL IN % | D22: =D21/C21*100 -> 90.990849
A23: COAG COAGULUM | D23: SD SURFACE DEFECT | G23: TT THIN TIP | J23: BL BLISTER | M23: PS PLY SEPARATION | R23: SB STEP BALLOON | V23: PW PROJECTED WIRE
A24: RW RAISED WIRE | D24: BEP BAD EYE PUNCHING | G24: DEC DECOLORISATION | J24: BM BLACK MARK | N24: WEB WEBBING | R24: BT BAD TRIMMING | W24: SF SHORT FUNNEL
A25: WK WRINKLE | D25: BP BUMP | G25: TF TORN FUNNEL | J25: PH PIN HOLE | N25: BST BAD STRIPPING | S25: BIC BEND IN CATHETER | X25: FP FOREIGN PARTICLE

Sheet APRIL 25
B1: DISPOSAFE HEALTH AND LIFE CARE LIMITED Plot No.37A, Sector-06, Ballabgarh (Faridabad) Haryana India 121006 | W1: Doc. no. : | Z1: F/QC/01:00
W2: Supersedes : | Z2: None
W3: Effective Date : | Z3: 45692
B4: VISUAL INSPECTION REPORT | W4: Page 1 of 1
A6: DATE | B6: REC. QTY | C6: ACCEPT QTY | D6: HOLD QTY | E6: REJ. QTY | F6: REJ % | G6: REASON FOR REJECTION
G7: 1 | H7: 2 | I7: 3 | J7: 4 | K7: 5 | L7: 6 | M7: 7 | N7: 8 | O7: 9 | P7: 10 | Q7: 11 | R7: 12 | S7: 13 | T7: 14 | U7: 15 | V7: 16 | W7: 17 | X7: 18 | Y7: 19 | Z7: 20 | AA7: 21
G8: COAG | H8: SD | I8: TT | J8: BL | K8: PS | L8: SB | M8: PW | N8: FP | O8: RW | P8: BEP | Q8: DEC | R8: BM | S8: WEB | T8: BT | U8: SF | V8: BIC | W8: WK | X8: BMP | Y8: TF | Z8: PH | AA8: BST
A9: 45748 | B9: 10982 | C9: 9627 | D9: 301 | E9: =B9-(C9+D9) -> 1054 | F9: =E9/B9*100 -> 9.5975232 | G9: 181 | H9: 66 | K9: 616 | R9: 185 | X9: 6
A10: 45749 | B10: 11054 | C10: 9907 | D10: 319 | E10: =B10-(C10+D10) -> 828 | F10: =E10/B10*100 -> 7.4905012 | G10: 292 | H10: 37 | K10: 322 | R10: 146 | X10: 31
A11: 45750 | B11: 12039 | C11: 10746 | D11: 446 | E11: =B11-(C11+D11) -> 847 | F11: =E11/B11*100 -> 7.0354681 | G11: 320 | H11: 119 | K11: 73 | R11: 182 | Y11: 153
A12: 45751 | B12: 11041 | C12: 9573 | D12: 351 | E12: =B12-(C12+D12) -> 1117 | F12: =E12/B12*100 -> 10.116837 | G12: 423 | H12: 325 | K12: 78 | R12: 261 | W12: 21 | Y12: 9
A13: 45752 | B13: 8585 | C13: 7501 | D13: 430 | E13: =B13-(C13+D13) -> 654 | F13: =E13/B13*100 -> 7.6179383 | G13: 108 | H13: 148 | K13: 108 | P13: 1 | R13: 248 | W13: 39 | X13: 5 | Y13: 9
A14: 45754 | B14: 5230 | C14: 4553 | D14: 68 | E14: =B14-(C14+D14) -> 609 | F14: =E14/B14*100 -> 11.644359 | G14: 10 | H14: 23 | K14: 326 | R14: 233 | X14: 9 | Y14: 8
A15: 45755 | B15: 10167 | C15: 9400 | D15: 87 | E15: =B15-(C15+D15) -> 680 | F15: =E15/B15*100 -> 6.6883053 | G15: 239 | H15: 129 | K15: 130 | R15: 145 | W15: 33 | Y15: 4
A16: 45756 | B16: 9455 | C16: 8912 | D16: 246 | E16: =B16-(C16+D16) -> 297 | F16: =E16/B16*100 -> 3.1411951 | G16: 61 | H16: 129 | K16: 27 | R16: 76 | X16: 3 | Y16: 1
A17: 45757 | B17: 10959 | C17: 10350 | D17: 154 | E17: =B17-(C17+D17) -> 455 | F17: =E17/B17*100 -> 4.1518387 | G17: 77 | H17: 97 | K17: 135 | R17: 131 | X17: 14 | Y17: 1
A18: 45758 | B18: 12959 | C18: 12214 | D18: 218 | E18: =B18-(C18+D18) -> 527 | F18: =E18/B18*100 -> 4.0666718 | G18: 41 | H18: 174 | K18: 86 | R18: 192 | X18: 32 | Y18: 2
A19: 45759 | B19: 7802 | C19: 7250 | D19: 173 | E19: =B19-(C19+D19) -> 379 | F19: =E19/B19*100 -> 4.8577288 | G19: 14 | H19: 73 | K19: 190 | R19: 93 | X19: 5 | Y19: 4
A20: 45761 | B20: 7479 | C20: 6182 | D20: 50 | E20: =B20-(C20+D20) -> 1247 | F20: =E20/B20*100 -> 16.673352 | G20: 89 | H20: 51 | K20: 973 | R20: 104 | X20: 24 | Y20: 6
A21: 45762 | B21: 12492 | C21: 11557 | D21: 235 | E21: =B21-(C21+D21) -> 700 | F21: =E21/B21*100 -> 5.6035863 | G21: 60 | H21: 68 | K21: 337 | R21: 226 | X21: 8 | Y21: 1
A22: 45763 | B22: 10594 | C22: 8339 | D22: 584 | E22: 671 | F22: =E22/B22*100 -> 6.3337738 | G22: 291 | H22: 50 | R22: 81 | Z22: 229
A23: 45764 | B23: 11049 | C23: 10209 | D23: 160 | E23: =B23-(C23+D23) -> 680 | F23: =E23/B23*100 -> 6.1544031 | G23: 262 | H23: 163 | R23: 94 | Z23: 161
A24: 45765 | B24: 9273 | C24: 8453 | D24: 98 | E24: =B24-(C24+D24) -> 722 | F24: =E24/B24*100 -> 7.7860455 | G24: 292 | H24: 153 | R24: 99 | Y24: 84 | Z24: 94
A25: 45766 | B25: 10344 | C25: 9612 | D25: 312 | E25: =B25-(C25+D25) -> 420 | F25: =E25/B25*100 -> 4.0603248 | G25: 182 | H25: 85 | R25: 146 | Y25: 7
A26: 45768 | B26: 9439 | C26: 7281 | D26: 1867 | E26: =B26-(C26+D26) -> 291 | F26: =E26/B26*100 -> 3.0829537 | G26: 124 | H26: 73 | R26: 84 | Y26: 10
A27: 45769 | E27: =B27-(C27+D27) -> 0 | F27: =E27/B27*100 -> #DIV/0!
A28: 45770 | B28: 8884 | C28: 7370 | D28: 1100 | E28: =B28-(C28+D28) -> 414 | F28: =E28/B28*100 -> 4.660063 | G28: 71 | K28: 78 | R28: 90 | X28: 1 | Y28: 33
A29: 45771 | B29: 9929 | C29: 6878 | D29: 1898 | E29: =B29-(C29+D29) -> 1153 | F29: =E29/B29*100 -> 11.612448 | G29: 77 | H29: 73 | K29: 868 | R29: 126 | X29: 5 | Y29: 4
A30: 45772 | B30: 10020 | C30: 8614 | D30: 441 | E30: =B30-(C30+D30) -> 965 | F30: =E30/B30*100 -> 9.6307385 | G30: 32 | H30: 29 | J30: 768 | R30: 126 | X30: 10
A31: 45773 | B31: 8544 | C31: 5986 | D31: 985 | E31: =B31-(C31+D31) -> 1573 | F31: =E31/B31*100 -> 18.410581 | G31: 12 | H31: 48 | K31: 1251 | R31: 124 | X31: 42 | Y31: 96
A32: 45775 | B32: 9730 | C32: 8183 | D32: 621 | E32: =B32-(C32+D32) -> 926 | F32: =E32/B32*100 -> 9.5169579 | G32: 44 | H32: 120 | I32: 486 | R32: 254 | X32: 14 | Y32: 8
A33: 45776 | B33: 9468 | C33: 8788 | D33: 326 | E33: =B33-(C33+D33) -> 354 | F33: =E33/B33*100 -> 3.73891 | G33: 28 | H33: 109 | K33: 66 | R33: 136 | W33: 5 | X33: 2 | Y33: 8
A34: 45777 | B34: 10249 | C34: 7811 | D34: 730 | E34: =B34-(C34+D34) -> 1708 | F34: =E34/B34*100 -> 16.66504 | G34: 91 | H34: 70 | K34: 1145 | R34: 225 | X34: 9 | Y34: 4
A35: TOTAL | B35: =SUM(B9:B34) -> 247767 | C35: =SUM(C9:C34) -> 215296 | D35: =SUM(D9:D34) -> 12200 | E35: =SUM(E9:E34) -> 19271 | F35: =E35/B35*100 -> 7.777872 | G35: =SUM(G9:G34) -> 3421 | H35: =SUM(H9:H34) -> 2412 | I35: =SUM(I9:I34) -> 486 | J35: =SUM(J9:J34) -> 768 | K35: =SUM(K9:K34) -> 6809 | L35: =SUM(L9:L34) -> 0 | M35: =SUM(M9:M34) -> 0 | N35: =SUM(N9:N34) -> 0 | ... AA35: =SUM(AA9:AA34) -> 0
C36: =C35/B35*100 -> 86.894542 | D36: =D35/B35*100 -> 4.923981 | E36: =E35/B35*100 -> 7.777872 | G36: =G35/B35*100 -> 1.3807327 | H36: =H35/B35*100 -> 0.97349526 | I36: =I35/B35*100 -> 0.19615203 | K36: =K35/B35*100 -> 2.7481464 | L36: =L35/B35*100 -> 0 | O36: =O35/B35*100 -> 0 | P36: =P35/B35*100 -> 0.000403605 | R36: =R35/B35*100 -> 1.5365242 | S36: =S35/B35*100 -> 0 | T36: =T35/B35*100 -> 0 | U36: =U35/B35*100 -> 0 | V36: =V35/B35*100 -> 0 | W36: =W35/B35*100 -> 0.03955329 | X36: =X35/B35*100 -> 0.0887931 | Y36: =Y35/B35*100 -> 0.18242946
G37: 0.5 | H37: 0.5 | I37: 0.1 | J37: 0.2 | K37: 0.2 | L37: 0.1 | M37: 0.1 | N37: 0.1 | O37: 0.1 | P37: 0.4 | Q37: 0.4 | R37: 1 | S37: 0.1 | T37: 0.1 | U37: 0.1 | V37: 0.1 | W37: 0.2 | X37: 0.3 | Y37: 0.1 | Z37: 0.1 | AA37: 0.2

Sheet MAY 25
B1: DISPOSAFE HEALTH AND LIFE CARE LIMITED Plot No.37A, Sector-06, Ballabgarh (Faridabad) Haryana India 121006 | W1: Doc. No. : | Z1: F/QC/01:00
W2: Supersedes : | Z2: None
W3: Effective Date : | Z3: 45692
B4: VISUAL INSPECTION REPORT | W4: Page 1 of 1
A6: DATE | B6: REC. QTY | C6: ACCEPT QTY | D6: HOLD QTY | E6: REJ. QTY | F6: REJ % | G6: REASON FOR REJECTION
G7: 1 | H7: 2 | I7: 3 | J7: 4 | K7: 5 | L7: 6 | M7: 7 | N7: 8 | O7: 9 | P7: 10 | Q7: 11 | R7: 12 | S7: 13 | T7: 14 | U7: 15 | V7: 16 | W7: 17 | X7: 18 | Y7: 19 | Z7: 20 | AA7: 21
G8: COAG | H8: SD | I8: TT | J8: BL | K8: PS | L8: SB | M8: PW | N8: FP | O8: RW | P8: BEP | Q8: DEC | R8: BM | S8: WEB | T8: BT | U8: SF | V8: BIC | W8: WK | X8: BMP | Y8: TF | Z8: PH | AA8: BST
A9: 45778 | B9: 8346 | C9: 6229 | D9: 1666 | E9: =B9-(C9+D9) -> 451 | F9: =E9/B9*100 -> 5.4037862 | G9: 67 | H9: 88 | K9: 139 | M9: 11 | R9: 140 | X9: 7 | Y9: 4
A10: 45779 | B10: 4590 | C10: 4208 | D10: 189 | E10: =B10-(C10+D10) -> 193 | F10: =E10/B10*100 -> 4.204793 | G10: 33 | H10: 10 | K10: 39 | R10: 103 | X10: 7 | Y10: 1
A11: 45780 | B11: 3624 | C11: 2280 | D11: 988 | E11: =B11-(C11+D11) -> 356 | F11: =E11/B11*100 -> 9.8233996 | G11: 8 | H11: 20 | K11: 270 | R11: 42 | X11: 15 | Y11: 1
A12: TOTAL | B12: =SUM(B9:B11) -> 16560 | C12: =SUM(C9:C11) -> 12717 | D12: =SUM(D9:D11) -> 2843 | E12: =SUM(E9:E11) -> 1000 | F12: =SUM(F9:F11) -> 19.431979 | G12: =SUM(G9:G11) -> 108 | H12: =SUM(H9:H11) -> 118 | K12: =SUM(K9:K11) -> 448 | M12: =SUM(M9:M11) -> 11 | R12: =SUM(R9:R11) -> 285 | X12: =SUM(X9:X11) -> 29 | Y12: =SUM(Y9:Y11) -> 6
A13: % | C13: =C12/$B$12*100 -> 76.793478 | D13: =D12/$B$12*100 -> 17.167874 | E13: =E12/$B$12*100 -> 6.0386473 | F13: =F12/$B$12*100 -> 0.11734287 | G13: =G12/$B$12*100 -> 0.65217391 | H13: =H12/$B$12*100 -> 0.71256039 | K13: =K12/$B$12*100 -> 2.705314 | M13: =M12/$B$12*100 -> 0.066425121 | R13: =R12/$B$12*100 -> 1.7210145 | X13: =X12/$B$12*100 -> 0.17512077 | Y13: =Y12/$B$12*100 -> 0.036231884
A14: 45781 | B14: SUNDAY
A15: 45782 | B15: 6924 | C15: 5847 | D15: 191 | E15: =B15-(C15+D15) -> 886 | F15: =E15/B15*100 -> 12.796072 | G15: 11 | H15: 233 | K15: 219 | R15: 363 | X15: 53 | Y15: 7
A16: 45783 | B16: 7528 | C16: 6490 | D16: 215 | E16: =B16-(C16+D16) -> 823 | F16: =E16/B16*100 -> 10.932519 | G16: 3 | H16: 77 | K16: 451 | R16: 247 | X16: 40 | Y16: 10
A17: 45784 | B17: 8703 | C17: 7627 | D17: 243 | E17: =B17-(C17+D17) -> 833 | F17: =E17/B17*100 -> 9.5714122 | G17: 70 | H17: 114 | K17: 422 | O17: 10 | R17: 220 | X17: 44 | Y17: 3
A18: 45785 | B18: 9138 | C18: 7898 | D18: 558 | E18: =B18-(C18+D18) -> 682 | F18: =E18/B18*100 -> 7.4633399 | G18: 34 | H18: 174 | K18: 120 | O18: 41 | R18: 219 | X18: 159 | Y18: 4
A19: 45786 | B19: 10611 | C19: 8845 | D19: 1121 | E19: =B19-(C19+D19) -> 645 | F19: =E19/B19*100 -> 6.0785977 | G19: 29 | H19: 85 | K19: 160 | O19: 16 | R19: 326 | X19: 28 | Y19: 1
A20: 45787 | B20: 4375 | C20: 4110 | D20: 72 | E20: =B20-(C20+D20) -> 193 | F20: =E20/B20*100 -> 4.4114286 | G20: 30 | H20: 37 | R20: 93 | X20: 33
A21: TOTAL | B21: =SUM(B15:B20) -> 47279 | C21: =SUM(C15:C20) -> 40817 | D21: =SUM(D15:D20) -> 2400 | E21: =SUM(E15:E20) -> 4062 | F21: =E21/B21*100 -> 8.5915523 | G21: =SUM(G15:G20) -> 177 | H21: =SUM(H15:H20) -> 720 | K21: =SUM(K15:K20) -> 1372 | O21: =SUM(O15:O20) -> 67 | R21: =SUM(R15:R20) -> 1468 | X21: =SUM(X15:X20) -> 357 | Y21: =SUM(Y15:Y20) -> 25
A22: % | C22: =C21/$B$21*100 -> 86.332198 | D22: =D21/$B$21*100 -> 5.0762495 | E22: =E21/$B$21*100 -> 8.5915523 | F22: =F21/$B$21*100 -> 0.018172026 | G22: =G21/$B$21*100 -> 0.3743734 | H22: =H21/$B$21*100 -> 1.5228748 | K22: =K21/$B$21*100 -> 2.9019226 | O22: =O21/$B$21*100 -> 0.14171197 | R22: =R21/$B$21*100 -> 3.1049726 | X22: =X21/$B$21*100 -> 0.75509211 | Y22: =Y21/$B$21*100 -> 0.052877599
A23: 45788 | B23: SUNDAY
A24: 45789 | B24: 11451 | C24: 9915 | D24: 297 | E24: =B24-(C24+D24) -> 1239 | F24: =E24/B24*100 -> 10.820016 | G24: 56 | H24: 100 | K24: 505 | O24: 105 | R24: 419 | X24: 53 | Y24: 1
A25: 45790 | B25: 10602 | C25: 9560 | D25: 181 | E25: =B25-(C25+D25) -> 861 | F25: =E25/B25*100 -> 8.1211092 | G25: 11 | H25: 107 | K25: 238 | O25: 104 | R25: 379 | X25: 19 | Y25: 3
A26: 45791 | B26: 9696 | C26: 8825 | D26: 196 | E26: =B26-(C26+D26) -> 675 | F26: =E26/B26*100 -> 6.9616337 | G26: 22 | H26: 142 | K26: 173 | O26: 69 | R26: 239 | W26: 8 | X26: 17 | Y26: 5
A27: 45792 | B27: 9893 | C27: 8931 | D27: 273 | E27: =B27-(C27+D27) -> 689 | F27: =E27/B27*100 -> 6.9645204 | G27: 28 | H27: 69 | K27: 41 | O27: 146 | R27: 389 | X27: 14 | Y27: 2
A28: 45793 | B28: 11688 | C28: 10757 | D28: 212 | E28: =B28-(C28+D28) -> 719 | F28: =E28/B28*100 -> 6.1516085 | G28: 48 | H28: 105 | K28: 49 | O28: 189 | R28: 315 | X28: 11 | Y28: 2
A29: 45794 | B29: 12454 | C29: 11708 | D29: 192 | E29: =B29-(C29+D29) -> 554 | F29: =E29/B29*100 -> 4.44837 | G29: 36 | H29: 112 | K29: 120 | O29: 16 | R29: 259 | Y29: 6 | Z29: 5
A30: TOTAL | B30: =SUM(B24:B29) -> 65784 | C30: =SUM(C24:C29) -> 59696 | D30: =SUM(D24:D29) -> 1351 | E30: =SUM(E24:E29) -> 4737 | F30: =E30/B30*100 -> 7.2008391 | G30: =SUM(G24:G29) -> 201 | H30: =SUM(H24:H29) -> 635 | I30: =SUM(I24:I29) -> 0 | J30: =SUM(J24:J29) -> 0 | K30: =SUM(K24:K29) -> 1126 | L30: =SUM(L24:L29) -> 0 | M30: =SUM(M24:M29) -> 0 | N30: =SUM(N24:N29) -> 0 | ... AA30: =SUM(AA24:AA29) -> 0
A31: % | C31: =C30/B30*100 -> 90.74547 | D31: =D30/B30*100 -> 2.0536909 | E31: =E30/B30*100 -> 7.2008391 | G31: =G30/B30*100 -> 0.30554542 | H31: =H30/$B$30*100 -> 0.96528031 | K31: =K30/$B$30*100 -> 1.7116624 | O31: =O30/$B$30*100 -> 0.95615955 | R31: =R30/$B$30*100 -> 3.0402529 | W31: =W30/$B$30*100 -> 0.012161012 | X31: =X30/$B$30*100 -> 0.17329442 | Y31: =Y30/$B$30*100 -> 0.028882403 | Z31: =Z30/$B$30*100 -> 0.0076006324
A32: 45795 | B32: SUNDAY
A33: 45796 | B33: 12215 | C33: 11004 | D33: 316 | E33: =B33-(C33+D33) -> 895 | F33: =E33/B33*100 -> 7.3270569 | G33: 19 | H33: 41 | K33: 630 | O33: 14 | R33: 184 | X33: 6 | Y33: 1
A34: 45797 | B34: 11397 | C34: 10292 | D34: 223 | E34: =B34-(C34+D34) -> 882 | F34: =E34/B34*100 -> 7.7388787 | G34: 16 | H34: 52 | K34: 678 | O34: 17 | R34: 109 | X34: 9 | Y34: 11
A35: 45798 | B35: 10437 | C35: 9557 | D35: 274 | E35: 572 | F35: =E35/B35*100 -> 5.4805021 | G35: 39 | H35: 49 | K35: 338 | O35: 15 | R35: 14 | X35: 4 | Y35: 8
A36: 45799 | B36: 12008 | C36: 10736 | D36: 198 | E36: =B36-(C36+D36) -> 1074 | F36: =E36/B36*100 -> 8.9440373 | G36: 17 | H36: 48 | K36: 831 | O36: 25 | P36: 10 | R36: 135 | X36: 5 | Y36: 3
A37: 45800 | B37: 12477 | C37: 11464 | D37: 186 | E37: =B37-(C37+D37) -> 827 | F37: =E37/B37*100 -> 6.6281959 | G37: 14 | H37: 71 | K37: 522 | O37: 15 | P37: 65 | R37: 121 | X37: 7 | Y37: 12
A38: 45801 | B38: 13316 | C38: 11691 | D38: 280 | E38: =B38-(C38+D38) -> 1345 | F38: =E38/B38*100 -> 10.100631 | G38: 51 | H38: 60 | K38: 1022 | O38: 24 | P38: 14 | R38: 148 | Y38: 9
A39: TOTAL | B39: =SUM(B33:B38) -> 71850 | C39: =SUM(C33:C38) -> 64744 | D39: =SUM(D33:D38) -> 1477 | E39: =SUM(E33:E38) -> 5595 | F39: =E39/B39*100 -> 7.7870564 | G39: =SUM(G33:G38) -> 156 | H39: =SUM(H33:H38) -> 321 | K39: =SUM(K33:K38) -> 4021 | O39: =SUM(O33:O38) -> 110 | R39: =SUM(R33:R38) -> 711 | X39: =SUM(X33:X38) -> 31 | Y39: =SUM(Y33:Y38) -> 44
A40: % | C40: =C39/$B$39*100 -> 90.109951 | D40: =D39/$B$39*100 -> 2.0556715 | E40: =E39/$B$39*100 -> 7.7870564 | F40: =F39/$B$39*100 -> 0.010837935 | G40: =G39/$B$39*100 -> 0.217119 | H40: =H39/$B$39*100 -> 0.44676409 | K40: =K39/$B$39*100 -> 5.5963814 | O40: =O39/$B$39*100 -> 0.15309673 | R40: =R39/$B$39*100 -> 0.98956159 | X40: =X39/$B$39*100 -> 0.043145442 | Y40: =Y39/$B$39*100 -> 0.061238692
A41: 45802 | B41: SUNDAY
...

Sheet JUNE 25
B1: DISPOSAFE HEALTH AND LIFE CARE LIMITED Plot No.37A, Sector-06, Ballabgarh (Faridabad) Haryana India 121006 | X1: Doc. No. : | AA1: F/QC/01:00
X2: Supersedes : | AA2: 00
X3: Effective Date : | AA3: 45607
B4: VISUAL INSPECTION REPORT | X4: Page 1 of 1
A5: DATE | B5: REC. QTY | C5: ACCEPT QTY | D5: HOLD QTY | E5: HOLD% | F5: REJ. QTY | G5: REJ % | H5: REASON FOR REJECTION
H6: 1 | I6: 2 | J6: 3 | K6: 4 | L6: 5 | M6: 6 | N6: 7 | O6: 8 | P6: 9 | Q6: 10 | R6: 11 | S6: 12 | T6: 13 | U6: 14 | V6: 15 | W6: 16 | X6: 17 | Y6: 18 | Z6: 19 | AA6: 20 | AB6: 21
H7: COAG | I7: SD | J7: TT | K7: BL | L7: PS | M7: SB | N7: PW | O7: FP | P7: RW | Q7: BEP | R7: DEC | S7: BM | T7: WEB | U7: BT | V7: SF | W7: BIC | X7: WK | Y7: BMP | Z7: TF | AA7: PH | AB7: BST
A8: 45809 | B8: SUNDAY
A9: 45810 | B9: 10616 | C9: 8689 | D9: 1582 | E9: =D9/B9*100 -> 14.902035 | F9: =B9-(C9+D9) -> 345 | G9: =F9/B9*100 -> 3.2498116 | H9: 46 | I9: 66 | L9: 10 | P9: 41 | Q9: 45 | S9: 126 | Y9: 7 | Z9: 4
A10: 45811 | B10: 7134 | C10: 6284 | D10: 305 | E10: =D10/B10*100 -> 4.2753014 | F10: =B10-(C10+D10) -> 545 | G10: =F10/B10*100 -> 7.6394729 | H10: 42 | I10: 87 | P10: 41 | Q10: 210 | S10: 150 | Y10: 11 | Z10: 4
A11: 45812 | B11: 8882 | C11: 7866 | D11: 299 | E11: =D11/B11*100 -> 3.3663589 | F11: =B11-(C11+D11) -> 717 | G11: =F11/B11*100 -> 8.0725062 | H11: 68 | I11: 101 | L11: 155 | P11: 79 | Q11: 121 | S11: 185 | Y11: 3 | Z11: 5
A12: 45813 | B12: 10963 | C12: 9942 | D12: 330 | E12: =D12/B12*100 -> 3.010125 | F12: =B12-(C12+D12) -> 691 | G12: =F12/B12*100 -> 6.3030192 | H12: 98 | I12: 94 | L12: 50 | P12: 111 | Q12: 102 | S12: 218 | Y12: 12 | Z12: 6
A13: 45814 | B13: 9576 | C13: 8635 | D13: 382 | E13: =D13/B13*100 -> 3.9891395 | F13: =B13-(C13+D13) -> 559 | G13: =F13/B13*100 -> 5.8375104 | H13: 48 | I13: 82 | L13: 129 | P13: 27 | Q13: 45 | S13: 214 | Y13: 6 | Z13: 8
A14: 45815 | B14: 11760 | C14: 10625 | D14: 285 | E14: =D14/B14*100 -> 2.4234694 | F14: =B14-(C14+D14) -> 850 | G14: =F14/B14*100 -> 7.2278912 | H14: 54 | I14: 59 | L14: 106 | P14: 233 | Q14: 59 | S14: 303 | Y14: 33 | Z14: 3
A15: TOTAL | B15: =SUM(B8:B14) -> 58931 | C15: =SUM(C8:C14) -> 52041 | D15: =SUM(D8:D14) -> 3183 | F15: =SUM(F8:F14) -> 3707 | G15: =SUM(G8:G14) -> 38.330212 | H15: =SUM(H8:H14) -> 356 | I15: =SUM(I8:I14) -> 489 | L15: =SUM(L8:L14) -> 450 | N15: =SUM(N8:N14) -> 0 | S15: =SUM(S8:S14) -> 1196 | Y15: =SUM(Y8:Y14) -> 72 | Z15: =SUM(Z8:Z14) -> 30
A16: % | C16: =C15/$B$15*100 -> 88.308361 | D16: =D15/$B$15*100 -> 5.4012319 | F16: =F15/$B$15*100 -> 6.2904074 | G16: =G15/$B$15*100 -> 0.065042527 | H16: =H15/$B$15*100 -> 0.60409632 | I16: =I15/$B$15*100 -> 0.82978398 | L16: =L15/$B$15*100 -> 0.76360489 | N16: =N15/$B$15*100 -> 0 | S16: =S15/$B$15*100 -> 2.0294921 | Y16: =Y15/$B$15*100 -> 0.12217678 | Z16: =Z15/$B$15*100 -> 0.050906993
A17: 45816 | B17: SUNDAY
A18: 45817 | B18: 11133 | C18: 10220 | D18: 335 | E18: =D18/B18*100 -> 3.0090721 | F18: =B18-(C18+D18) -> 578 | G18: =F18/B18*100 -> 5.1917722 | H18: 94 | I18: 59 | L18: 53 | P18: 78 | Q18: 24 | S18: 266 | Y18: 1 | Z18: 3
A19: 45818 | B19: 10733 | C19: 9642 | D19: 544 | E19: =D19/B19*100 -> 5.0684804 | F19: =B19-(C19+D19) -> 547 | G19: =F19/B19*100 -> 5.0964316 | H19: 92 | I19: 84 | L19: 96 | P19: 63 | Q19: 31 | S19: 175 | Y19: 3 | Z19: 3
A20: 45819 | B20: 11697 | C20: 10146 | D20: 387 | E20: =D20/B20*100 -> 3.3085407 | F20: =B20-(C20+D20) -> 1164 | G20: =F20/B20*100 -> 9.9512696 | H20: 103 | I20: 100 | L20: 111 | P20: 23 | Q20: 70 | S20: 448 | Z20: 9
A21: 45820 | B21: 10553 | C21: 10112 | D21: 26 | E21: =D21/B21*100 -> 0.24637544 | F21: =B21-(C21+D21) -> 415 | G21: =F21/B21*100 -> 3.932531 | H21: 140 | I21: 98 | L21: 12 | S21: 109 | Y21: 4 | Z21: 52
A22: 45821 | B22: 9505 | C22: 8630 | D22: 206 | E22: =D22/B22*100 -> 2.1672804 | F22: =B22-(C22+D22) -> 669 | G22: =F22/B22*100 -> 7.0384008 | H22: 70 | I22: 101 | L22: 78 | P22: 32 | Q22: 49 | S22: 324 | Z22: 15
A23: 45822 | B23: 9867 | C23: 9066 | D23: 253 | E23: =D23/B23*100 -> 2.5641026 | F23: =B23-(C23+D23) -> 548 | G23: =F23/B23*100 -> 5.5538664 | H23: 57 | I23: 48 | L23: 12 | P23: 39 | Q23: 128 | S23: 263 | AA23: 1
A24: TOTAL | B24: =SUM(B18:B23) -> 63488 | C24: =SUM(C18:C23) -> 57816 | D24: =SUM(D18:D23) -> 1751 | F24: =SUM(F18:F23) -> 3921 | G24: =F24/B24*100 -> 6.1759703 | H24: =SUM(H18:H23) -> 556 | I24: =SUM(I18:I23) -> 490 | L24: =SUM(L18:L23) -> 362 | P24: =SUM(P18:P23) -> 235 | S24: =SUM(S18:S23) -> 1585 | Y24: =SUM(Y18:Y23) -> 8 | Z24: =SUM(Z18:Z23) -> 82
A25: % | C25: =C24/$B$24*100 -> 91.066028 | D25: =D24/$B$24*100 -> 2.7580015 | F25: =F24/$B$24*100 -> 6.1759703 | G25: =G24/$B$24*100 -> 0.0097277757 | H25: =H24/$B$24*100 -> 0.87575605 | I25: =I24/$B$24*100 -> 0.7717994 | L25: =L24/$B$24*100 -> 0.57018649 | P25: =P24/$B$24*100 -> 0.37014869 | S25: =S24/$B$24*100 -> 2.4965348 | Y25: =Y24/$B$24*100 -> 0.012600806 | Z25: =Z24/$B$24*100 -> 0.12915827
A26: 45823 | B26: SUNDAY
A27: 45824 | B27: 11497 | C27: 10483 | D27: 400 | E27: =D27/B27*100 -> 3.4791685 | F27: =B27-(C27+D27) -> 614 | G27: =F27/B27*100 -> 5.3405236 | H27: 62 | I27: 90 | L27: 18 | P27: 7 | Q27: 103 | S27: 330 | Z27: 4
A28: 45825 | B28: 11226 | C28: 10107 | D28: 324 | E28: =D28/B28*100 -> 2.8861571 | F28: =B28-(C28+D28) -> 795 | G28: =F28/B28*100 -> 7.0817745 | H28: 100 | I28: 164 | L28: 110 | P28: 35 | Q28: 39 | S28: 340 | Z28: 7
A29: 45826 | B29: 10787 | C29: 9862 | D29: 310 | E29: =D29/B29*100 -> 2.8738296 | F29: =B29-(C29+D29) -> 615 | G29: =F29/B29*100 -> 5.7013071 | H29: 92 | I29: 118 | L29: 5 | P29: 85 | Q29: 15 | S29: 298 | Z29: 2
A30: 45827 | B30: 11204 | C30: 10148 | D30: 524 | E30: =D30/B30*100 -> 4.6769011 | F30: =B30-(C30+D30) -> 532 | G30: =F30/B30*100 -> 4.7483042 | H30: 103 | I30: 36 | L30: 6 | P30: 58 | Q30: 45 | S30: 281 | Y30: 1 | Z30: 2
A31: 45828 | B31: 9384 | C31: 8614 | D31: 214 | E31: =D31/B31*100 -> 2.2804774 | F31: =B31-(C31+D31) -> 556 | G31: =F31/B31*100 -> 5.9249787 | H31: 151 | I31: 73 | L31: 14 | P31: 14 | S31: 299 | Y31: 3 | Z31: 2
A32: 45829 | B32: 10569 | C32: 9860 | D32: 259 | E32: =D32/B32*100 -> 2.450563 | F32: =B32-(C32+D32) -> 450 | G32: =F32/B32*100 -> 4.2577349 | H32: 61 | I32: 38 | L32: 16 | P32: 41 | Q32: 20 | S32: 264 | Y32: 6 | Z32: 4
A33: TOTAL | B33: =SUM(B27:B32) -> 64667 | C33: =SUM(C27:C32) -> 59074 | D33: =SUM(D27:D32) -> 2031 | F33: =SUM(F27:F32) -> 3562 | G33: =F33/B33*100 -> 5.508219 | H33: =SUM(H27:H32) -> 569 | I33: =SUM(I27:I32) -> 519 | J33: =SUM(J27:J32) -> 0 | K33: =SUM(K27:K32) -> 0 | L33: =SUM(L27:L32) -> 169 | M33: =SUM(M27:M32) -> 0 | N33: =SUM(N27:N32) -> 0 | O33: =SUM(O27:O32) -> 0 | ... AB33: =SUM(AB27:AB32) -> 0
A34: % | C34: =C33/B33*100 -> 91.351076 | D34: =D33/B33*100 -> 3.1407055 | F34: =F33/B33*100 -> 5.508219 | H34: =H33/B33*100 -> 0.87989237 | I34: =I33/$B$33*100 -> 0.80257318 | L34: =L33/$B$33*100 -> 0.26133886 | P34: =P33/$B$33*100 -> 0.37113211 | S34: =S33/$B$33*100 -> 2.8020474 | X34: =X33/$B$33*100 -> 0 | Y34: =Y33/$B$33*100 -> 0.015463838 | Z34: =Z33/$B$33*100 -> 0.032474059 | AA34: =AA33/$B$33*100 -> 0
A35: 45830 | B35: 10013 | C35: 9544 | D35: 164 | E35: =D35/B35*100 -> 1.6378708 | F35: =B35-(C35+D35) -> 305 | G35: =F35/B35*100 -> 3.0460401 | H35: 53 | I35: 43 | L35: 23 | P35: 25 | Q35: 39 | S35: 120 | Z35: 2
A36: 45831 | B36: 12989 | C36: 12288 | D36: 318 | E36: =D36/B36*100 -> 2.4482254 | F36: =B36-(C36+D36) -> 383 | G36: =F36/B36*100 -> 2.9486489 | H36: 25 | I36: 38 | L36: 14 | P36: 68 | Q36: 32 | S36: 204 | Y36: 2
A37: 45832 | B37: 11910 | C37: 10958 | D37: 249 | E37: =D37/B37*100 -> 2.0906801 | F37: =B37-(C37+D37) -> 703 | G37: =F37/B37*100 -> 5.9026029 | H37: 140 | I37: 117 | M37: 100 | P37: 28 | Q37: 10 | S37: 308
A38: 45833 | B38: 11260 | C38: 10404 | D38: 176 | E38: =D38/B38*100 -> 1.5630551 | F38: =B38-(C38+D38) -> 680 | G38: =F38/B38*100 -> 6.0390764 | H38: 201 | I38: 143 | L38: 35 | P38: 15 | Q38: 61 | S38: 225
A39: 45834 | B39: 12886 | C39: 12069 | D39: 230 | E39: =D39/B39*100 -> 1.7848828 | F39: =B39-(C39+D39) -> 587 | G39: =F39/B39*100 -> 4.5553314 | H39: 122 | I39: 68 | L39: 11 | P39: 25 | Q39: 7 | S39: 347 | Y39: 3 | Z39: 4
A40: 45835 | B40: 11844 | C40: 11028 | D40: 160 | E40: =D40/B40*100 -> 1.350895 | F40: =B40-(C40+D40) -> 656 | G40: =F40/B40*100 -> 5.5386694 | H40: 143 | I40: 71 | L40: 18 | P40: 18 | Q40: 8 | S40: 348
...

Sheet JULY 25
B1: DISPOSAFE HEALTH AND LIFE CARE LIMITED Plot No.37A, Sector-06, Ballabgarh (Faridabad) Haryana India 121006 | X1: Doc. No. : | AA1: F/QC/01:00
X2: Supersedes : | AA2: 00
X3: Effective Date : | AA3: 45607
B4: VISUAL INSPECTION REPORT | X4: Page 1 of 1
A5: DATE | B5: REC. QTY | C5: ACCEPT QTY | D5: HOLD QTY | E5: HOLD% | F5: REJ. QTY | G5: REJ % | H5: REASON FOR REJECTION
H6: 1 | I6: 2 | J6: 3 | K6: 4 | L6: 5 | M6: 6 | N6: 7 | O6: 8 | P6: 9 | Q6: 10 | R6: 11 | S6: 12 | T6: 13 | U6: 14 | V6: 15 | W6: 16 | X6: 17 | Y6: 18 | Z6: 19 | AA6: 20 | AB6: 21
H7: COAG | I7: SD | J7: TT | K7: BL | L7: PS | M7: SB | N7: PW | O7: FP | P7: RW | Q7: BEP | R7: DEC | S7: BM | T7: WEB | U7: BT | V7: SF | W7: BIC | X7: WK | Y7: BMP | Z7: TF | AA7: PH | AB7: BST
A8: 45839 | B8: 7482 | C8: 6049 | D8: 482 | E8: =D8/B8*100 -> 6.4421278 | F8: =B8-(C8+D8) -> 951 | G8: =F8/B8*100 -> 12.710505 | H8: 245 | I8: 72 | L8: 68 | P8: 14 | Q8: 45 | S8: 507
A9: 45840 | B9: 13349 | C9: 11022 | D9: 1352 | E9: =D9/B9*100 -> 10.128099 | F9: =B9-(C9+D9) -> 975 | G9: =F9/B9*100 -> 7.3039179 | H9: 460 | I9: 81 | L9: 168 | P9: 20 | Q9: 5 | S9: 221 | T9: 13 | Z9: 7
A10: 45841 | B10: 10643 | C10: 9232 | D10: 419 | E10: =D10/B10*100 -> 3.9368599 | F10: =B10-(C10+D10) -> 992 | G10: =F10/B10*100 -> 9.3206803 | H10: 175 | I10: 78 | L10: 96 | P10: 80 | Q10: 136 | S10: 402 | Z10: 25
A11: 45842 | B11: 13078 | C11: 11892 | D11: 391 | E11: =D11/B11*100 -> 2.9897538 | F11: =B11-(C11+D11) -> 795 | G11: =F11/B11*100 -> 6.0789111 | H11: 161 | I11: 70 | L11: 38 | P11: 43 | Q11: 62 | S11: 416 | Y11: 5
A12: 45843 | B12: 10618 | C12: 9749 | D12: 308 | E12: =D12/B12*100 -> 2.9007346 | F12: =B12-(C12+D12) -> 561 | G12: =F12/B12*100 -> 5.2834809 | H12: 151 | I12: 119 | L12: 30 | Q12: 29 | S12: 232
A13: TOTAL | B13: =SUM(B8:B12) -> 55170 | C13: =SUM(C8:C12) -> 47944 | D13: =SUM(D8:D12) -> 2952 | E13: =SUM(E8:E12) -> 26.397576 | F13: =SUM(F8:F12) -> 4274 | G13: =SUM(G8:G12) -> 40.697495 | H13: =SUM(H8:H12) -> 1192 | I13: =SUM(I8:I12) -> 420 | ... AB13: =SUM(AB8:AB12) -> 0
A14: % | C14: =C13/$B$13*100 -> 86.902302 | D14: =D13/$B$13*100 -> 5.3507341 | E14: =E13/$B$13*100 -> 0.047847699 | F14: =F13/$B$13*100 -> 7.7469639 | G14: =G13/$B$13*100 -> 0.073767438 | H14: =H13/$B$13*100 -> 2.1605945 | I14: =I13/$B$13*100 -> 0.76128331 | J14: =J13/$B$13*100 -> 0 | ... AB14: =AB13/$B$13*100 -> 0 | AC14: =SUM(H14:AB14) -> 7.7469639
A15: 45844 | B15: 8182 | C15: 7202 | D15: 148 | E15: =D15/B15*100 -> 1.8088487 | F15: =B15-(C15+D15) -> 832 | G15: =F15/B15*100 -> 10.168663 | H15: 128 | I15: 29 | L15: 301 | P15: 47 | Q15: 14 | S15: 311 | Z15: 2 | AE15: =SUM(B35:B39,B43:B46,'AUGUST 25'!B8:B9,'AUGUST 25'!B13:B17,'AUGUST 25'!B22:B25,'AUGUST 25'!B30:B35) -> 300203 | AG15: =SUM(F35:F39,F43:F46,'AUGUST 25'!F8:F9,'AUGUST 25'!F13:F17,'AUGUST 25'!F22:F25,'AUGUST 25'!F30:F35) -> 11935 | AI15: =AG15/AE15*100 -> 3.9756431
A16: 45845 | B16: 9058 | C16: 7949 | D16: 418 | E16: =D16/B16*100 -> 4.6147052 | F16: =B16-(C16+D16) -> 691 | G16: =F16/B16*100 -> 7.6286156 | H16: 110 | I16: 199 | L16: 127 | P16: 9 | Q16: 51 | S16: 195
A17: 45846 | B17: 9811 | C17: 8359 | D17: 359 | E17: =D17/B17*100 -> 3.6591581 | F17: =B17-(C17+D17) -> 1093 | G17: =F17/B17*100 -> 11.140557 | H17: 110 | I17: 266 | L17: 40 | P17: 43 | Q17: 237 | S17: 390 | Z17: 7
A18: 45847 | B18: 11534 | C18: 10670 | D18: 190 | E18: =D18/B18*100 -> 1.6473036 | F18: =B18-(C18+D18) -> 674 | G18: =F18/B18*100 -> 5.8435929 | H18: 100 | I18: 77 | L18: 79 | P18: 52 | Q18: 29 | S18: 333 | Y18: 3 | Z18: 1
A19: 45848 | B19: 10445 | C19: 9505 | D19: 167 | E19: =D19/B19*100 -> 1.5988511 | F19: =B19-(C19+D19) -> 773 | G19: =F19/B19*100 -> 7.4006702 | H19: 70 | I19: 223 | L19: 123 | P19: 18 | Q19: 26 | S19: 298 | X19: 15
A20: 45849 | B20: 10340 | C20: 9422 | D20: 328 | E20: =D20/B20*100 -> 3.172147 | F20: =B20-(C20+D20) -> 590 | G20: =F20/B20*100 -> 5.7059961 | H20: 98 | I20: 81 | L20: 11 | P20: 61 | S20: 231 | X20: 100 | Z20: 8
A21: 45850 | B21: 11138 | C21: 10176 | D21: 350 | E21: =D21/B21*100 -> 3.1423954 | F21: =B21-(C21+D21) -> 612 | G21: =F21/B21*100 -> 5.4947028 | H21: 81 | I21: 42 | L21: 15 | P21: 77 | Q21: 5 | S21: 325 | X21: 57 | Y21: 2 | Z21: 8
A22: TOTAL | B22: =SUM(B15:B21) -> 70508 | C22: =SUM(C15:C21) -> 63283 | D22: =SUM(D15:D21) -> 1960 | E22: =SUM(E15:E21) -> 19.643409 | F22: =SUM(F15:F21) -> 5265 | G22: =F22/B22*100 -> 7.4672378 | H22: =SUM(H15:H21) -> 697 | I22: =SUM(I15:I21) -> 917 | J22: =SUM(J15:J21) -> 0 | K22: =SUM(K15:K21) -> 0 | L22: =SUM(L15:L21) -> 696 | M22: =SUM(M15:M21) -> 0 | N22: =SUM(N15:N21) -> 0 | O22: =SUM(O15:O21) -> 0 | ... AB22: =SUM(AB15:AB21) -> 0
A23: % | C23: =C22/$B$22*100 -> 89.752936 | D23: =D22/$B$22*100 -> 2.7798264 | E23: =E22/$B$22*100 -> 0.02785983 | F23: =F22/$B$22*100 -> 7.4672378 | G23: =G22/$B$22*100 -> 0.010590625 | H23: =H22/$B$22*100 -> 0.98854031 | I23: =I22/$B$22*100 -> 1.3005616 | J23: =J22/$B$22*100 -> 0 | ... AB23: =AB22/$B$22*100 -> 0 | AC23: =SUM(H23:AB23) -> 7.4672378
A24: 45851 | E24: =D24/B24*100 -> #DIV/0! | F24: =B24-(C24+D24) -> 0 | G24: =F24/B24*100 -> #DIV/0!
A25: 45852 | B25: 11290 | C25: 10305 | D25: 385 | E25: =D25/B25*100 -> 3.4100974 | F25: =B25-(C25+D25) -> 600 | G25: =F25/B25*100 -> 5.3144376 | H25: 116 | I25: 53 | L25: 28 | P25: 54 | Q25: 18 | S25: 307 | X25: 12 | Y25: 8 | Z25: 4
A26: 45853 | B26: 11943 | C26: 11116 | D26: 255 | E26: =D26/B26*100 -> 2.1351419 | F26: =B26-(C26+D26) -> 572 | G26: =F26/B26*100 -> 4.7894164 | H26: 125 | I26: 77 | P26: 31 | Q26: 17 | S26: 242 | X26: 10 | Y26: 10 | Z26: 60
A27: 45854 | B27: 9674 | C27: 9005 | D27: 65 | E27: =D27/B27*100 -> 0.67190407 | F27: =B27-(C27+D27) -> 604 | G27: =F27/B27*100 -> 6.2435394 | H27: 110 | I27: 100 | L27: 78 | Q27: 31 | S27: 184 | Z27: 81
A28: 45855 | B28: 10096 | C28: 9429 | D28: 64 | E28: =D28/B28*100 -> 0.63391442 | F28: =B28-(C28+D28) -> 603 | G28: =F28/B28*100 -> 5.9726624 | H28: 95 | I28: 97 | L28: 26 | M28: 6 | Q28: 101 | S28: 236 | Z28: 42
A29: 45856 | B29: 12103 | C29: 11421 | D29: 157 | E29: =D29/B29*100 -> 1.297199 | F29: =B29-(C29+D29) -> 525 | G29: =F29/B29*100 -> 4.3377675 | H29: 93 | I29: 86 | L29: 43 | Q29: 30 | S29: 234 | Z29: 39
A30: 45857 | B30: 12283 | C30: 11507 | D30: 221 | E30: =D30/B30*100 -> 1.7992347 | F30: =B30-(C30+D30) -> 555 | G30: =F30/B30*100 -> 4.5184401 | H30: 101 | I30: 76 | L30: 77 | Q30: 40 | S30: 242 | Z30: 20
A31: TOTAL | B31: =SUM(B24:B30) -> 67389 | C31: =SUM(C24:C30) -> 62783 | D31: =SUM(D24:D30) -> 1147 | E31: =SUM(E24:E30) -> #DIV/0! | F31: =SUM(F24:F30) -> 3459 | G31: =SUM(G24:G30) -> #DIV/0! | H31: =SUM(H24:H30) -> 640 | I31: =SUM(I24:I30) -> 489 | ... AB31: =SUM(AB24:AB30) -> 0
A32: % | C32: =C31/$B$31*100 -> 93.165057 | D32: =D31/$B$31*100 -> 1.7020582 | E32: =E31/$B$31*100 -> #DIV/0! | F32: =F31/$B$31*100 -> 5.1328852 | G32: =G31/$B$31*100 -> #DIV/0! | H32: =H31/$B$31*100 -> 0.94970989 | I32: =I31/$B$31*100 -> 0.72563772 | J32: =J31/$B$31*100 -> 0 | ... AB32: =AB31/$B$31*100 -> 0 | AC32: =SUM(H32:AB32) -> 5.1046907
A33: 45858 | E33: =D33/B33*100 -> #DIV/0! | F33: =B33-(C33+D33) -> 0 | G33: =F33/B33*100 -> #DIV/0!
A34: 45859 | B34: 10884 | C34: 10120 | D34: 340 | E34: =D34/B34*100 -> 3.1238515 | F34: =B34-(C34+D34) -> 424 | G34: =F34/B34*100 -> 3.8956266 | H34: 70 | I34: 65 | L34: 61 | Q34: 24 | S34: 165 | Z34: 39
A35: 45860 | B35: 14229 | C35: 13366 | D35: 282 | E35: =D35/B35*100 -> 1.981868 | F35: =B35-(C35+D35) -> 581 | G35: =F35/B35*100 -> 4.0832103 | H35: 63 | I35: 56 | L35: 23 | P35: 42 | Q35: 10 | S35: 362 | X35: 5 | Y35: 18 | Z35: 2
A36: 45861 | B36: 14278 | C36: 13291 | D36: 342 | E36: =D36/B36*100 -> 2.3952935 | F36: =B36-(C36+D36) -> 645 | G36: =F36/B36*100 -> 4.5174394 | H36: 130 | I36: 69 | L36: 44 | P36: 2 | Q36: 35 | S36: 314 | Y36: 30 | Z36: 21
A37: 45862 | B37: 15795 | C37: 14843 | D37: 443 | E37: =D37/B37*100 -> 2.804685 | F37: =B37-(C37+D37) -> 509 | G37: =F37/B37*100 -> 3.2225388 | H37: 111 | I37: 68 | L37: 27 | P37: 2 | Q37: 1 | S37: 280 | Y37: 20
A38: 45863 | B38: 13114 | C38: 12280 | D38: 273 | E38: =D38/B38*100 -> 2.0817447 | F38: =B38-(C38+D38) -> 561 | G38: =F38/B38*100 -> 4.277871 | H38: 93 | I38: 62 | P38: 10 | S38: 260 | Y38: 134 | Z38: 2
A39: 45864 | B39: 15077 | C39: 13976 | D39: 486 | E39: =D39/B39*100 -> 3.2234529 | F39: =B39-(C39+D39) -> 615 | G39: =F39/B39*100 -> 4.0790608 | H39: 132 | I39: 59 | P39: 55 | Q39: 1 | S39: 231 | Y39: 129 | Z39: 9
A40: TOTAL | B40: =SUM(B33:B39) -> 83377 | C40: =SUM(C33:C39) -> 77876 | D40: =SUM(D33:D39) -> 2166 | E40: =SUM(E33:E39) -> #DIV/0! | F40: =SUM(F33:F39) -> 3335 | G40: =SUM(G33:G39) -> #DIV/0! | H40: =SUM(H33:H39) -> 599 | I40: =SUM(I33:I39) -> 379 | ... AB40: =SUM(AB33:AB39) -> 0
...

Sheet AUGUST 25
B1: DISPOSAFE HEALTH AND LIFE CARE LIMITED Plot No.37A, Sector-06, Ballabgarh (Faridabad) Haryana India 121006 | X1: Doc. No. : | AA1: F/QC/01:00
X2: Supersedes : | AA2: 00
X3: Effective Date : | AA3: 45607
B4: VISUAL INSPECTION REPORT | X4: Page 1 of 1
A5: DATE | B5: REC. QTY | C5: ACCEPT QTY | D5: HOLD QTY | E5: HOLD% | F5: REJ. QTY | G5: REJ % | H5: REASON FOR REJECTION
H6: 1 | I6: 2 | J6: 3 | K6: 4 | L6: 5 | M6: 6 | N6: 7 | O6: 8 | P6: 9 | Q6: 10 | R6: 11 | S6: 12 | T6: 13 | U6: 14 | V6: 15 | W6: 16 | X6: 17 | Y6: 18 | Z6: 19 | AA6: 20 | AB6: 21
H7: COAG | I7: SD | J7: TT | K7: BL | L7: PS | M7: SB | N7: PW | O7: FP | P7: RW | Q7: BEP | R7: DEC | S7: BM | T7: WEB | U7: BT | V7: SF | W7: BIC | X7: WK | Y7: BMP | Z7: TF | AA7: PH | AB7: BST
A8: 45870 | B8: 14352 | C8: 13483 | D8: 412 | E8: =D8/B8*100 -> 2.87068 | F8: =B8-(C8+D8) -> 457 | G8: =F8/B8*100 -> 3.1842252 | H8: 80 | I8: 41 | P8: 48 | Q8: 2 | S8: 183 | X8: 2 | Y8: 10 | Z8: 71
A9: 45871 | B9: 11884 | C9: 11771 | D9: 231 | E9: =D9/B9*100 -> 1.94379 | F9: 423 | G9: =F9/B9*100 -> 3.5594076 | H9: 78 | I9: 71 | L9: 5 | P9: 38 | Q9: 13 | S9: 162 | Y9: 8 | Z9: 46
A10: TOTAL | B10: =SUM(B8:B9) -> 26236 | C10: =SUM(C8:C9) -> 25254 | D10: =SUM(D8:D9) -> 643 | E10: =SUM(E8:E9) -> 4.81447 | F10: =SUM(F8:F9) -> 880 | G10: =SUM(G8:G9) -> 6.7436328 | H10: =SUM(H8:H9) -> 158 | I10: =SUM(I8:I9) -> 112 | ... AB10: =SUM(AB8:AB9) -> 0
A11: % | C11: =C10/$B$10*100 -> 96.257051 | D11: =D10/$B$10*100 -> 2.4508309 | E11: =E10/$B$10*100 -> 0.018350625 | F11: =F10/$B$10*100 -> 3.3541698 | G11: =G10/$B$10*100 -> 0.025703738 | H11: =H10/$B$10*100 -> 0.60222595 | I11: =I10/$B$10*100 -> 0.42689434 | J11: =J10/$B$10*100 -> 0 | ... AB11: =AB10/$B$10*100 -> 0 | AC11: =SUM(H11:AB11) -> 3.2703156
A12: 45872 | E12: =D12/B12*100 -> #DIV/0! | F12: =B12-(C12+D12) -> 0 | G12: =F12/B12*100 -> #DIV/0!
A13: 45873 | B13: 9697 | C13: 8890 | D13: 526 | E13: =D13/B13*100 -> 5.424358 | F13: =B13-(C13+D13) -> 281 | G13: =F13/B13*100 -> 2.8978034 | H13: 49 | I13: 17 | P13: 108 | S13: 65 | Y13: 42
A14: 45874 | B14: 12170 | C14: 10928 | D14: 705 | E14: =D14/B14*100 -> 5.7929334 | F14: =B14-(C14+D14) -> 537 | G14: =F14/B14*100 -> 4.4124897 | H14: 139 | I14: 24 | P14: 125 | S14: 176 | Y14: 68 | Z14: 5
A15: 45875 | B15: 9162 | C15: 8596 | D15: 275 | E15: =D15/B15*100 -> 3.0015281 | F15: =B15-(C15+D15) -> 291 | G15: =F15/B15*100 -> 3.1761624 | H15: 96 | I15: 20 | P15: 79 | Q15: 13 | S15: 64 | Y15: 13 | Z15: 6
A16: 45876 | B16: 11553 | C16: 9762 | D16: 1207 | E16: =D16/B16*100 -> 10.447503 | F16: =B16-(C16+D16) -> 584 | G16: =F16/B16*100 -> 5.0549641 | H16: 96 | I16: 74 | P16: 65 | Q16: 5 | S16: 199 | Y16: 140 | Z16: 5
A17: 45877 | B17: 8843 | C17: 6765 | D17: 1341 | E17: =D17/B17*100 -> 15.164537 | F17: =B17-(C17+D17) -> 737 | G17: =F17/B17*100 -> 8.3342757 | H17: 60 | I17: 60 | L17: 8 | P17: 102 | S17: 352 | X17: 2 | Y17: 169 | Z17: 4
A18: 45878 | B18: HOLIDAY
A19: TOTAL | B19: =SUM(B12:B18) -> 51425 | C19: =SUM(C12:C18) -> 44941 | D19: =SUM(D12:D18) -> 4054 | E19: =SUM(E12:E18) -> #DIV/0! | F19: =SUM(F12:F18) -> 2430 | G19: =SUM(G12:G18) -> #DIV/0! | H19: =SUM(H12:H18) -> 440 | I19: =SUM(I12:I18) -> 195 | ... AB19: =SUM(AB12:AB18) -> 0
A20: % | C20: =C19/$B$19*100 -> 87.391347 | D20: =D19/$B$19*100 -> 7.8833252 | E20: =E19/$B$19*100 -> #DIV/0! | F20: =F19/$B$19*100 -> 4.7253281 | G20: =G19/$B$19*100 -> #DIV/0! | H20: =H19/$B$19*100 -> 0.85561497 | I20: =I19/$B$19*100 -> 0.379193 | J20: =J19/$B$19*100 -> 0 | ... AB20: =AB19/$B$19*100 -> 0 | AC20: =SUM(H20:AB20) -> 4.7642197
A21: 45879 | E21: 0 | F21: =B21-(C21+D21) -> 0
A22: 45880 | B22: 10488 | C22: 9678 | D22: 656 | E22: =D22/B22*100 -> 6.2547674 | F22: =B22-(C22+D22) -> 154 | G22: =F22/B22*100 -> 1.4683448 | H22: 207 | L22: 102 | Q22: 6 | S22: 92 | X22: 138 | Y22: 101 | Z22: 10
A23: 45881 | B23: 7782 | C23: 6410 | D23: 743 | E23: =D23/B23*100 -> 9.5476741 | F23: =B23-(C23+D23) -> 629 | G23: =F23/B23*100 -> 8.0827551 | H23: 103 | I23: 17 | L23: 3 | Q23: 67 | S23: 165 | X23: 214 | Y23: 45 | Z23: 15
A24: 45882 | B24: 9961 | C24: 8888 | D24: 612 | E24: =D24/B24*100 -> 6.1439614 | F24: =B24-(C24+D24) -> 461 | G24: =F24/B24*100 -> 4.6280494 | H24: 80 | I24: 5 | Q24: 56 | S24: 142 | X24: 74 | Y24: 17 | Z24: 87
A25: 45883 | B25: 8592 | C25: 7888 | D25: 361 | E25: =D25/B25*100 -> 4.2015829 | F25: =B25-(C25+D25) -> 343 | G25: =F25/B25*100 -> 3.9920857 | H25: 56 | I25: 10 | Q25: 13 | S25: 67 | X25: 53 | Y25: 9 | Z25: 135
A26: 45884 | B26: HOLIDAY | E26: =D26/B26*100 -> #VALUE! | F26: =B26-(C26+D26) -> #VALUE! | G26: =F26/B26*100 -> #VALUE!
A27: 45884 | B27: HOLIDAY
A28: TOTAL | B28: =SUM(B21:B27) -> 36823 | C28: =SUM(C21:C27) -> 32864 | D28: =SUM(D21:D27) -> 2372 | F28: =SUM(F21:F25) -> 1587 | G28: =SUM(G21:G25) -> 18.171235 | H28: =SUM(H21:H27) -> 446 | I28: =SUM(I21:I27) -> 32 | J28: =SUM(J21:J27) -> 0 | K28: =SUM(K21:K27) -> 0 | L28: =SUM(L21:L27) -> 105 | M28: =SUM(M21:M27) -> 0 | N28: =SUM(N21:N27) -> 0 | O28: =SUM(O21:O27) -> 0 | ... AB28: =SUM(AB21:AB27) -> 0
A29: % | C29: =C28/$B$28*100 -> 89.248567 | D29: =D28/$B$28*100 -> 6.4416262 | F29: =F28/$B$28*100 -> 4.3098064 | G29: =G28/$B$28*100 -> 0.049347514 | H29: =H28/$B$28*100 -> 1.2111995 | I29: =I28/$B$28*100 -> 0.086902208 | J29: =J28/$B$28*100 -> 0 | K29: =K28/$B$28*100 -> 0 | L29: =L28/$B$28*100 -> 0.28514787 | M29: =M28/$B$28*100 -> 0 | ... AB29: =AB28/$B$28*100 -> 0 | AC29: =SUM(H29:AB29) -> 5.6730848
A30: 45886 | B30: 8547 | C30: 8242 | D30: 86 | E30: =D30/B30*100 -> 1.006201 | F30: =B30-(C30+D30) -> 219 | G30: =F30/B30*100 -> 2.5623026 | H30: 34 | I30: 16 | Q30: 16 | S30: 66 | Z30: 87
A31: 45887 | B31: 6890 | C31: 6696 | D31: 89 | E31: =D31/B31*100 -> 1.2917271 | F31: =B31-(C31+D31) -> 105 | G31: =F31/B31*100 -> 1.5239478 | H31: 26 | I31: 19 | Q31: 9 | S31: 32 | Y31: 2 | Z31: 17
A32: 45888 | B32: 11334 | C32: 10733 | D32: 74 | E32: =D32/B32*100 -> 0.65290277 | F32: =B32-(C32+D32) -> 527 | G32: =F32/B32*100 -> 4.6497265 | H32: 59 | I32: 18 | L32: 143 | Q32: 154 | S32: 106 | X32: 6 | Y32: 12 | Z32: 29
A33: 45889 | B33: 12010 | C33: 11516 | D33: 45 | E33: =D33/B33*100 -> 0.37468776 | F33: =B33-(C33+D33) -> 449 | G33: =F33/B33*100 -> 3.7385512 | H33: 55 | I33: 22 | L33: 32 | Q33: 155 | S33: 78 | X33: 79 | Y33: 10 | Z33: 18
A34: 45890 | B34: 12150 | C34: 11422 | D34: 204 | E34: =D34/B34*100 -> 1.6790123 | F34: =B34-(C34+D34) -> 524 | G34: =F34/B34*100 -> 4.3127572 | H34: 96 | I34: 19 | L34: 56 | Q34: 63 | R34: 209 | S34: 72 | X34: 1 | Y34: 3 | Z34: 5
A35: 45891 | B35: 11276 | C35: 10723 | D35: 271 | E35: =D35/B35*100 -> 2.4033345 | F35: =B35-(C35+D35) -> 282 | G35: =F35/B35*100 -> 2.5008868 | H35: 119 | I35: 11 | L35: 61 | Q35: 12 | S35: 73 | Y35: 3 | Z35: 3
A36: 45892 | B36: 14379 | C36: 13789 | D36: 312 | E36: =D36/B36*100 -> 2.169831 | F36: =B36-(C36+D36) -> 278 | G36: =F36/B36*100 -> 1.9333751 | H36: 80 | I36: 3 | P36: 22 | Q36: 10 | S36: 120 | Z36: 43 | AF36: 2296
A37: TOTAL | B37: =SUM(B30:B36) -> 76586 | C37: =SUM(C30:C36) -> 73121 | D37: =SUM(D30:D36) -> 1081 | F37: =SUM(F30:F36) -> 2384 | G37: =SUM(G30:G36) -> 21.221547 | H37: =SUM(H30:H36) -> 469 | I37: =SUM(I30:I36) -> 108 | J37: =SUM(J30:J36) -> 0 | K37: =SUM(K30:K36) -> 0 | L37: =SUM(L30:L36) -> 292 | M37: =SUM(M30:M36) -> 0 | ... AB37: =SUM(AB30:AB36) -> 0
A38: % | C38: =C37/$B$37*100 -> 95.475674 | D38: =D37/$B$37*100 -> 1.4114851 | F38: =F37/$B$37*100 -> 3.1128405 | G38: =G37/$B$37*100 -> 0.027709434 | H38: =H37/$B$37*100 -> 0.61238346 | I38: =I37/$B$37*100 -> 0.14101794 | J38: =J37/$B$37*100 -> 0 | K38: =K37/$B$37*100 -> 0 | L38: =L37/$B$37*100 -> 0.38127073 | M38: =M37/$B$37*100 -> 0 | ... AB38: =AB37/$B$37*100 -> 0 | AC38: =SUM(H38:AB38) -> 3.1128405 | AF38: =AF36*(1-2.5%) -> 2238.6
A39: 45893 | E39: =D39/B39*100 -> #DIV/0! | F39: =B39-(C39+D39) -> 0 | G39: =F39/B39*100 -> #DIV/0!
A40: 45894 | B40: 15667 | C40: 14501 | D40: 304 | E40: =D40/B40*100 -> 1.9403842 | F40: =B40-(C40+D40) -> 862 | G40: =F40/B40*100 -> 5.5020106 | H40: 195 | I40: 26 | L40: 387 | Q40: 9 | S40: 127 | X40: 134 | Y40: 22 | Z40: 12
...

Sheet SEPTEMBER 25
B1: DISPOSAFE HEALTH AND LIFE CARE LIMITED Plot No.37A, Sector-06, Ballabgarh (Faridabad) Haryana India 121006 | X1: Doc. No. : | AA1: F/QC/01:00
X2: Supersedes : | AA2: 00
X3: Effective Date : | AA3: 45607
B4: VISUAL INSPECTION REPORT | X4: Page 1 of 1
A5: DATE | B5: REC. QTY | C5: ACCEPT QTY | D5: HOLD QTY | E5: HOLD% | F5: REJ. QTY | G5: REJ % | H5: REASON FOR REJECTION
H6: 1 | I6: 2 | J6: 3 | K6: 4 | L6: 5 | M6: 6 | N6: 7 | O6: 8 | P6: 9 | Q6: 10 | R6: 11 | S6: 12 | T6: 13 | U6: 14 | V6: 15 | W6: 16 | X6: 17 | Y6: 18 | Z6: 19 | AA6: 20 | AB6: 21
H7: COAG | I7: SD | J7: TT | K7: BL | L7: PS | M7: SB | N7: PW | O7: FP | P7: RW | Q7: BEP | R7: DEC | S7: BM | T7: WEB | U7: BT | V7: SF | W7: BIC | X7: WK | Y7: BMP | Z7: TF | AA7: PH | AB7: BST
A8: 45901 | B8: 10978 | C8: 10362 | D8: 160 | E8: =D8/B8*100 -> 1.4574604 | F8: =B8-(C8+D8) -> 456 | G8: =F8/B8*100 -> 4.1537621 | H8: 23 | I8: 30 | L8: 221 | Q8: 48 | S8: 107 | X8: 1 | Y8: 13 | Z8: 13
A9: 45902 | B9: 11564 | C9: 10203 | D9: 121 | E9: =D9/B9*100 -> 1.0463507 | F9: =B9-(C9+D9) -> 1240 | G9: =F9/B9*100 -> 10.722933 | H9: 26 | I9: 57 | L9: 1000 | Q9: 66 | S9: 65 | Y9: 21 | Z9: 5
A10: 45903 | B10: 15899 | C10: 13162 | D10: 375 | E10: =D10/B10*100 -> 2.3586389 | F10: =B10-(C10+D10) -> 2362 | G10: =F10/B10*100 -> 14.85628 | H10: 60 | I10: 64 | L10: 1355 | Q10: 311 | S10: 164 | X10: 374 | Y10: 28 | Z10: 6
A11: 45904 | B11: 16134 | C11: 15038 | D11: 160 | E11: =D11/B11*100 -> 0.99169456 | F11: =B11-(C11+D11) -> 936 | G11: =F11/B11*100 -> 5.8014132 | H11: 24 | I11: 26 | L11: 745 | Q11: 7 | S11: 108 | Y11: 24 | Z11: 2
A12: 45905 | B12: 11960 | C12: 9933 | D12: 134 | E12: =D12/B12*100 -> 1.1204013 | F12: =B12-(C12+D12) -> 1893 | G12: =F12/B12*100 -> 15.827759 | H12: 30 | I12: 6 | L12: 1743 | Q12: 3 | S12: 66 | Y12: 39 | Z12: 6
A13: 45906 | B13: 12754 | C13: 11459 | D13: 166 | E13: =D13/B13*100 -> 1.3015525 | F13: =B13-(C13+D13) -> 1129 | G13: =F13/B13*100 -> 8.8521248 | H13: 27 | I13: 46 | L13: 887 | Q13: 108 | Y13: 8 | Z13: 53
A14: TOTAL | B14: =SUM(B8:B13) -> 79289 | C14: =SUM(C8:C13) -> 70157 | D14: =SUM(D8:D13) -> 1116 | E14: =SUM(E8:E13) -> 8.2760984 | F14: =SUM(F8:F13) -> 8016 | G14: =SUM(G8:G13) -> 60.214273 | H14: =SUM(H8:H13) -> 190 | I14: =SUM(I8:I13) -> 229 | ... AB14: =SUM(AB8:AB13) -> 0
A15: % | C15: =C14/$B$14*100 -> 88.482639 | D15: =D14/$B$14*100 -> 1.4075092 | E15: =E14/$B$14*100 -> 0.01043789 | F15: =F14/$B$14*100 -> 10.109851 | G15: =G14/$B$14*100 -> 0.075942782 | H15: =H14/$B$14*100 -> 0.23962971 | I15: =I14/$B$14*100 -> 0.28881686 | J15: =J14/$B$14*100 -> 0 | ... AB15: =AB14/$B$14*100 -> 0 | AC15: =SUM(H15:AB15) -> 10.109851
A16: 45907 | E16: =D16/B16*100 -> #DIV/0! | F16: =B16-(C16+D16) -> 0 | G16: =F16/B16*100 -> #DIV/0!
A17: 45908 | B17: 20305 | C17: 18898 | D17: 318 | E17: =D17/B17*100 -> 1.5661167 | F17: =B17-(C17+D17) -> 1089 | G17: =F17/B17*100 -> 5.363211 | H17: 55 | I17: 29 | L17: 847 | Q17: 17 | S17: 91 | Y17: 35 | Z17: 15
A18: 45909 | B18: 13013 | C18: 11930 | D18: 212 | E18: =D18/B18*100 -> 1.6291401 | F18: =B18-(C18+D18) -> 871 | G18: =F18/B18*100 -> 6.6933067 | H18: 78 | I18: 23 | L18: 659 | Q18: 100 | Y18: 11
A19: 45910 | B19: 13029 | C19: 12069 | D19: 287 | E19: =D19/B19*100 -> 2.2027784 | F19: =B19-(C19+D19) -> 673 | G19: =F19/B19*100 -> 5.1654003 | H19: 31 | I19: 22 | L19: 481 | Q19: 2 | S19: 117 | X19: 6 | Y19: 7 | Z19: 7
A20: 45911 | B20: 9391 | C20: 7409 | D20: 130 | E20: =D20/B20*100 -> 1.3843041 | F20: =B20-(C20+D20) -> 1852 | G20: =F20/B20*100 -> 19.721009 | H20: 21 | I20: 9 | L20: 1702 | Q20: 26 | S20: 87 | Y20: 4 | Z20: 3
A21: 45912 | B21: 12457 | C21: 11920 | D21: 82 | E21: =D21/B21*100 -> 0.65826443 | F21: =B21-(C21+D21) -> 455 | G21: =F21/B21*100 -> 3.6525648 | H21: 40 | L21: 278 | P21: 4 | S21: 122 | Y21: 5 | Z21: 6
A22: 45913 | B22: 13830 | C22: 13524 | D22: 64 | E22: =D22/B22*100 -> 0.46276211 | F22: =B22-(C22+D22) -> 242 | G22: =F22/B22*100 -> 1.7498192 | H22: 74 | L22: 5 | P22: 12 | Q22: 35 | S22: 106 | Z22: 10
A23: TOTAL | B23: =SUM(B16:B22) -> 82025 | C23: =SUM(C16:C22) -> 75750 | D23: =SUM(D16:D22) -> 1093 | E23: =D23/B23*100 -> 1.3325206 | F23: =SUM(F16:F22) -> 5182 | G23: =SUM(G16:G22) -> #DIV/0! | H23: =SUM(H16:H22) -> 299 | I23: =SUM(I16:I22) -> 83 | J23: =SUM(J16:J22) -> 0 | K23: =SUM(K16:K22) -> 0 | L23: =SUM(L16:L22) -> 3972 | M23: =SUM(M16:M22) -> 0 | ... AB23: =SUM(AB16:AB22) -> 0
A24: % | C24: =C23/$B$23*100 -> 92.349893 | D24: =D23/$B$23*100 -> 1.3325206 | E24: =E23/$B$23*100 -> 0.0016245298 | F24: =F23/$B$23*100 -> 6.3175861 | G24: =G23/$B$23*100 -> #DIV/0! | H24: =H23/$B$23*100 -> 0.36452301 | I24: =I23/$B$23*100 -> 0.10118866 | J24: =J23/$B$23*100 -> 0 | ... AB24: =AB23/$B$23*100 -> 0 | AC24: =SUM(H24:AB24) -> 6.3175861
A25: 45914 | E25: 0 | F25: =B25-(C25+D25) -> 0
A26: 45915 | B26: 15012 | C26: 14439 | D26: 247 | E26: =D26/B26*100 -> 1.6453504 | F26: =B26-(C26+D26) -> 326 | G26: =F26/B26*100 -> 2.1715961 | H26: 84 | L26: 35 | P26: 13 | S26: 178 | Z26: 16
A27: 45916 | B27: 12241 | C27: 11813 | D27: 115 | E27: =D27/B27*100 -> 0.93946573 | F27: =B27-(C27+D27) -> 313 | G27: =F27/B27*100 -> 2.5569806 | H27: 42 | L27: 142 | P27: 6 | S27: 118 | Z27: 5
A28: 45917 | B28: 11948 | C28: 11126 | D28: 117 | E28: =D28/B28*100 -> 0.97924339 | F28: =B28-(C28+D28) -> 705 | G28: =F28/B28*100 -> 5.9005691 | H28: 128 | L28: 250 | P28: 8 | Q28: 15 | R28: 169 | S28: 130 | Y28: 5
A29: 45918 | B29: 10490 | C29: 10048 | D29: 128 | E29: =D29/B29*100 -> 1.2202097 | F29: =B29-(C29+D29) -> 314 | G29: =F29/B29*100 -> 2.993327 | H29: 33 | I29: 23 | L29: 202 | Q29: 28 | S29: 28
A30: 45919 | B30: 10392 | C30: 9532 | D30: 151 | E30: =D30/B30*100 -> 1.4530408 | F30: =B30-(C30+D30) -> 709 | G30: =F30/B30*100 -> 6.8225558 | H30: 169 | I30: 137 | L30: 77 | Q30: 110 | S30: 87 | X30: 111 | Y30: 9 | Z30: 9
A31: 45920 | B31: 13040 | C31: 12790 | D31: 68 | E31: =D31/B31*100 -> 0.52147239 | F31: =B31-(C31+D31) -> 182 | G31: =F31/B31*100 -> 1.3957055 | H31: 33 | I31: 18 | L31: 74 | Q31: 5 | S31: 52
A32: TOTAL | B32: =SUM(B25:B31) -> 73123 | C32: =SUM(C25:C31) -> 69748 | D32: =SUM(D25:D31) -> 826 | E32: =D32/B32*100 -> 1.1296035 | F32: =SUM(F25:F31) -> 2549 | G32: =SUM(G25:G31) -> 21.840734 | H32: =SUM(H25:H31) -> 489 | I32: =SUM(I25:I31) -> 178 | J32: =SUM(J25:J31) -> 0 | K32: =SUM(K25:K31) -> 0 | L32: =SUM(L25:L31) -> 780 | M32: =SUM(M25:M31) -> 0 | ... AB32: =SUM(AB25:AB31) -> 0
A33: % | C33: =C32/$B$32*100 -> 95.384489 | D33: =D32/$B$32*100 -> 1.1296035 | F33: =F32/$B$32*100 -> 3.4859073 | G33: =G32/$B$32*100 -> 0.029868488 | H33: =H32/$B$32*100 -> 0.66873624 | I33: =I32/$B$32*100 -> 0.24342546 | J33: =J32/$B$32*100 -> 0 | K33: =K32/$B$32*100 -> 0 | L33: =L32/$B$32*100 -> 1.0666958 | M33: =M32/$B$32*100 -> 0 | ... AB33: =AB32/$B$32*100 -> 0 | AC33: =SUM(H33:AB33) -> 3.4859073
A34: 45921 | E34: =D34/B34*100 -> #DIV/0! | F34: =B34-(C34+D34) -> 0 | G34: =F34/B34*100 -> #DIV/0!
A35: 45922 | B35: 12985 | C35: 12353 | D35: 140 | E35: =D35/B35*100 -> 1.0781671 | F35: =B35-(C35+D35) -> 492 | G35: =F35/B35*100 -> 3.7889873 | H35: 46 | I35: 144 | L35: 153 | Q35: 43 | S35: 80 | X35: 11 | Y35: 9 | Z35: 6
A36: 45923 | B36: 14247 | C36: 13402 | D36: 107 | E36: =D36/B36*100 -> 0.75103531 | F36: =B36-(C36+D36) -> 738 | G36: =F36/B36*100 -> 5.1800379 | H36: 31 | I36: 23 | L36: 627 | S36: 51 | Y36: 5 | Z36: 1
A37: 45924 | B37: 11960 | C37: 11272 | D37: 87 | E37: =D37/B37*100 -> 0.72742475 | F37: =B37-(C37+D37) -> 601 | G37: =F37/B37*100 -> 5.0250836 | H37: 31 | I37: 20 | L37: 60 | Q37: 453 | S37: 28 | Z37: 9
A38: 45925 | B38: 13910 | C38: 13253 | D38: 246 | E38: =D38/B38*100 -> 1.7685119 | F38: =B38-(C38+D38) -> 411 | G38: =F38/B38*100 -> 2.9547088 | H38: 28 | I38: 74 | L38: 10 | Q38: 8 | S38: 54 | Y38: 104 | Z38: 31
A39: 45926 | B39: 11156 | C39: 10377 | D39: 217 | E39: =D39/B39*100 -> 1.9451416 | F39: =B39-(C39+D39) -> 562 | G39: =F39/B39*100 -> 5.0376479 | H39: 16 | I39: 106 | L39: 97 | S39: 151 | X39: 8 | Y39: 160 | Z39: 24
A40: 45927 | B40: 12028 | C40: 11057 | D40: 331 | E40: =D40/B40*100 -> 2.7519122 | F40: =B40-(C40+D40) -> 640 | G40: =F40/B40*100 -> 5.3209179 | H40: 32 | I40: 77 | L40: 71 | Q40: 36 | S40: 194 | X40: 3 | Y40: 227
...

Sheet OCTOBER 25
B1: DISPOSAFE HEALTH AND LIFE CARE LIMITED Plot No.37A, Sector-06, Ballabgarh (Faridabad) Haryana India 121006 | X1: Doc. No. : | AA1: F/QC/01:00
X2: Supersedes : | AA2: 00
X3: Effective Date : | AA3: 45607
B4: VISUAL INSPECTION REPORT | X4: Page 1 of 1
A5: DATE | B5: REC. QTY | C5: ACCEPT QTY | D5: HOLD QTY | E5: HOLD% | F5: REJ. QTY | G5: REJ % | H5: REASON FOR REJECTION
H6: 1 | I6: 2 | J6: 3 | K6: 4 | L6: 5 | M6: 6 | N6: 7 | O6: 8 | P6: 9 | Q6: 10 | R6: 11 | S6: 12 | T6: 13 | U6: 14 | V6: 15 | W6: 16 | X6: 17 | Y6: 18 | Z6: 19 | AA6: 20 | AB6: 21
H7: COAG | I7: SD | J7: TT | K7: BL | L7: PS | M7: SB | N7: PW | O7: FP | P7: RW | Q7: BEP | R7: DEC | S7: BM | T7: WEB | U7: BT | V7: SF | W7: BIC | X7: WK | Y7: BMP | Z7: TF | AA7: PH | AB7: BST
A8: 45931 | B8: 8381 | C8: 7602 | D8: 602 | E8: =D8/B8*100 -> 7.1829137 | F8: =B8-(C8+D8) -> 177 | G8: =F8/B8*100 -> 2.1119198 | H8: 26 | I8: 13 | L8: 45 | S8: 88 | Z8: 5
A9: 45932 | B9: VIJAYA DASHMI
A10: 45933 | B10: 13268 | C10: 12516 | D10: 265 | E10: =D10/B10*100 -> 1.9972867 | F10: =B10-(C10+D10) -> 487 | G10: =F10/B10*100 -> 3.6704854 | H10: 50 | I10: 84 | L10: 200 | Q10: 8 | S10: 198 | Z10: 7
A11: 45934 | B11: 15053 | C11: 13602 | D11: 1042 | E11: =D11/B11*100 -> 6.9222082 | F11: =B11-(C11+D11) -> 409 | G11: =F11/B11*100 -> 2.7170664 | H11: 43 | I11: 49 | L11: 65 | N11: 2 | S11: 220 | X11: 27 | Z11: 3
A12: TOTAL | B12: =SUM(B8:B11) -> 36702 | C12: =SUM(C8:C11) -> 33720 | D12: =SUM(D8:D11) -> 1909 | E12: =SUM(E8:E11) -> 16.102409 | F12: =SUM(F8:F11) -> 1073 | G12: =SUM(G8:G11) -> 8.4994716 | H12: =SUM(H8:H11) -> 119 | I12: =SUM(I8:I11) -> 146 | ... AB12: =SUM(AB8:AB11) -> 0
A13: % | C13: =C12/$B$12*100 -> 91.875102 | D13: =D12/$B$12*100 -> 5.2013514 | E13: =E12/$B$12*100 -> 0.043873382 | F13: =F12/$B$12*100 -> 2.9235464 | G13: =G12/$B$12*100 -> 0.023158061 | H13: =H12/$B$12*100 -> 0.32423301 | I13: =I12/$B$12*100 -> 0.39779849 | J13: =J12/$B$12*100 -> 0 | ... AB13: =AB12/$B$12*100 -> 0 | AC13: =SUM(H13:AB13) -> 3.0870252
A14: 45935 | E14: =D14/B14*100 -> #DIV/0! | F14: =B14-(C14+D14) -> 0 | G14: =F14/B14*100 -> #DIV/0!
A15: 45936 | B15: 9702 | C15: 8338 | D15: 1061 | E15: =D15/B15*100 -> 10.93589 | F15: =B15-(C15+D15) -> 303 | G15: =F15/B15*100 -> 3.1230674 | H15: 37 | I15: 58 | L15: 104 | S15: 104
A16: 45937 | B16: 8600 | C16: 7856 | D16: 376 | E16: =D16/B16*100 -> 4.372093 | F16: =B16-(C16+D16) -> 368 | G16: =F16/B16*100 -> 4.2790698 | H16: 32 | I16: 94 | O16: 20 | Q16: 70 | S16: 126 | X16: 26
A17: 45938 | B17: 9978 | C17: 8553 | D17: 385 | E17: =D17/B17*100 -> 3.8584887 | F17: =B17-(C17+D17) -> 1040 | G17: =F17/B17*100 -> 10.42293 | H17: 191 | I17: 272 | N17: 6 | O17: 6 | Q17: 170 | S17: 265 | Y17: 132
A18: 45939 | B18: 8349 | C18: 7596 | D18: 300 | E18: =D18/B18*100 -> 3.5932447 | F18: =B18-(C18+D18) -> 453 | G18: =F18/B18*100 -> 5.4257995 | H18: 108 | I18: 60 | Q18: 95 | S18: 145 | Y18: 45
A19: 45940 | B19: 7311 | C19: 6652 | D19: 138 | E19: =D19/B19*100 -> 1.8875667 | F19: =B19-(C19+D19) -> 521 | G19: =F19/B19*100 -> 7.1262481 | H19: 58 | I19: 59 | L19: 261 | P19: 23 | S19: 113 | X19: 4 | AA19: 3
A20: 45941 | B20: 8226 | C20: 7578 | D20: 266 | E20: =D20/B20*100 -> 3.2336494 | F20: =B20-(C20+D20) -> 382 | G20: =F20/B20*100 -> 4.6438123 | H20: 100 | I20: 63 | Q20: 46 | S20: 114 | X20: 8 | Y20: 51
A21: TOTAL | B21: =SUM(B14:B20) -> 52166 | C21: =SUM(C14:C20) -> 46573 | D21: =SUM(D14:D20) -> 2526 | E21: =D21/B21*100 -> 4.8422344 | F21: =SUM(F14:F20) -> 3067 | G21: =SUM(G14:G20) -> #DIV/0! | H21: =SUM(H14:H20) -> 526 | I21: =SUM(I14:I20) -> 606 | J21: =SUM(J14:J20) -> 0 | K21: =SUM(K14:K20) -> 0 | L21: =SUM(L14:L20) -> 365 | M21: =SUM(M14:M20) -> 0 | ... AB21: =SUM(AB14:AB20) -> 0
A22: % | C22: =C21/$B$21*100 -> 89.278457 | D22: =D21/$B$21*100 -> 4.8422344 | E22: =E21/$B$21*100 -> 0.0092823571 | F22: =F21/$B$21*100 -> 5.8793084 | G22: =G21/$B$21*100 -> #DIV/0! | H22: =H21/$B$21*100 -> 1.0083196 | I22: =I21/$B$21*100 -> 1.1616762 | J22: =J21/$B$21*100 -> 0 | ... AB22: =AB21/$B$21*100 -> 0 | AC22: =SUM(H22:AB22) -> 5.8831423
A23: 45942 | E23: 0 | F23: =B23-(C23+D23) -> 0
A24: 45943 | B24: 7196 | C24: 6194 | D24: 353 | E24: =D24/B24*100 -> 4.9055031 | F24: =B24-(C24+D24) -> 649 | G24: =F24/B24*100 -> 9.0188994 | H24: 91 | I24: 81 | Q24: 260 | S24: 178 | Y24: 39
A25: 45944 | B25: 7331 | C25: 6817 | D25: 86 | E25: =D25/B25*100 -> 1.1731005 | F25: =B25-(C25+D25) -> 428 | G25: =F25/B25*100 -> 5.8382213 | H25: 4 | I25: 118 | L25: 151 | P25: 24 | Q25: 65 | S25: 65 | Y25: 1
A26: 45945 | B26: 6863 | C26: 6261 | D26: 256 | E26: =D26/B26*100 -> 3.7301472 | F26: =B26-(C26+D26) -> 346 | G26: =F26/B26*100 -> 5.041527 | H26: 110 | I26: 40 | L26: 56 | Q26: 7 | S26: 133
A27: 45946 | B27: 9708 | C27: 8709 | D27: 516 | E27: =D27/B27*100 -> 5.315204 | F27: =B27-(C27+D27) -> 483 | G27: =F27/B27*100 -> 4.9752781 | H27: 105 | I27: 20 | L27: 35 | Q27: 100 | S27: 195 | Y27: 28
A28: 45947 | B28: 6419 | C28: 5568 | D28: 630 | E28: =D28/B28*100 -> 9.8146129 | F28: =B28-(C28+D28) -> 221 | G28: =F28/B28*100 -> 3.4429039 | H28: 83 | I28: 25 | L28: 96 | P28: 88 | Q28: 25 | S28: 110 | Z28: 3
A29: 45948 | B29: 5090 | C29: 4553 | D29: 41 | E29: =D29/B29*100 -> 0.80550098 | F29: =B29-(C29+D29) -> 496 | G29: =F29/B29*100 -> 9.7445972 | H29: 72 | I29: 25 | P29: 66 | Q29: 68 | S29: 227 | X29: 16 | Y29: 20 | Z29: 2
A30: TOTAL | B30: =SUM(B23:B29) -> 42607 | C30: =SUM(C23:C29) -> 38102 | D30: =SUM(D23:D29) -> 1882 | E30: =D30/B30*100 -> 4.4171146 | F30: =SUM(F23:F29) -> 2623 | G30: =SUM(G23:G29) -> 38.061427 | H30: =SUM(H23:H29) -> 465 | I30: =SUM(I23:I29) -> 309 | J30: =SUM(J23:J29) -> 0 | K30: =SUM(K23:K29) -> 0 | L30: =SUM(L23:L29) -> 338 | M30: =SUM(M23:M29) -> 0 | ... AB30: =SUM(AB23:AB29) -> 0
A31: % | C31: =C30/$B$30*100 -> 89.42662 | D31: =D30/$B$30*100 -> 4.4171146 | F31: =F30/$B$30*100 -> 6.1562654 | G31: =G30/$B$30*100 -> 0.089331394 | H31: =H30/$B$30*100 -> 1.09137 | I31: =I30/$B$30*100 -> 0.72523294 | J31: =J30/$B$30*100 -> 0 | K31: =K30/$B$30*100 -> 0 | L31: =L30/$B$30*100 -> 0.79329688 | M31: =M30/$B$30*100 -> 0 | ... AB31: =AB30/$B$30*100 -> 0 | AC31: =SUM(H31:AB31) -> 6.6467951
A32: 45949 | B32: 2301 | C32: 2088 | D32: 82 | E32: =D32/B32*100 -> 3.563668 | F32: =B32-(C32+D32) -> 131 | G32: =F32/B32*100 -> 5.6931769 | H32: 6 | I32: 4 | Q32: 17 | S32: 72 | X32: 30 | Z32: 2
A33: 45950 | B33: HAPPY DIWALI
A34: 45951
A35: 45952
A36: 45953
A37: 45954 | B37: 7344 | C37: 6579 | D37: 113 | E37: =D37/B37*100 -> 1.538671 | F37: =B37-(C37+D37) -> 652 | G37: =F37/B37*100 -> 8.8779956
A38: 45955 | B38: 7000 | C38: 6360 | D38: 123 | E38: =D38/B38*100 -> 1.7571429 | F38: =B38-(C38+D38) -> 517 | G38: =F38/B38*100 -> 7.3857143
A39: TOTAL | B39: =SUM(B32:B38) -> 16645 | C39: =SUM(C32:C38) -> 15027 | D39: =SUM(D32:D38) -> 318 | E39: =D39/B39*100 -> 1.9104836 | F39: =SUM(F32:F38) -> 1300 | G39: =SUM(G32:G38) -> 21.956887 | H39: =SUM(H32:H38) -> 6 | I39: =SUM(I32:I38) -> 4 | J39: =SUM(J32:J38) -> 0 | K39: =SUM(K32:K38) -> 0 | L39: =SUM(L32:L38) -> 0 | M39: =SUM(M32:M38) -> 0 | ... AB39: =SUM(AB32:AB38) -> 0
A40: % | C40: =C39/$B$39*100 -> 90.279363 | D40: =D39/$B$39*100 -> 1.9104836 | F40: =F39/$B$39*100 -> 7.8101532 | G40: =G39/$B$39*100 -> 0.13191281 | H40: =H39/$B$39*100 -> 0.036046861 | I40: =I39/$B$39*100 -> 0.024031241 | J40: =J39/$B$39*100 -> 0 | K40: =K39/$B$39*100 -> 0 | L40: =L39/$B$39*100 -> 0 | M40: =M39/$B$39*100 -> 0 | ... AB40: =AB39/$B$39*100 -> 0 | AC40: =SUM(H40:AB40) -> 0.78702313
...

Sheet NOVEMBER 25
B1: DISPOSAFE HEALTH AND LIFE CARE LIMITED Plot No.37A, Sector-06, Ballabgarh (Faridabad) Haryana India 121006 | X1: Doc. No. : | AA1: F/QC/01:00
X2: Supersedes : | AA2: 00
X3: Effective Date : | AA3: 45607
B4: VISUAL INSPECTION REPORT | X4: Page 1 of 1
A5: DATE | B5: REC. QTY | C5: ACCEPT QTY | D5: HOLD QTY | E5: HOLD% | F5: REJ. QTY | G5: REJ % | H5: REASON FOR REJECTION
H6: 1 | I6: 2 | J6: 3 | K6: 4 | L6: 5 | M6: 6 | N6: 7 | O6: 8 | P6: 9 | Q6: 10 | R6: 11 | S6: 12 | T6: 13 | U6: 14 | V6: 15 | W6: 16 | X6: 17 | Y6: 18 | Z6: 19 | AA6: 20 | AB6: 21
H7: COAG | I7: SD | J7: TT | K7: BL | L7: PS | M7: SB | N7: PW | O7: FP | P7: RW | Q7: BEP | R7: DEC | S7: BM | T7: WEB | U7: BT | V7: SF | W7: BIC | X7: WK | Y7: BMP | Z7: TF | AA7: PH | AB7: BST
A8: 45962 | B8: 4262 | C8: 3990 | D8: 162 | E8: =D8/B8*100 -> 3.8010324 | F8: =B8-(C8+D8) -> 110 | G8: =F8/B8*100 -> 2.5809479 | H8: 20 | I8: 23 | S8: 60 | Y8: 1 | Z8: 6
A9: TOTAL | B9: =SUM(B8:B8) -> 4262 | C9: =SUM(C8:C8) -> 3990 | D9: =SUM(D8:D8) -> 162 | E9: =SUM(E8:E8) -> 3.8010324 | F9: =SUM(F8:F8) -> 110 | G9: =SUM(G8:G8) -> 2.5809479 | H9: =SUM(H8:H8) -> 20 | I9: =SUM(I8:I8) -> 23 | ... AB9: =SUM(AB8:AB8) -> 0
A10: % | C10: =C9/$B$9*100 -> 93.61802 | D10: =D9/$B$9*100 -> 3.8010324 | E10: =E9/$B$9*100 -> 0.089184242 | F10: =F9/$B$9*100 -> 2.5809479 | G10: =G9/$B$9*100 -> 0.060557201 | H10: =H9/$B$9*100 -> 0.46926326 | I10: =I9/$B$9*100 -> 0.53965275 | J10: =J9/$B$9*100 -> 0 | ... AB10: =AB9/$B$9*100 -> 0 | AC10: =SUM(H10:AB10) -> 2.5809479
A11: 45963 | E11: =D11/B11*100 -> #DIV/0! | F11: =B11-(C11+D11) -> 0 | G11: =F11/B11*100 -> #DIV/0!
A12: 45964 | B12: 7058 | C12: 6771 | D12: 74 | E12: =D12/B12*100 -> 1.0484557 | F12: =B12-(C12+D12) -> 213 | G12: =F12/B12*100 -> 3.0178521 | H12: 22 | I12: 37 | L12: 41 | Q12: 41 | S12: 65 | Y12: 7
A13: 45965 | B13: 11014 | C13: 10786 | D13: 95 | E13: =D13/B13*100 -> 0.86253859 | F13: =B13-(C13+D13) -> 133 | G13: =F13/B13*100 -> 1.207554 | H13: 5 | I13: 15 | L13: 28 | Q13: 25 | S13: 60
A14: 45966 | B14: 12059 | C14: 11641 | D14: 139 | E14: =D14/B14*100 -> 1.1526661 | F14: =B14-(C14+D14) -> 279 | G14: =F14/B14*100 -> 2.3136247 | H14: 22 | I14: 25 | K14: 65 | Q14: 47 | S14: 113 | Y14: 7
A15: 45967 | B15: 9759 | C15: 8787 | D15: 142 | E15: =D15/B15*100 -> 1.4550671 | F15: =B15-(C15+D15) -> 830 | G15: =F15/B15*100 -> 8.5049698 | H15: 8 | L15: 617 | Q15: 4 | S15: 193 | Y15: 4 | Z15: 4
